Workbook

Sheet Datos_Completos
A1: Nombre | B1: Grupo y Asignatura
A2: ALFARO LINARES SANDRA | B2: IRICE701 - Tecnologias para Manejo Masivo de Datos_x000D_ IRICE801 - Cómputo en la Nube_x000D_ IRICE802 - Cómputo en la Nube_x000D_
A3: BAEZA FLORES MARIA DEL CARMEN | B3: LDDPAE804 - Imagen Corporativa_x000D_ DDA502 - Imagen Digital Animada_x000D_ DDA501 - Animación en 3D_x000D_ DDA401 - Animación en 2D_x000D_ DAD101 - Comunicación Gráfica.__x000D_
A4: BERNAL FUENTES SILVIA GUADALUPE | B4: DAD202 - Representación Geométrica._x000D_
A5: CRUZ GARCIA MISAEL
A6: GARCIA TRINIDAD ENRIQUE | B6: IRICE801 - Matemáticas para Ingeniería I_x000D_ IRICE802 - Matemáticas para Ingeniería I_x000D_
A7: GOMEZ GONZALEZ JORGE | B7: DAD208 - Representación Geométrica._x000D_ DDA209 - Geometría Descriptiva._x000D_ DDA206 - Geometría Descriptiva._x000D_ DDA401 - Física_x000D_
A8: GONZALEZ GARCIA VERONICA | B8: DDA505 - Integradora II_x000D_ LDDPA1001 - Gestión de Proyectos_x000D_ DAD205 - Modelado Manual._x000D_ DAD206 - Modelado Manual._x000D_ DAD207 - Modelado Manual._x000D_ DDA208 - Modelado Manual._x000D_
A9: IBARRA VAZQUEZ JESSICA DANIELA | B9: DDA503 - Animación en 3D_x000D_ DDA301 - Software CAD_x000D_ DAD201 - Modelado Manual._x000D_ DAD202 - Modelado Manual._x000D_ DDA502 - Animación en 3D_x000D_
A10: INFANTE DE LA FUENTE JUAN GABRIEL | B10: DSM 401 - Evaluacion y mejora para el Desarrollo de Software _x000D_ DSM 501 - Integradora_x000D_ DSM 502 - Integradora_x000D_ DGSE802 - Desarrollo Web Profesional _x000D_ IRICE802 - Gestión de La Seguridad Informática_x000D_
A11: ISLAS GONZALEZ YUNUEN | B11: LDDPAE804 - Animación 2D Avanzada_x000D_ DDA504 - Animación en 3D_x000D_ DDA505 - Imagen Digital Animada_x000D_ DDA503 - Imagen Digital Animada_x000D_
A12: LANDIN HERREJON JOSE LUIS GUSTAVO | B12: DAD206 - Representación Geométrica._x000D_ DAD207 - Representación Geométrica._x000D_ DAD204 - Mercadotecnia._x000D_ DDA401 - Formación Sociocultural IV_x000D_ DDA502 - Expresión Oral y Escrita II °_x000D_ DDA301 - Mercadotecnia_x000D_ DDA501 - Integradora II_x000D_ DAD101 - Representación Visual.__x000D_
A13: LIMA ARRONA FERNANDO | B13: CD201 - Programación._x000D_ IRD501 - Introducción a Big Data_x000D_ IRD502 - Introducción a Big Data_x000D_
A14: MALDONADO GUERRERO ALHAN GERARD | B14: DDA504 - Edición de Audio y Video_x000D_ DDA505 - Edición de Audio y Video_x000D_ LDDPA901 - Proceso de Producción Audiovisual_x000D_ DAD203 - Modelado Manual._x000D_ DDA503 - Expresión Oral y Escrita II__x000D_
A15: MARTINEZ VEGA FERMIN | B15: LDDPA701 - Estadística_x000D_ LDDPA702 - Estadística_x000D_ DAD205 - Geometría Descriptiva._x000D_ DAD208 - Geometría Descriptiva._x000D_ DDA401 - Prototipos_x000D_
A16: MENDOZA CALVA HECTOR RAUL | B16: DAD201 - Ilustración Digital._x000D_ DAD202 - Ilustración Digital._x000D_ DDA502 - Integradora II_x000D_
A17: MONROY TREJO ALEJANDRO | B17: LDDPA1001 - Postproducción Audiovisual_x000D_ LDDPA701 - Estética Digital_x000D_ LDDPA702 - Estética Digital_x000D_ DAD209 - Representación Geométrica._x000D_
... A35: ZAMACONA PRADO NAYELI | B35: LDDPA701 - Metodología de Diseño_x000D_ LDDPA702 - Metodología de Diseño_x000D_ DAD201 - Mercadotecnia._x000D_ DAD202 - Mercadotecnia._x000D_ DAD203 - Mercadotecnia._x000D_ DDA401 - Diseño Editorial Digital_x000D_ DAD101 - Fundamentos de Diseño y del Lenguaje Visual.__x000D_
A37: GONZALEZ GARCIA VERONICA

Sheet ALFARO LINARES SANDRA
B1: UNIVERSIDAD TECNOLÓGICA FIDEL VELÁZQUEZ
B2: SECRETARÍA ACADÉMICA
B3: CARGA HORARIA PROFESOR DE ASIGNATURA
I5: NOMBRE DE LA DIVISIÓN: TELEMÁTICA
I6: PERIODO CUATRIMESTRAL: (MAYO - AGOSTO 2025) 2025-2
I7: VIGENCIA APARTIR DE: 01/05/2025 AL 30/08/2025
B10: ALFARO LINARES SANDRA | N10: MAESTRÍA
B11: NOMBRE DE LA PROFESORA O PROFESOR | N11: PROFESIÓN Y GRADO MÁXIMO DE ESTUDIOS
B13: DISTRIBUCIÓN DE HORAS AL CUATRIMESTRE
B14: DOCENCIA | D14: FRENTE A GRUPO | H14: ASIGNATURA | L14: CLAVE | M14: GRUPO | N14: HORAS/SEMANA/MES | R14: HORAS TOTALES POR SEMANA**
L15: {=INDEX(z_3_Materias!B2:B508, MATCH(H15, z_3_Materias!A2:A508, 0))} -> 0 | N15: {=INDEX(z_3_Materias!D2:D508, MATCH(H15, z_3_Materias!A2:A508, 0))} -> 0 | R15: =SUM(N15:Q23) -> 0 | T15: =H15&" "&M15
L16: {=INDEX(z_3_Materias!B2:B508, MATCH(H16, z_3_Materias!A2:A508, 0))} -> 0 | N16: {=INDEX(z_3_Materias!D2:D508, MATCH(H16, z_3_Materias!A2:A508, 0))} -> 0 | T16: =H16&" "&M16
L17: {=INDEX(z_3_Materias!B2:B508, MATCH(H17, z_3_Materias!A2:A508, 0))} -> 0 | N17: {=INDEX(z_3_Materias!D2:D508, MATCH(H17, z_3_Materias!A2:A508, 0))} -> 0 | T17: =H17&" "&M17
L18: {=INDEX(z_3_Materias!B2:B508, MATCH(H18, z_3_Materias!A2:A508, 0))} -> 0 | N18: {=INDEX(z_3_Materias!D2:D508, MATCH(H18, z_3_Materias!A2:A508, 0))} -> 0 | T18: =H18&" "&M18
L19: {=INDEX(z_3_Materias!B2:B508, MATCH(H19, z_3_Materias!A2:A508, 0))} -> 0 | N19: {=INDEX(z_3_Materias!D2:D508, MATCH(H19, z_3_Materias!A2:A508, 0))} -> 0 | T19: =H19&" "&M19
L20: {=INDEX(z_3_Materias!B2:B508, MATCH(H20, z_3_Materias!A2:A508, 0))} -> 0 | N20: {=INDEX(z_3_Materias!D2:D508, MATCH(H20, z_3_Materias!A2:A508, 0))} -> 0 | T20: =H20&" "&M20
L21: {=INDEX(z_3_Materias!B2:B508, MATCH(H21, z_3_Materias!A2:A508, 0))} -> 0 | N21: {=INDEX(z_3_Materias!D2:D508, MATCH(H21, z_3_Materias!A2:A508, 0))} -> 0 | T21: =H21&" "&M21
L22: {=INDEX(z_3_Materias!B2:B508, MATCH(H22, z_3_Materias!A2:A508, 0))} -> 0 | N22: {=INDEX(z_3_Materias!D2:D508, MATCH(H22, z_3_Materias!A2:A508, 0))} -> 0 | T22: =H22&" "&M22
L23: {=INDEX(z_3_Materias!B2:B508, MATCH(H23, z_3_Materias!A2:A508, 0))} -> 0 | N23: {=INDEX(z_3_Materias!D2:D508, MATCH(H23, z_3_Materias!A2:A508, 0))} -> 0 | T23: =H23&" "&M23
B25: HORARIO SEMANAL*11)
B26: DISTRIBUCIÓN DE HORAS | H26: LUNES | J26: MARTES | L26: MIERCOLES | N26: JUEVES | P26: VIERNES | R26: SÁBADO
B27: 07:00 A 08:00
B28: 08:00 A 09:00
B29: 09:00 A 10:00
B30: 10:00 A 11:00
B31: 11:00 A 12:00
B32: 12:00 A 13:00
B33: 13:00 A 14:00
B34: 14:00 A 15:00
B35: 15:00 A 16:00
B36: 16:00 A 17:00
B37: 17:00 A 18:00
B38: 18:00 A 19:00
... B41: 21:00 A 22:00
C46: MTRO. OLIVER RAÚL VELÁZQUEZ TORRES | N46: =B10 -> ALFARO LINARES SANDRA
C47: NOMBRE Y FIRMA DEL DIRECTOR ACADÉMICO | N47: NOMBRE Y FIRMA DE LA PROFESORA O PROFESOR

Sheet BAEZA FLORES MARIA DEL CARMEN
B1: UNIVERSIDAD TECNOLÓGICA FIDEL VELÁZQUEZ
B2: SECRETARÍA ACADÉMICA
B3: CARGA HORARIA PROFESOR DE ASIGNATURA
I5: NOMBRE DE LA DIVISIÓN: TELEMÁTICA
I6: PERIODO CUATRIMESTRAL: (MAYO - AGOSTO 2025) 2025-2
I7: VIGENCIA APARTIR DE: 01/05/2025 AL 30/08/2025
B10: BAEZA FLORES MARIA DEL CARMEN | N10: MAESTRÍA
B11: NOMBRE DE LA PROFESORA O PROFESOR | N11: PROFESIÓN Y GRADO MÁXIMO DE ESTUDIOS
B13: DISTRIBUCIÓN DE HORAS AL CUATRIMESTRE
B14: DOCENCIA | D14: FRENTE A GRUPO | H14: ASIGNATURA | L14: CLAVE | M14: GRUPO | N14: HORAS/SEMANA/MES | R14: HORAS TOTALES POR SEMANA**
L15: {=INDEX(z_3_Materias!B2:B508, MATCH(H15, z_3_Materias!A2:A508, 0))} -> 0 | N15: {=INDEX(z_3_Materias!D2:D508, MATCH(H15, z_3_Materias!A2:A508, 0))} -> 0 | R15: =SUM(N15:Q23) -> 5 | T15: =H15&" "&M15
L16: {=INDEX(z_3_Materias!B2:B508, MATCH(H16, z_3_Materias!A2:A508, 0))} -> 0 | N16: {=INDEX(z_3_Materias!D2:D508, MATCH(H16, z_3_Materias!A2:A508, 0))} -> 0 | T16: =H16&" "&M16
L17: {=INDEX(z_3_Materias!B2:B508, MATCH(H17, z_3_Materias!A2:A508, 0))} -> 0 | N17: {=INDEX(z_3_Materias!D2:D508, MATCH(H17, z_3_Materias!A2:A508, 0))} -> 0 | T17: =H17&" "&M17
L18: {=INDEX(z_3_Materias!B2:B508, MATCH(H18, z_3_Materias!A2:A508, 0))} -> 0 | N18: {=INDEX(z_3_Materias!D2:D508, MATCH(H18, z_3_Materias!A2:A508, 0))} -> 0 | T18: =H18&" "&M18
L19: {=INDEX(z_3_Materias!B2:B508, MATCH(H19, z_3_Materias!A2:A508, 0))} -> 0 | N19: {=INDEX(z_3_Materias!D2:D508, MATCH(H19, z_3_Materias!A2:A508, 0))} -> 0 | T19: =H19&" "&M19
L20: {=INDEX(z_3_Materias!B2:B508, MATCH(H20, z_3_Materias!A2:A508, 0))} -> 0 | N20: 5 | T20: =H20&" "&M20
L21: {=INDEX(z_3_Materias!B2:B508, MATCH(H21, z_3_Materias!A2:A508, 0))} -> 0 | N21: {=INDEX(z_3_Materias!D2:D508, MATCH(H21, z_3_Materias!A2:A508, 0))} -> 0 | T21: =H21&" "&M21
L22: {=INDEX(z_3_Materias!B2:B508, MATCH(H22, z_3_Materias!A2:A508, 0))} -> 0 | N22: {=INDEX(z_3_Materias!D2:D508, MATCH(H22, z_3_Materias!A2:A508, 0))} -> 0 | T22: =H22&" "&M22
L23: {=INDEX(z_3_Materias!B2:B508, MATCH(H23, z_3_Materias!A2:A508, 0))} -> 0 | N23: {=INDEX(z_3_Materias!D2:D508, MATCH(H23, z_3_Materias!A2:A508, 0))} -> 0 | T23: =H23&" "&M23
B25: HORARIO SEMANAL*11)
B26: DISTRIBUCIÓN DE HORAS | H26: LUNES | J26: MARTES | L26: MIERCOLES | N26: JUEVES | P26: VIERNES | R26: SÁBADO
B27: 07:00 A 08:00
B28: 08:00 A 09:00
B29: 09:00 A 10:00
B30: 10:00 A 11:00
B31: 11:00 A 12:00
B32: 12:00 A 13:00
B33: 13:00 A 14:00
B34: 14:00 A 15:00
B35: 15:00 A 16:00
B36: 16:00 A 17:00
B37: 17:00 A 18:00
B38: 18:00 A 19:00
... B41: 21:00 A 22:00
C46: MTRO. OLIVER RAÚL VELÁZQUEZ TORRES | N46: =B10 -> BAEZA FLORES MARIA DEL CARMEN
C47: NOMBRE Y FIRMA DEL DIRECTOR ACADÉMICO | N47: NOMBRE Y FIRMA DE LA PROFESORA O PROFESOR

Sheet CRUZ GARCIA MISAEL
B1: UNIVERSIDAD TECNOLÓGICA FIDEL VELÁZQUEZ
B2: SECRETARÍA ACADÉMICA
B3: CARGA HORARIA PROFESOR DE ASIGNATURA
I5: NOMBRE DE LA DIVISIÓN: TELEMÁTICA
I6: PERIODO CUATRIMESTRAL: (MAYO - AGOSTO 2025) 2025-2
I7: VIGENCIA APARTIR DE: 01/05/2025 AL 30/08/2025
B10: CRUZ GARCIA MISAEL | N10: MAESTRÍA
B11: NOMBRE DE LA PROFESORA O PROFESOR | N11: PROFESIÓN Y GRADO MÁXIMO DE ESTUDIOS
B13: DISTRIBUCIÓN DE HORAS AL CUATRIMESTRE
B14: DOCENCIA | D14: FRENTE A GRUPO | H14: ASIGNATURA | L14: CLAVE | M14: GRUPO | N14: HORAS/SEMANA/MES | R14: HORAS TOTALES POR SEMANA**
H15: Modelos Estadísticos* | L15: {=INDEX(z_3_Materias!B2:B508, MATCH(H15, z_3_Materias!A2:A508, 0))} -> 24CD020 | M15: CD301 | N15: {=INDEX(z_3_Materias!D2:D508, MATCH(H15, z_3_Materias!A2:A508, 0))} -> 6 | R15: =SUM(N15:Q23) -> 6 | T15: =H15&" "&M15 -> Modelos Estadísticos* CD301
L16: {=INDEX(z_3_Materias!B2:B508, MATCH(H16, z_3_Materias!A2:A508, 0))} -> 0 | N16: {=INDEX(z_3_Materias!D2:D508, MATCH(H16, z_3_Materias!A2:A508, 0))} -> 0 | T16: =H16&" "&M16
L17: {=INDEX(z_3_Materias!B2:B508, MATCH(H17, z_3_Materias!A2:A508, 0))} -> 0 | N17: {=INDEX(z_3_Materias!D2:D508, MATCH(H17, z_3_Materias!A2:A508, 0))} -> 0 | T17: =H17&" "&M17
L18: {=INDEX(z_3_Materias!B2:B508, MATCH(H18, z_3_Materias!A2:A508, 0))} -> 0 | N18: {=INDEX(z_3_Materias!D2:D508, MATCH(H18, z_3_Materias!A2:A508, 0))} -> 0 | T18: =H18&" "&M18
L19: {=INDEX(z_3_Materias!B2:B508, MATCH(H19, z_3_Materias!A2:A508, 0))} -> 0 | N19: {=INDEX(z_3_Materias!D2:D508, MATCH(H19, z_3_Materias!A2:A508, 0))} -> 0 | T19: =H19&" "&M19
L20: {=INDEX(z_3_Materias!B2:B508, MATCH(H20, z_3_Materias!A2:A508, 0))} -> 0 | N20: {=INDEX(z_3_Materias!D2:D508, MATCH(H20, z_3_Materias!A2:A508, 0))} -> 0 | T20: =H20&" "&M20
L21: {=INDEX(z_3_Materias!B2:B508, MATCH(H21, z_3_Materias!A2:A508, 0))} -> 0 | N21: {=INDEX(z_3_Materias!D2:D508, MATCH(H21, z_3_Materias!A2:A508, 0))} -> 0 | T21: =H21&" "&M21
L22: {=INDEX(z_3_Materias!B2:B508, MATCH(H22, z_3_Materias!A2:A508, 0))} -> 0 | N22: {=INDEX(z_3_Materias!D2:D508, MATCH(H22, z_3_Materias!A2:A508, 0))} -> 0 | T22: =H22&" "&M22
L23: {=INDEX(z_3_Materias!B2:B508, MATCH(H23, z_3_Materias!A2:A508, 0))} -> 0 | N23: {=INDEX(z_3_Materias!D2:D508, MATCH(H23, z_3_Materias!A2:A508, 0))} -> 0 | T23: =H23&" "&M23
B25: HORARIO SEMANAL*11)
B26: DISTRIBUCIÓN DE HORAS | H26: LUNES | J26: MARTES | L26: MIERCOLES | N26: JUEVES | P26: VIERNES | R26: SÁBADO
B27: 07:00 A 08:00
B28: 08:00 A 09:00
B29: 09:00 A 10:00
B30: 10:00 A 11:00
B31: 11:00 A 12:00
B32: 12:00 A 13:00
B33: 13:00 A 14:00
B34: 14:00 A 15:00
B35: 15:00 A 16:00
B36: 16:00 A 17:00
B37: 17:00 A 18:00
B38: 18:00 A 19:00
... B41: 21:00 A 22:00
C46: MTRO. OLIVER RAÚL VELÁZQUEZ TORRES | N46: =B10 -> CRUZ GARCIA MISAEL
C47: NOMBRE Y FIRMA DEL DIRECTOR ACADÉMICO | N47: NOMBRE Y FIRMA DE LA PROFESORA O PROFESOR

Sheet GARCIA TRINIDAD ENRIQUE
B1: UNIVERSIDAD TECNOLÓGICA FIDEL VELÁZQUEZ
B2: SECRETARÍA ACADÉMICA
B3: CARGA HORARIA PROFESOR DE ASIGNATURA
I5: NOMBRE DE LA DIVISIÓN: TELEMÁTICA
I6: PERIODO CUATRIMESTRAL: (MAYO - AGOSTO 2025) 2025-2
I7: VIGENCIA APARTIR DE: 01/05/2025 AL 30/08/2025
B10: GARCIA TRINIDAD ENRIQUE | N10: MAESTRÍA
B11: NOMBRE DE LA PROFESORA O PROFESOR | N11: PROFESIÓN Y GRADO MÁXIMO DE ESTUDIOS
B13: DISTRIBUCIÓN DE HORAS AL CUATRIMESTRE
B14: DOCENCIA | D14: FRENTE A GRUPO | H14: ASIGNATURA | L14: CLAVE | M14: GRUPO | N14: HORAS/SEMANA/MES | R14: HORAS TOTALES POR SEMANA**
L15: {=INDEX(z_3_Materias!B2:B508, MATCH(H15, z_3_Materias!A2:A508, 0))} -> 0 | N15: {=INDEX(z_3_Materias!D2:D508, MATCH(H15, z_3_Materias!A2:A508, 0))} -> 0 | R15: =SUM(N15:Q23) -> 0 | T15: =H15&" "&M15
L16: {=INDEX(z_3_Materias!B2:B508, MATCH(H16, z_3_Materias!A2:A508, 0))} -> 0 | N16: {=INDEX(z_3_Materias!D2:D508, MATCH(H16, z_3_Materias!A2:A508, 0))} -> 0 | T16: =H16&" "&M16
L17: {=INDEX(z_3_Materias!B2:B508, MATCH(H17, z_3_Materias!A2:A508, 0))} -> 0 | N17: {=INDEX(z_3_Materias!D2:D508, MATCH(H17, z_3_Materias!A2:A508, 0))} -> 0 | T17: =H17&" "&M17
L18: {=INDEX(z_3_Materias!B2:B508, MATCH(H18, z_3_Materias!A2:A508, 0))} -> 0 | N18: {=INDEX(z_3_Materias!D2:D508, MATCH(H18, z_3_Materias!A2:A508, 0))} -> 0 | T18: =H18&" "&M18
L19: {=INDEX(z_3_Materias!B2:B508, MATCH(H19, z_3_Materias!A2:A508, 0))} -> 0 | N19: {=INDEX(z_3_Materias!D2:D508, MATCH(H19, z_3_Materias!A2:A508, 0))} -> 0 | T19: =H19&" "&M19
L20: {=INDEX(z_3_Materias!B2:B508, MATCH(H20, z_3_Materias!A2:A508, 0))} -> 0 | N20: {=INDEX(z_3_Materias!D2:D508, MATCH(H20, z_3_Materias!A2:A508, 0))} -> 0 | T20: =H20&" "&M20
L21: {=INDEX(z_3_Materias!B2:B508, MATCH(H21, z_3_Materias!A2:A508, 0))} -> 0 | N21: {=INDEX(z_3_Materias!D2:D508, MATCH(H21, z_3_Materias!A2:A508, 0))} -> 0 | T21: =H21&" "&M21
L22: {=INDEX(z_3_Materias!B2:B508, MATCH(H22, z_3_Materias!A2:A508, 0))} -> 0 | N22: {=INDEX(z_3_Materias!D2:D508, MATCH(H22, z_3_Materias!A2:A508, 0))} -> 0 | T22: =H22&" "&M22
L23: {=INDEX(z_3_Materias!B2:B508, MATCH(H23, z_3_Materias!A2:A508, 0))} -> 0 | N23: {=INDEX(z_3_Materias!D2:D508, MATCH(H23, z_3_Materias!A2:A508, 0))} -> 0 | T23: =H23&" "&M23
B25: HORARIO SEMANAL*11)
B26: DISTRIBUCIÓN DE HORAS | H26: LUNES | J26: MARTES | L26: MIERCOLES | N26: JUEVES | P26: VIERNES | R26: SÁBADO
B27: 07:00 A 08:00
B28: 08:00 A 09:00
B29: 09:00 A 10:00
B30: 10:00 A 11:00
B31: 11:00 A 12:00
B32: 12:00 A 13:00
B33: 13:00 A 14:00
B34: 14:00 A 15:00
B35: 15:00 A 16:00
B36: 16:00 A 17:00
B37: 17:00 A 18:00
B38: 18:00 A 19:00
... B41: 21:00 A 22:00
C46: MTRO. OLIVER RAÚL VELÁZQUEZ TORRES | N46: =B10 -> GARCIA TRINIDAD ENRIQUE
C47: NOMBRE Y FIRMA DEL DIRECTOR ACADÉMICO | N47: NOMBRE Y FIRMA DE LA PROFESORA O PROFESOR

Sheet GOMEZ GONZALEZ JORGE
B1: UNIVERSIDAD TECNOLÓGICA FIDEL VELÁZQUEZ
B2: SECRETARÍA ACADÉMICA
B3: CARGA HORARIA PROFESOR DE ASIGNATURA
I5: NOMBRE DE LA DIVISIÓN: TELEMÁTICA
I6: PERIODO CUATRIMESTRAL: (MAYO - AGOSTO 2025) 2025-2
I7: VIGENCIA APARTIR DE: 01/05/2025 AL 30/08/2025
B10: GOMEZ GONZALEZ JORGE | N10: MAESTRÍA
B11: NOMBRE DE LA PROFESORA O PROFESOR | N11: PROFESIÓN Y GRADO MÁXIMO DE ESTUDIOS
B13: DISTRIBUCIÓN DE HORAS AL CUATRIMESTRE
B14: DOCENCIA | D14: FRENTE A GRUPO | H14: ASIGNATURA | L14: CLAVE | M14: GRUPO | N14: HORAS/SEMANA/MES | R14: HORAS TOTALES POR SEMANA**
L15: {=INDEX(z_3_Materias!B2:B508, MATCH(H15, z_3_Materias!A2:A508, 0))} -> 0 | N15: {=INDEX(z_3_Materias!D2:D508, MATCH(H15, z_3_Materias!A2:A508, 0))} -> 0 | R15: =SUM(N15:Q23) -> 0 | T15: =H15&" "&M15
L16: {=INDEX(z_3_Materias!B2:B508, MATCH(H16, z_3_Materias!A2:A508, 0))} -> 0 | N16: {=INDEX(z_3_Materias!D2:D508, MATCH(H16, z_3_Materias!A2:A508, 0))} -> 0 | T16: =H16&" "&M16
L17: {=INDEX(z_3_Materias!B2:B508, MATCH(H17, z_3_Materias!A2:A508, 0))} -> 0 | N17: {=INDEX(z_3_Materias!D2:D508, MATCH(H17, z_3_Materias!A2:A508, 0))} -> 0 | T17: =H17&" "&M17
L18: {=INDEX(z_3_Materias!B2:B508, MATCH(H18, z_3_Materias!A2:A508, 0))} -> 0 | N18: {=INDEX(z_3_Materias!D2:D508, MATCH(H18, z_3_Materias!A2:A508, 0))} -> 0 | T18: =H18&" "&M18
L19: {=INDEX(z_3_Materias!B2:B508, MATCH(H19, z_3_Materias!A2:A508, 0))} -> 0 | N19: {=INDEX(z_3_Materias!D2:D508, MATCH(H19, z_3_Materias!A2:A508, 0))} -> 0 | T19: =H19&" "&M19
L20: {=INDEX(z_3_Materias!B2:B508, MATCH(H20, z_3_Materias!A2:A508, 0))} -> 0 | N20: {=INDEX(z_3_Materias!D2:D508, MATCH(H20, z_3_Materias!A2:A508, 0))} -> 0 | T20: =H20&" "&M20
L21: {=INDEX(z_3_Materias!B2:B508, MATCH(H21, z_3_Materias!A2:A508, 0))} -> 0 | N21: {=INDEX(z_3_Materias!D2:D508, MATCH(H21, z_3_Materias!A2:A508, 0))} -> 0 | T21: =H21&" "&M21
L22: {=INDEX(z_3_Materias!B2:B508, MATCH(H22, z_3_Materias!A2:A508, 0))} -> 0 | N22: {=INDEX(z_3_Materias!D2:D508, MATCH(H22, z_3_Materias!A2:A508, 0))} -> 0 | T22: =H22&" "&M22
L23: {=INDEX(z_3_Materias!B2:B508, MATCH(H23, z_3_Materias!A2:A508, 0))} -> 0 | N23: {=INDEX(z_3_Materias!D2:D508, MATCH(H23, z_3_Materias!A2:A508, 0))} -> 0 | T23: =H23&" "&M23
B25: HORARIO SEMANAL*11)
B26: DISTRIBUCIÓN DE HORAS | H26: LUNES | J26: MARTES | L26: MIERCOLES | N26: JUEVES | P26: VIERNES | R26: SÁBADO
B27: 07:00 A 08:00
B28: 08:00 A 09:00
B29: 09:00 A 10:00
B30: 10:00 A 11:00
B31: 11:00 A 12:00
B32: 12:00 A 13:00
B33: 13:00 A 14:00
B34: 14:00 A 15:00
B35: 15:00 A 16:00
B36: 16:00 A 17:00
B37: 17:00 A 18:00
B38: 18:00 A 19:00
... B41: 21:00 A 22:00
C46: MTRO. OLIVER RAÚL VELÁZQUEZ TORRES | N46: =B10 -> GOMEZ GONZALEZ JORGE
C47: NOMBRE Y FIRMA DEL DIRECTOR ACADÉMICO | N47: NOMBRE Y FIRMA DE LA PROFESORA O PROFESOR

Sheet GONZALEZ GARCIA VERONICA
B1: UNIVERSIDAD TECNOLÓGICA FIDEL VELÁZQUEZ
B2: SECRETARÍA ACADÉMICA
B3: CARGA HORARIA PROFESOR DE ASIGNATURA
I5: NOMBRE DE LA DIVISIÓN: TELEMÁTICA
I6: PERIODO CUATRIMESTRAL: (MAYO - AGOSTO 2025) 2025-2
I7: VIGENCIA APARTIR DE: 01/05/2025 AL 30/08/2025
B10: GONZALEZ GARCIA VERONICA | N10: MAESTRÍA
B11: NOMBRE DE LA PROFESORA O PROFESOR | N11: PROFESIÓN Y GRADO MÁXIMO DE ESTUDIOS
B13: DISTRIBUCIÓN DE HORAS AL CUATRIMESTRE
B14: DOCENCIA | D14: FRENTE A GRUPO | L14: CLAVE | M14: GRUPO | N14: HORAS/SEMANA/MES | R14: HORAS TOTALES POR SEMANA**
L15: {=INDEX(z_3_Materias!B2:B508, MATCH(H15, z_3_Materias!A2:A508, 0))} -> 0 | N15: {=INDEX(z_3_Materias!D2:D508, MATCH(H15, z_3_Materias!A2:A508, 0))} -> 0 | R15: =SUM(N15:Q23) -> 0 | T15: =H15&" "&M15
L16: {=INDEX(z_3_Materias!B2:B508, MATCH(H16, z_3_Materias!A2:A508, 0))} -> 0 | N16: {=INDEX(z_3_Materias!D2:D508, MATCH(H16, z_3_Materias!A2:A508, 0))} -> 0 | T16: =H16&" "&M16
L17: {=INDEX(z_3_Materias!B2:B508, MATCH(H17, z_3_Materias!A2:A508, 0))} -> 0 | N17: {=INDEX(z_3_Materias!D2:D508, MATCH(H17, z_3_Materias!A2:A508, 0))} -> 0 | T17: =H17&" "&M17
L18: {=INDEX(z_3_Materias!B2:B508, MATCH(H18, z_3_Materias!A2:A508, 0))} -> 0 | N18: {=INDEX(z_3_Materias!D2:D508, MATCH(H18, z_3_Materias!A2:A508, 0))} -> 0 | T18: =H18&" "&M18
L19: {=INDEX(z_3_Materias!B2:B508, MATCH(H19, z_3_Materias!A2:A508, 0))} -> 0 | N19: {=INDEX(z_3_Materias!D2:D508, MATCH(H19, z_3_Materias!A2:A508, 0))} -> 0 | T19: =H19&" "&M19
L20: {=INDEX(z_3_Materias!B2:B508, MATCH(H20, z_3_Materias!A2:A508, 0))} -> 0 | N20: {=INDEX(z_3_Materias!D2:D508, MATCH(H20, z_3_Materias!A2:A508, 0))} -> 0 | T20: =H20&" "&M20
L21: {=INDEX(z_3_Materias!B2:B508, MATCH(H21, z_3_Materias!A2:A508, 0))} -> 0 | N21: {=INDEX(z_3_Materias!D2:D508, MATCH(H21, z_3_Materias!A2:A508, 0))} -> 0 | T21: =H21&" "&M21
L22: {=INDEX(z_3_Materias!B2:B508, MATCH(H22, z_3_Materias!A2:A508, 0))} -> 0 | N22: {=INDEX(z_3_Materias!D2:D508, MATCH(H22, z_3_Materias!A2:A508, 0))} -> 0 | T22: =H22&" "&M22
L23: {=INDEX(z_3_Materias!B2:B508, MATCH(H23, z_3_Materias!A2:A508, 0))} -> 0 | N23: {=INDEX(z_3_Materias!D2:D508, MATCH(H23, z_3_Materias!A2:A508, 0))} -> 0 | T23: =H23&" "&M23
B25: HORARIO SEMANAL*11)
B26: DISTRIBUCIÓN DE HORAS | H26: LUNES | J26: MARTES | L26: MIERCOLES | N26: JUEVES | P26: VIERNES | R26: SÁBADO
B27: 07:00 A 08:00
B28: 08:00 A 09:00
B29: 09:00 A 10:00
B30: 10:00 A 11:00
B31: 11:00 A 12:00
B32: 12:00 A 13:00
B33: 13:00 A 14:00
B34: 14:00 A 15:00
B35: 15:00 A 16:00
B36: 16:00 A 17:00
B37: 17:00 A 18:00
B38: 18:00 A 19:00
... B41: 21:00 A 22:00
C46: MTRO. OLIVER RAÚL VELÁZQUEZ TORRES | N46: =B10 -> GONZALEZ GARCIA VERONICA
C47: NOMBRE Y FIRMA DEL DIRECTOR ACADÉMICO | N47: NOMBRE Y FIRMA DE LA PROFESORA O PROFESOR

Sheet IBARRA VAZQUEZ JESSICA DANIELA
B1: UNIVERSIDAD TECNOLÓGICA FIDEL VELÁZQUEZ
B2: SECRETARÍA ACADÉMICA
B3: CARGA HORARIA PROFESOR DE ASIGNATURA
I5: NOMBRE DE LA DIVISIÓN: TELEMÁTICA
I6: PERIODO CUATRIMESTRAL: (MAYO - AGOSTO 2025) 2025-2
I7: VIGENCIA APARTIR DE: 01/05/2025 AL 30/08/2025
B10: IBARRA VAZQUEZ JESSICA DANIELA | N10: MAESTRÍA
B11: NOMBRE DE LA PROFESORA O PROFESOR | N11: PROFESIÓN Y GRADO MÁXIMO DE ESTUDIOS
B13: DISTRIBUCIÓN DE HORAS AL CUATRIMESTRE
B14: DOCENCIA | D14: FRENTE A GRUPO | H14: ASIGNATURA | L14: CLAVE | M14: GRUPO | N14: HORAS/SEMANA/MES | R14: HORAS TOTALES POR SEMANA**
L15: {=INDEX(z_3_Materias!B2:B508, MATCH(H15, z_3_Materias!A2:A508, 0))} -> 0 | N15: {=INDEX(z_3_Materias!D2:D508, MATCH(H15, z_3_Materias!A2:A508, 0))} -> 0 | R15: =SUM(N15:Q23) -> 0 | T15: =H15&" "&M15
L16: {=INDEX(z_3_Materias!B2:B508, MATCH(H16, z_3_Materias!A2:A508, 0))} -> 0 | N16: {=INDEX(z_3_Materias!D2:D508, MATCH(H16, z_3_Materias!A2:A508, 0))} -> 0 | T16: =H16&" "&M16
L17: {=INDEX(z_3_Materias!B2:B508, MATCH(H17, z_3_Materias!A2:A508, 0))} -> 0 | N17: {=INDEX(z_3_Materias!D2:D508, MATCH(H17, z_3_Materias!A2:A508, 0))} -> 0 | T17: =H17&" "&M17
L18: {=INDEX(z_3_Materias!B2:B508, MATCH(H18, z_3_Materias!A2:A508, 0))} -> 0 | N18: {=INDEX(z_3_Materias!D2:D508, MATCH(H18, z_3_Materias!A2:A508, 0))} -> 0 | T18: =H18&" "&M18
L19: {=INDEX(z_3_Materias!B2:B508, MATCH(H19, z_3_Materias!A2:A508, 0))} -> 0 | N19: {=INDEX(z_3_Materias!D2:D508, MATCH(H19, z_3_Materias!A2:A508, 0))} -> 0 | T19: =H19&" "&M19
L20: {=INDEX(z_3_Materias!B2:B508, MATCH(H20, z_3_Materias!A2:A508, 0))} -> 0 | N20: {=INDEX(z_3_Materias!D2:D508, MATCH(H20, z_3_Materias!A2:A508, 0))} -> 0 | T20: =H20&" "&M20
L21: {=INDEX(z_3_Materias!B2:B508, MATCH(H21, z_3_Materias!A2:A508, 0))} -> 0 | N21: {=INDEX(z_3_Materias!D2:D508, MATCH(H21, z_3_Materias!A2:A508, 0))} -> 0 | T21: =H21&" "&M21
L22: {=INDEX(z_3_Materias!B2:B508, MATCH(H22, z_3_Materias!A2:A508, 0))} -> 0 | N22: {=INDEX(z_3_Materias!D2:D508, MATCH(H22, z_3_Materias!A2:A508, 0))} -> 0 | T22: =H22&" "&M22
L23: {=INDEX(z_3_Materias!B2:B508, MATCH(H23, z_3_Materias!A2:A508, 0))} -> 0 | N23: {=INDEX(z_3_Materias!D2:D508, MATCH(H23, z_3_Materias!A2:A508, 0))} -> 0 | T23: =H23&" "&M23
B25: HORARIO SEMANAL*11)
B26: DISTRIBUCIÓN DE HORAS | H26: LUNES | J26: MARTES | L26: MIERCOLES | N26: JUEVES | P26: VIERNES | R26: SÁBADO
B27: 07:00 A 08:00
B28: 08:00 A 09:00
B29: 09:00 A 10:00
B30: 10:00 A 11:00
B31: 11:00 A 12:00
B32: 12:00 A 13:00
B33: 13:00 A 14:00
B34: 14:00 A 15:00
B35: 15:00 A 16:00
B36: 16:00 A 17:00
B37: 17:00 A 18:00
B38: 18:00 A 19:00
... B41: 21:00 A 22:00
C46: MTRO. OLIVER RAÚL VELÁZQUEZ TORRES | N46: =B10 -> IBARRA VAZQUEZ JESSICA DANIELA
C47: NOMBRE Y FIRMA DEL DIRECTOR ACADÉMICO | N47: NOMBRE Y FIRMA DE LA PROFESORA O PROFESOR

Sheet INFANTE DE LA FUENTE JUAN GABRI
B1: UNIVERSIDAD TECNOLÓGICA FIDEL VELÁZQUEZ
B2: SECRETARÍA ACADÉMICA
B3: CARGA HORARIA PROFESOR DE ASIGNATURA
I5: NOMBRE DE LA DIVISIÓN: TELEMÁTICA
I6: PERIODO CUATRIMESTRAL: (MAYO - AGOSTO 2025) 2025-2
I7: VIGENCIA APARTIR DE: 01/05/2025 AL 30/08/2025
B10: INFANTE DE LA FUENTE JUAN GABRIEL | N10: MAESTRÍA
B11: NOMBRE DE LA PROFESORA O PROFESOR | N11: PROFESIÓN Y GRADO MÁXIMO DE ESTUDIOS
B13: DISTRIBUCIÓN DE HORAS AL CUATRIMESTRE
B14: DOCENCIA | D14: FRENTE A GRUPO | H14: ASIGNATURA | L14: CLAVE | M14: GRUPO | N14: HORAS/SEMANA/MES | R14: HORAS TOTALES POR SEMANA**
T15: =H15&" "&M15
T16: =H16&" "&M16
T17: =H17&" "&M17
T18: =H18&" "&M18
L19: {=INDEX(z_3_Materias!B2:B508, MATCH(H19, z_3_Materias!A2:A508, 0))} -> 0 | T19: =H19&" "&M19
L20: {=INDEX(z_3_Materias!B2:B508, MATCH(H20, z_3_Materias!A2:A508, 0))} -> 0 | N20: {=INDEX(z_3_Materias!D2:D508, MATCH(H20, z_3_Materias!A2:A508, 0))} -> 0 | T20: =H20&" "&M20
L21: {=INDEX(z_3_Materias!B2:B508, MATCH(H21, z_3_Materias!A2:A508, 0))} -> 0 | N21: {=INDEX(z_3_Materias!D2:D508, MATCH(H21, z_3_Materias!A2:A508, 0))} -> 0 | T21: =H21&" "&M21
L22: {=INDEX(z_3_Materias!B2:B508, MATCH(H22, z_3_Materias!A2:A508, 0))} -> 0 | N22: {=INDEX(z_3_Materias!D2:D508, MATCH(H22, z_3_Materias!A2:A508, 0))} -> 0 | T22: =H22&" "&M22
L23: {=INDEX(z_3_Materias!B2:B508, MATCH(H23, z_3_Materias!A2:A508, 0))} -> 0 | N23: {=INDEX(z_3_Materias!D2:D508, MATCH(H23, z_3_Materias!A2:A508, 0))} -> 0 | T23: =H23&" "&M23
B25: HORARIO SEMANAL*11)
B26: DISTRIBUCIÓN DE HORAS | H26: LUNES | J26: MARTES | L26: MIERCOLES | N26: JUEVES | P26: VIERNES | R26: SÁBADO
B27: 07:00 A 08:00
B28: 08:00 A 09:00
B29: 09:00 A 10:00
B30: 10:00 A 11:00
B31: 11:00 A 12:00
B32: 12:00 A 13:00
B33: 13:00 A 14:00
B34: 14:00 A 15:00
B35: 15:00 A 16:00
B36: 16:00 A 17:00
B37: 17:00 A 18:00
B38: 18:00 A 19:00
... B41: 21:00 A 22:00
C44: ING. OSCAR ARMANDO BAEZA HUICOCHEA
C45: NOMBRE Y FIRMA DEL DIRECTOR ACADÉMICO
N46: =B10 -> INFANTE DE LA FUENTE JUAN GABRIEL
C47: MTRO. OLIVER RAÚL VELÁZQUEZ TORRES | N47: NOMBRE Y FIRMA DE LA PROFESORA O PROFESOR
C48: NOMBRE Y FIRMA DEL DIRECTOR ACADÉMICO

Sheet ISLAS GONZALEZ YUNUEN
B1: UNIVERSIDAD TECNOLÓGICA FIDEL VELÁZQUEZ
B2: SECRETARÍA ACADÉMICA
B3: CARGA HORARIA PROFESOR DE ASIGNATURA
I5: NOMBRE DE LA DIVISIÓN: TELEMÁTICA
I6: PERIODO CUATRIMESTRAL: (MAYO - AGOSTO 2025) 2025-2
I7: VIGENCIA APARTIR DE: 01/05/2025 AL 30/08/2025
B10: ISLAS GONZALEZ YUNUEN | N10: LICENCIATURA
B11: NOMBRE DE LA PROFESORA O PROFESOR | N11: PROFESIÓN Y GRADO MÁXIMO DE ESTUDIOS
B13: DISTRIBUCIÓN DE HORAS AL CUATRIMESTRE
B14: DOCENCIA | D14: FRENTE A GRUPO | H14: ASIGNATURA | L14: CLAVE | M14: GRUPO | N14: HORAS/SEMANA/MES | R14: HORAS TOTALES POR SEMANA**
L15: {=INDEX(z_3_Materias!B2:B508, MATCH(H15, z_3_Materias!A2:A508, 0))} -> 0 | N15: {=INDEX(z_3_Materias!D2:D508, MATCH(H15, z_3_Materias!A2:A508, 0))} -> 0 | R15: =SUM(N15:Q23) -> 0 | T15: =H15&" "&M15
L16: {=INDEX(z_3_Materias!B2:B508, MATCH(H16, z_3_Materias!A2:A508, 0))} -> 0 | N16: {=INDEX(z_3_Materias!D2:D508, MATCH(H16, z_3_Materias!A2:A508, 0))} -> 0 | T16: =H16&" "&M16
L17: {=INDEX(z_3_Materias!B2:B508, MATCH(H17, z_3_Materias!A2:A508, 0))} -> 0 | N17: {=INDEX(z_3_Materias!D2:D508, MATCH(H17, z_3_Materias!A2:A508, 0))} -> 0 | T17: =H17&" "&M17
L18: {=INDEX(z_3_Materias!B2:B508, MATCH(H18, z_3_Materias!A2:A508, 0))} -> 0 | N18: {=INDEX(z_3_Materias!D2:D508, MATCH(H18, z_3_Materias!A2:A508, 0))} -> 0 | T18: =H18&" "&M18
L19: {=INDEX(z_3_Materias!B2:B508, MATCH(H19, z_3_Materias!A2:A508, 0))} -> 0 | N19: {=INDEX(z_3_Materias!D2:D508, MATCH(H19, z_3_Materias!A2:A508, 0))} -> 0 | T19: =H19&" "&M19
L20: {=INDEX(z_3_Materias!B2:B508, MATCH(H20, z_3_Materias!A2:A508, 0))} -> 0 | N20: {=INDEX(z_3_Materias!D2:D508, MATCH(H20, z_3_Materias!A2:A508, 0))} -> 0 | T20: =H20&" "&M20
L21: {=INDEX(z_3_Materias!B2:B508, MATCH(H21, z_3_Materias!A2:A508, 0))} -> 0 | N21: {=INDEX(z_3_Materias!D2:D508, MATCH(H21, z_3_Materias!A2:A508, 0))} -> 0 | T21: =H21&" "&M21
L22: {=INDEX(z_3_Materias!B2:B508, MATCH(H22, z_3_Materias!A2:A508, 0))} -> 0 | N22: {=INDEX(z_3_Materias!D2:D508, MATCH(H22, z_3_Materias!A2:A508, 0))} -> 0 | T22: =H22&" "&M22
L23: {=INDEX(z_3_Materias!B2:B508, MATCH(H23, z_3_Materias!A2:A508, 0))} -> 0 | N23: {=INDEX(z_3_Materias!D2:D508, MATCH(H23, z_3_Materias!A2:A508, 0))} -> 0 | T23: =H23&" "&M23
B25: HORARIO SEMANAL*11)
B26: DISTRIBUCIÓN DE HORAS | H26: LUNES | J26: MARTES | L26: MIERCOLES | N26: JUEVES | P26: VIERNES | R26: SÁBADO
B27: 07:00 A 08:00
B28: 08:00 A 09:00
B29: 09:00 A 10:00
B30: 10:00 A 11:00
B31: 11:00 A 12:00
B32: 12:00 A 13:00
B33: 13:00 A 14:00
B34: 14:00 A 15:00
B35: 15:00 A 16:00
B36: 16:00 A 17:00
B37: 17:00 A 18:00
B38: 18:00 A 19:00
... B41: 21:00 A 22:00
C46: MTRO. OLIVER RAÚL VELÁZQUEZ TORRES | N46: =B10 -> ISLAS GONZALEZ YUNUEN
C47: NOMBRE Y FIRMA DEL DIRECTOR ACADÉMICO | N47: NOMBRE Y FIRMA DE LA PROFESORA O PROFESOR

Sheet LANDIN HERREJON JOSE LUIS GUSTA
B1: UNIVERSIDAD TECNOLÓGICA FIDEL VELÁZQUEZ
B2: SECRETARÍA ACADÉMICA
B3: CARGA HORARIA PROFESOR DE ASIGNATURA
I5: NOMBRE DE LA DIVISIÓN: TELEMÁTICA
I6: PERIODO CUATRIMESTRAL: (MAYO - AGOSTO 2025) 2025-2
I7: VIGENCIA APARTIR DE: 01/05/2025 AL 30/08/2025
B10: LANDIN HERREJON JOSE LUIS GUSTAVO | N10: MAESTRÍA
B11: NOMBRE DE LA PROFESORA O PROFESOR | N11: PROFESIÓN Y GRADO MÁXIMO DE ESTUDIOS
B13: DISTRIBUCIÓN DE HORAS AL CUATRIMESTRE
B14: DOCENCIA | D14: FRENTE A GRUPO | H14: ASIGNATURA | L14: CLAVE | M14: GRUPO | N14: HORAS/SEMANA/MES | R14: HORAS TOTALES POR SEMANA**
L15: {=INDEX(z_3_Materias!B2:B508, MATCH(H15, z_3_Materias!A2:A508, 0))} -> 0 | N15: {=INDEX(z_3_Materias!D2:D508, MATCH(H15, z_3_Materias!A2:A508, 0))} -> 0 | R15: =SUM(N15:Q23) -> 0 | T15: =H15&" "&M15
L16: {=INDEX(z_3_Materias!B2:B508, MATCH(H16, z_3_Materias!A2:A508, 0))} -> 0 | N16: {=INDEX(z_3_Materias!D2:D508, MATCH(H16, z_3_Materias!A2:A508, 0))} -> 0 | T16: =H16&" "&M16
L17: {=INDEX(z_3_Materias!B2:B508, MATCH(H17, z_3_Materias!A2:A508, 0))} -> 0 | N17: {=INDEX(z_3_Materias!D2:D508, MATCH(H17, z_3_Materias!A2:A508, 0))} -> 0 | T17: =H17&" "&M17
L18: {=INDEX(z_3_Materias!B2:B508, MATCH(H18, z_3_Materias!A2:A508, 0))} -> 0 | N18: {=INDEX(z_3_Materias!D2:D508, MATCH(H18, z_3_Materias!A2:A508, 0))} -> 0 | T18: =H18&" "&M18
L19: {=INDEX(z_3_Materias!B2:B508, MATCH(H19, z_3_Materias!A2:A508, 0))} -> 0 | N19: {=INDEX(z_3_Materias!D2:D508, MATCH(H19, z_3_Materias!A2:A508, 0))} -> 0 | T19: =H19&" "&M19
L20: {=INDEX(z_3_Materias!B2:B508, MATCH(H20, z_3_Materias!A2:A508, 0))} -> 0 | N20: {=INDEX(z_3_Materias!D2:D508, MATCH(H20, z_3_Materias!A2:A508, 0))} -> 0 | T20: =H20&" "&M20
L21: {=INDEX(z_3_Materias!B2:B508, MATCH(H21, z_3_Materias!A2:A508, 0))} -> 0 | N21: {=INDEX(z_3_Materias!D2:D508, MATCH(H21, z_3_Materias!A2:A508, 0))} -> 0 | T21: =H21&" "&M21
L22: {=INDEX(z_3_Materias!B2:B508, MATCH(H22, z_3_Materias!A2:A508, 0))} -> 0 | N22: {=INDEX(z_3_Materias!D2:D508, MATCH(H22, z_3_Materias!A2:A508, 0))} -> 0 | T22: =H22&" "&M22
L23: {=INDEX(z_3_Materias!B2:B508, MATCH(H23, z_3_Materias!A2:A508, 0))} -> 0 | N23: {=INDEX(z_3_Materias!D2:D508, MATCH(H23, z_3_Materias!A2:A508, 0))} -> 0 | T23: =H23&" "&M23
B25: HORARIO SEMANAL*11)
B26: DISTRIBUCIÓN DE HORAS | H26: LUNES | J26: MARTES | L26: MIERCOLES | N26: JUEVES | P26: VIERNES | R26: SÁBADO
B27: 07:00 A 08:00
B28: 08:00 A 09:00
B29: 09:00 A 10:00
B30: 10:00 A 11:00
B31: 11:00 A 12:00
B32: 12:00 A 13:00
B33: 13:00 A 14:00
B34: 14:00 A 15:00
B35: 15:00 A 16:00
B36: 16:00 A 17:00
B37: 17:00 A 18:00
B38: 18:00 A 19:00
... B41: 21:00 A 22:00
C46: MTRO. OLIVER RAÚL VELÁZQUEZ TORRES | N46: =B10 -> LANDIN HERREJON JOSE LUIS GUSTAVO
C47: NOMBRE Y FIRMA DEL DIRECTOR ACADÉMICO | N47: NOMBRE Y FIRMA DE LA PROFESORA O PROFESOR

Sheet LIMA ARRONA FERNANDO
B1: UNIVERSIDAD TECNOLÓGICA FIDEL VELÁZQUEZ
B2: SECRETARÍA ACADÉMICA
B3: CARGA HORARIA PROFESOR DE ASIGNATURA
I5: NOMBRE DE LA DIVISIÓN: TELEMÁTICA
I6: PERIODO CUATRIMESTRAL: (MAYO - AGOSTO 2025) 2025-2
I7: VIGENCIA APARTIR DE: 01/05/2025 AL 30/08/2025
B10: LIMA ARRONA FERNANDO | N10: MAESTRÍA
B11: NOMBRE DE LA PROFESORA O PROFESOR | N11: PROFESIÓN Y GRADO MÁXIMO DE ESTUDIOS
B13: DISTRIBUCIÓN DE HORAS AL CUATRIMESTRE
B14: DOCENCIA | D14: FRENTE A GRUPO | H14: ASIGNATURA | L14: CLAVE | M14: GRUPO | N14: HORAS/SEMANA/MES | R14: HORAS TOTALES POR SEMANA**
H15: Procesamiento de Datos* | L15: {=INDEX(z_3_Materias!B2:B508, MATCH(H15, z_3_Materias!A2:A508, 0))} -> 24CD019 | M15: CD301 | N15: {=INDEX(z_3_Materias!D2:D508, MATCH(H15, z_3_Materias!A2:A508, 0))} -> 6 | R15: =SUM(N15:Q23) -> 20 | T15: =H15&" "&M15 -> Procesamiento de Datos* CD301
H16: Programación Orientada a Objetos_ | L16: {=INDEX(z_3_Materias!B2:B508, MATCH(H16, z_3_Materias!A2:A508, 0))} -> 24IRD020 | M16: IRD301 | N16: {=INDEX(z_3_Materias!D2:D508, MATCH(H16, z_3_Materias!A2:A508, 0))} -> 7 | T16: =H16&" "&M16 -> Programación Orientada a Objetos_ IRD301
H17: Programación Orientada a Objetos_ | L17: {=INDEX(z_3_Materias!B2:B508, MATCH(H17, z_3_Materias!A2:A508, 0))} -> 24IRD020 | M17: IRD302 | N17: {=INDEX(z_3_Materias!D2:D508, MATCH(H17, z_3_Materias!A2:A508, 0))} -> 7 | T17: =H17&" "&M17 -> Programación Orientada a Objetos_ IRD302
L18: {=INDEX(z_3_Materias!B2:B508, MATCH(H18, z_3_Materias!A2:A508, 0))} -> 0 | N18: {=INDEX(z_3_Materias!D2:D508, MATCH(H18, z_3_Materias!A2:A508, 0))} -> 0 | T18: =H18&" "&M18
L19: {=INDEX(z_3_Materias!B2:B508, MATCH(H19, z_3_Materias!A2:A508, 0))} -> 0 | N19: {=INDEX(z_3_Materias!D2:D508, MATCH(H19, z_3_Materias!A2:A508, 0))} -> 0 | T19: =H19&" "&M19
L20: {=INDEX(z_3_Materias!B2:B508, MATCH(H20, z_3_Materias!A2:A508, 0))} -> 0 | N20: {=INDEX(z_3_Materias!D2:D508, MATCH(H20, z_3_Materias!A2:A508, 0))} -> 0 | T20: =H20&" "&M20
L21: {=INDEX(z_3_Materias!B2:B508, MATCH(H21, z_3_Materias!A2:A508, 0))} -> 0 | N21: {=INDEX(z_3_Materias!D2:D508, MATCH(H21, z_3_Materias!A2:A508, 0))} -> 0 | T21: =H21&" "&M21
L22: {=INDEX(z_3_Materias!B2:B508, MATCH(H22, z_3_Materias!A2:A508, 0))} -> 0 | N22: {=INDEX(z_3_Materias!D2:D508, MATCH(H22, z_3_Materias!A2:A508, 0))} -> 0 | T22: =H22&" "&M22
L23: {=INDEX(z_3_Materias!B2:B508, MATCH(H23, z_3_Materias!A2:A508, 0))} -> 0 | N23: {=INDEX(z_3_Materias!D2:D508, MATCH(H23, z_3_Materias!A2:A508, 0))} -> 0 | T23: =H23&" "&M23
B25: HORARIO SEMANAL*11)
B26: DISTRIBUCIÓN DE HORAS | H26: LUNES | J26: MARTES | L26: MIERCOLES | N26: JUEVES | P26: VIERNES | R26: SÁBADO
B27: 07:00 A 08:00 | H27: Programación Orientada a Objetos_ IRD302 | J27: Programación Orientada a Objetos_ IRD301 | L27: Programación Orientada a Objetos_ IRD302
B28: 08:00 A 09:00 | H28: Programación Orientada a Objetos_ IRD302 | J28: Programación Orientada a Objetos_ IRD301 | L28: Programación Orientada a Objetos_ IRD302
B29: 09:00 A 10:00 | H29: Programación Orientada a Objetos_ IRD301 | J29: Programación Orientada a Objetos_ IRD301 | L29: Programación Orientada a Objetos_ IRD302 | N29: Programación Orientada a Objetos_ IRD302 | P29: Programación Orientada a Objetos_ IRD301
B30: 10:00 A 11:00 | H30: Programación Orientada a Objetos_ IRD301 | N30: Programación Orientada a Objetos_ IRD302 | P30: Programación Orientada a Objetos_ IRD301
B31: 11:00 A 12:00 | H31: Procesamiento de Datos* CD301 | N31: Procesamiento de Datos* CD301 | P31: Procesamiento de Datos* CD301
B32: 12:00 A 13:00 | H32: Procesamiento de Datos* CD301 | N32: Procesamiento de Datos* CD301 | P32: Procesamiento de Datos* CD301
B33: 13:00 A 14:00
B34: 14:00 A 15:00
B35: 15:00 A 16:00
B36: 16:00 A 17:00
B37: 17:00 A 18:00
B38: 18:00 A 19:00
B39: 19:00 A 20:00
B40: 20:00 A 21:00
B41: 21:00 A 22:00
C46: MTRO. OLIVER RAÚL VELÁZQUEZ TORRES | N46: =B10 -> LIMA ARRONA FERNANDO
C47: NOMBRE Y FIRMA DEL DIRECTOR ACADÉMICO | N47: NOMBRE Y FIRMA DE LA PROFESORA O PROFESOR

Sheet MALDONADO GUERRERO ALHAN GERARD
B1: UNIVERSIDAD TECNOLÓGICA FIDEL VELÁZQUEZ
B2: SECRETARÍA ACADÉMICA
B3: CARGA HORARIA PROFESOR DE ASIGNATURA
I5: NOMBRE DE LA DIVISIÓN: TELEMÁTICA
I6: PERIODO CUATRIMESTRAL: (MAYO - AGOSTO 2025) 2025-2
I7: VIGENCIA APARTIR DE: 01/05/2025 AL 30/08/2025
B10: MALDONADO GUERRERO ALHAN GERARD | N10: MAESTRÍA
B11: NOMBRE DE LA PROFESORA O PROFESOR | N11: PROFESIÓN Y GRADO MÁXIMO DE ESTUDIOS
B13: DISTRIBUCIÓN DE HORAS AL CUATRIMESTRE
B14: DOCENCIA | D14: FRENTE A GRUPO | H14: ASIGNATURA | L14: CLAVE | M14: GRUPO | N14: HORAS/SEMANA/MES | R14: HORAS TOTALES POR SEMANA**
L15: {=INDEX(z_3_Materias!B2:B508, MATCH(H15, z_3_Materias!A2:A508, 0))} -> 0 | N15: {=INDEX(z_3_Materias!D2:D508, MATCH(H15, z_3_Materias!A2:A508, 0))} -> 0 | R15: =SUM(N15:Q23) -> 0 | T15: =H15&" "&M15
L16: {=INDEX(z_3_Materias!B2:B508, MATCH(H16, z_3_Materias!A2:A508, 0))} -> 0 | N16: {=INDEX(z_3_Materias!D2:D508, MATCH(H16, z_3_Materias!A2:A508, 0))} -> 0 | T16: =H16&" "&M16
L17: {=INDEX(z_3_Materias!B2:B508, MATCH(H17, z_3_Materias!A2:A508, 0))} -> 0 | N17: {=INDEX(z_3_Materias!D2:D508, MATCH(H17, z_3_Materias!A2:A508, 0))} -> 0 | T17: =H17&" "&M17
L18: {=INDEX(z_3_Materias!B2:B508, MATCH(H18, z_3_Materias!A2:A508, 0))} -> 0 | N18: {=INDEX(z_3_Materias!D2:D508, MATCH(H18, z_3_Materias!A2:A508, 0))} -> 0 | T18: =H18&" "&M18
L19: {=INDEX(z_3_Materias!B2:B508, MATCH(H19, z_3_Materias!A2:A508, 0))} -> 0 | N19: {=INDEX(z_3_Materias!D2:D508, MATCH(H19, z_3_Materias!A2:A508, 0))} -> 0 | T19: =H19&" "&M19
L20: {=INDEX(z_3_Materias!B2:B508, MATCH(H20, z_3_Materias!A2:A508, 0))} -> 0 | N20: {=INDEX(z_3_Materias!D2:D508, MATCH(H20, z_3_Materias!A2:A508, 0))} -> 0 | T20: =H20&" "&M20
L21: {=INDEX(z_3_Materias!B2:B508, MATCH(H21, z_3_Materias!A2:A508, 0))} -> 0 | N21: {=INDEX(z_3_Materias!D2:D508, MATCH(H21, z_3_Materias!A2:A508, 0))} -> 0 | T21: =H21&" "&M21
L22: {=INDEX(z_3_Materias!B2:B508, MATCH(H22, z_3_Materias!A2:A508, 0))} -> 0 | N22: {=INDEX(z_3_Materias!D2:D508, MATCH(H22, z_3_Materias!A2:A508, 0))} -> 0 | T22: =H22&" "&M22
L23: {=INDEX(z_3_Materias!B2:B508, MATCH(H23, z_3_Materias!A2:A508, 0))} -> 0 | N23: {=INDEX(z_3_Materias!D2:D508, MATCH(H23, z_3_Materias!A2:A508, 0))} -> 0 | T23: =H23&" "&M23
B25: HORARIO SEMANAL*11)
B26: DISTRIBUCIÓN DE HORAS | H26: LUNES | J26: MARTES | L26: MIERCOLES | N26: JUEVES | P26: VIERNES | R26: SÁBADO
B27: 07:00 A 08:00
B28: 08:00 A 09:00
B29: 09:00 A 10:00
B30: 10:00 A 11:00
B31: 11:00 A 12:00
B32: 12:00 A 13:00
B33: 13:00 A 14:00
B34: 14:00 A 15:00
B35: 15:00 A 16:00
B36: 16:00 A 17:00
B37: 17:00 A 18:00
B38: 18:00 A 19:00
... B41: 21:00 A 22:00
C46: MTRO. OLIVER RAÚL VELÁZQUEZ TORRES | N46: =B10 -> MALDONADO GUERRERO ALHAN GERARD
C47: NOMBRE Y FIRMA DEL DIRECTOR ACADÉMICO | N47: NOMBRE Y FIRMA DE LA PROFESORA O PROFESOR

Sheet MARTINEZ VEGA FERMIN
B1: UNIVERSIDAD TECNOLÓGICA FIDEL VELÁZQUEZ
B2: SECRETARÍA ACADÉMICA
B3: CARGA HORARIA PROFESOR DE ASIGNATURA
I5: NOMBRE DE LA DIVISIÓN: TELEMÁTICA
I6: PERIODO CUATRIMESTRAL: (MAYO - AGOSTO 2025) 2025-2
I7: VIGENCIA APARTIR DE: 01/05/2025 AL 30/08/2025
B10: MARTINEZ VEGA FERMIN | N10: MAESTRÍA
B11: NOMBRE DE LA PROFESORA O PROFESOR | N11: PROFESIÓN Y GRADO MÁXIMO DE ESTUDIOS
B13: DISTRIBUCIÓN DE HORAS AL CUATRIMESTRE
B14: DOCENCIA | D14: FRENTE A GRUPO | H14: ASIGNATURA | L14: CLAVE | M14: GRUPO | N14: HORAS/SEMANA/MES | R14: HORAS TOTALES POR SEMANA**
L15: {=INDEX(z_3_Materias!B2:B508, MATCH(H15, z_3_Materias!A2:A508, 0))} -> 0 | N15: {=INDEX(z_3_Materias!D2:D508, MATCH(H15, z_3_Materias!A2:A508, 0))} -> 0 | R15: =SUM(N15:Q23) -> 0 | T15: =H15&" "&M15
L16: {=INDEX(z_3_Materias!B2:B508, MATCH(H16, z_3_Materias!A2:A508, 0))} -> 0 | N16: {=INDEX(z_3_Materias!D2:D508, MATCH(H16, z_3_Materias!A2:A508, 0))} -> 0 | T16: =H16&" "&M16
L17: {=INDEX(z_3_Materias!B2:B508, MATCH(H17, z_3_Materias!A2:A508, 0))} -> 0 | N17: {=INDEX(z_3_Materias!D2:D508, MATCH(H17, z_3_Materias!A2:A508, 0))} -> 0 | T17: =H17&" "&M17
L18: {=INDEX(z_3_Materias!B2:B508, MATCH(H18, z_3_Materias!A2:A508, 0))} -> 0 | N18: {=INDEX(z_3_Materias!D2:D508, MATCH(H18, z_3_Materias!A2:A508, 0))} -> 0 | T18: =H18&" "&M18
L19: {=INDEX(z_3_Materias!B2:B508, MATCH(H19, z_3_Materias!A2:A508, 0))} -> 0 | N19: {=INDEX(z_3_Materias!D2:D508, MATCH(H19, z_3_Materias!A2:A508, 0))} -> 0 | T19: =H19&" "&M19
L20: {=INDEX(z_3_Materias!B2:B508, MATCH(H20, z_3_Materias!A2:A508, 0))} -> 0 | N20: {=INDEX(z_3_Materias!D2:D508, MATCH(H20, z_3_Materias!A2:A508, 0))} -> 0 | T20: =H20&" "&M20
L21: {=INDEX(z_3_Materias!B2:B508, MATCH(H21, z_3_Materias!A2:A508, 0))} -> 0 | N21: {=INDEX(z_3_Materias!D2:D508, MATCH(H21, z_3_Materias!A2:A508, 0))} -> 0 | T21: =H21&" "&M21
L22: {=INDEX(z_3_Materias!B2:B508, MATCH(H22, z_3_Materias!A2:A508, 0))} -> 0 | N22: {=INDEX(z_3_Materias!D2:D508, MATCH(H22, z_3_Materias!A2:A508, 0))} -> 0 | T22: =H22&" "&M22
L23: {=INDEX(z_3_Materias!B2:B508, MATCH(H23, z_3_Materias!A2:A508, 0))} -> 0 | N23: {=INDEX(z_3_Materias!D2:D508, MATCH(H23, z_3_Materias!A2:A508, 0))} -> 0 | T23: =H23&" "&M23
B25: HORARIO SEMANAL*11)
B26: DISTRIBUCIÓN DE HORAS | H26: LUNES | J26: MARTES | L26: MIERCOLES | N26: JUEVES | P26: VIERNES | R26: SÁBADO
B27: 07:00 A 08:00
B28: 08:00 A 09:00
B29: 09:00 A 10:00
B30: 10:00 A 11:00
B31: 11:00 A 12:00
B32: 12:00 A 13:00
B33: 13:00 A 14:00
B34: 14:00 A 15:00
B35: 15:00 A 16:00
B36: 16:00 A 17:00
B37: 17:00 A 18:00
B38: 18:00 A 19:00
... B41: 21:00 A 22:00
C46: MTRO. OLIVER RAÚL VELÁZQUEZ TORRES | N46: =B10 -> MARTINEZ VEGA FERMIN
C47: NOMBRE Y FIRMA DEL DIRECTOR ACADÉMICO | N47: NOMBRE Y FIRMA DE LA PROFESORA O PROFESOR

Sheet MENDOZA CALVA HECTOR RAUL
B1: UNIVERSIDAD TECNOLÓGICA FIDEL VELÁZQUEZ
B2: SECRETARÍA ACADÉMICA
B3: CARGA HORARIA PROFESOR DE ASIGNATURA
I5: NOMBRE DE LA DIVISIÓN: TELEMÁTICA
I6: PERIODO CUATRIMESTRAL: (MAYO - AGOSTO 2025) 2025-2
I7: VIGENCIA APARTIR DE: 01/05/2025 AL 30/08/2025
B10: MENDOZA CALVA HECTOR RAUL | N10: MAESTRÍA
B11: NOMBRE DE LA PROFESORA O PROFESOR | N11: PROFESIÓN Y GRADO MÁXIMO DE ESTUDIOS
B13: DISTRIBUCIÓN DE HORAS AL CUATRIMESTRE
B14: DOCENCIA | D14: FRENTE A GRUPO | H14: ASIGNATURA | L14: CLAVE | M14: GRUPO | N14: HORAS/SEMANA/MES | R14: HORAS TOTALES POR SEMANA**
L15: {=INDEX(z_3_Materias!B2:B508, MATCH(H15, z_3_Materias!A2:A508, 0))} -> 0 | N15: {=INDEX(z_3_Materias!D2:D508, MATCH(H15, z_3_Materias!A2:A508, 0))} -> 0 | R15: =SUM(N15:Q23) -> 0 | T15: =H15&" "&M15
L16: {=INDEX(z_3_Materias!B2:B508, MATCH(H16, z_3_Materias!A2:A508, 0))} -> 0 | N16: {=INDEX(z_3_Materias!D2:D508, MATCH(H16, z_3_Materias!A2:A508, 0))} -> 0 | T16: =H16&" "&M16
L17: {=INDEX(z_3_Materias!B2:B508, MATCH(H17, z_3_Materias!A2:A508, 0))} -> 0 | N17: {=INDEX(z_3_Materias!D2:D508, MATCH(H17, z_3_Materias!A2:A508, 0))} -> 0 | T17: =H17&" "&M17
L18: {=INDEX(z_3_Materias!B2:B508, MATCH(H18, z_3_Materias!A2:A508, 0))} -> 0 | T18: =H18&" "&M18
L19: {=INDEX(z_3_Materias!B2:B508, MATCH(H19, z_3_Materias!A2:A508, 0))} -> 0 | N19: {=INDEX(z_3_Materias!D2:D508, MATCH(H19, z_3_Materias!A2:A508, 0))} -> 0 | T19: =H19&" "&M19
L20: {=INDEX(z_3_Materias!B2:B508, MATCH(H20, z_3_Materias!A2:A508, 0))} -> 0 | N20: {=INDEX(z_3_Materias!D2:D508, MATCH(H20, z_3_Materias!A2:A508, 0))} -> 0 | T20: =H20&" "&M20
L21: {=INDEX(z_3_Materias!B2:B508, MATCH(H21, z_3_Materias!A2:A508, 0))} -> 0 | N21: {=INDEX(z_3_Materias!D2:D508, MATCH(H21, z_3_Materias!A2:A508, 0))} -> 0 | T21: =H21&" "&M21
L22: {=INDEX(z_3_Materias!B2:B508, MATCH(H22, z_3_Materias!A2:A508, 0))} -> 0 | N22: {=INDEX(z_3_Materias!D2:D508, MATCH(H22, z_3_Materias!A2:A508, 0))} -> 0 | T22: =H22&" "&M22
L23: {=INDEX(z_3_Materias!B2:B508, MATCH(H23, z_3_Materias!A2:A508, 0))} -> 0 | N23: {=INDEX(z_3_Materias!D2:D508, MATCH(H23, z_3_Materias!A2:A508, 0))} -> 0 | T23: =H23&" "&M23
B25: HORARIO SEMANAL*11)
B26: DISTRIBUCIÓN DE HORAS | H26: LUNES | J26: MARTES | L26: MIERCOLES | N26: JUEVES | P26: VIERNES | R26: SÁBADO
B27: 07:00 A 08:00
B28: 08:00 A 09:00
B29: 09:00 A 10:00
B30: 10:00 A 11:00
B31: 11:00 A 12:00
B32: 12:00 A 13:00
B33: 13:00 A 14:00
B34: 14:00 A 15:00
B35: 15:00 A 16:00
B36: 16:00 A 17:00
B37: 17:00 A 18:00
B38: 18:00 A 19:00
... B41: 21:00 A 22:00
C46: MTRO. OLIVER RAÚL VELÁZQUEZ TORRES | N46: =B10 -> MENDOZA CALVA HECTOR RAUL
C47: NOMBRE Y FIRMA DEL DIRECTOR ACADÉMICO | N47: NOMBRE Y FIRMA DE LA PROFESORA O PROFESOR

Sheet MONROY TREJO ALEJANDRO
B1: UNIVERSIDAD TECNOLÓGICA FIDEL VELÁZQUEZ
B2: SECRETARÍA ACADÉMICA
B3: CARGA HORARIA PROFESOR DE ASIGNATURA
I5: NOMBRE DE LA DIVISIÓN: TELEMÁTICA
I6: PERIODO CUATRIMESTRAL: (MAYO - AGOSTO 2025) 2025-2
I7: VIGENCIA APARTIR DE: 01/05/2025 AL 30/08/2025
B10: MONROY TREJO ALEJANDRO | N10: MAESTRÍA
B11: NOMBRE DE LA PROFESORA O PROFESOR | N11: PROFESIÓN Y GRADO MÁXIMO DE ESTUDIOS
B13: DISTRIBUCIÓN DE HORAS AL CUATRIMESTRE
B14: DOCENCIA | D14: FRENTE A GRUPO | H14: ASIGNATURA | L14: CLAVE | M14: GRUPO | N14: HORAS/SEMANA/MES | R14: HORAS TOTALES POR SEMANA**
L15: {=INDEX(z_3_Materias!B2:B508, MATCH(H15, z_3_Materias!A2:A508, 0))} -> 0 | N15: {=INDEX(z_3_Materias!D2:D508, MATCH(H15, z_3_Materias!A2:A508, 0))} -> 0 | R15: =SUM(N15:Q23) -> 0 | T15: =H15&" "&M15
L16: {=INDEX(z_3_Materias!B2:B508, MATCH(H16, z_3_Materias!A2:A508, 0))} -> 0 | N16: {=INDEX(z_3_Materias!D2:D508, MATCH(H16, z_3_Materias!A2:A508, 0))} -> 0 | T16: =H16&" "&M16
L17: {=INDEX(z_3_Materias!B2:B508, MATCH(H17, z_3_Materias!A2:A508, 0))} -> 0 | N17: {=INDEX(z_3_Materias!D2:D508, MATCH(H17, z_3_Materias!A2:A508, 0))} -> 0 | T17: =H17&" "&M17
L18: {=INDEX(z_3_Materias!B2:B508, MATCH(H18, z_3_Materias!A2:A508, 0))} -> 0 | N18: {=INDEX(z_3_Materias!D2:D508, MATCH(H18, z_3_Materias!A2:A508, 0))} -> 0 | T18: =H18&" "&M18
L19: {=INDEX(z_3_Materias!B2:B508, MATCH(H19, z_3_Materias!A2:A508, 0))} -> 0 | T19: =H19&" "&M19
L20: {=INDEX(z_3_Materias!B2:B508, MATCH(H20, z_3_Materias!A2:A508, 0))} -> 0 | N20: {=INDEX(z_3_Materias!D2:D508, MATCH(H20, z_3_Materias!A2:A508, 0))} -> 0 | T20: =H20&" "&M20
L21: {=INDEX(z_3_Materias!B2:B508, MATCH(H21, z_3_Materias!A2:A508, 0))} -> 0 | N21: {=INDEX(z_3_Materias!D2:D508, MATCH(H21, z_3_Materias!A2:A508, 0))} -> 0 | T21: =H21&" "&M21
L22: {=INDEX(z_3_Materias!B2:B508, MATCH(H22, z_3_Materias!A2:A508, 0))} -> 0 | N22: {=INDEX(z_3_Materias!D2:D508, MATCH(H22, z_3_Materias!A2:A508, 0))} -> 0 | T22: =H22&" "&M22
L23: {=INDEX(z_3_Materias!B2:B508, MATCH(H23, z_3_Materias!A2:A508, 0))} -> 0 | N23: {=INDEX(z_3_Materias!D2:D508, MATCH(H23, z_3_Materias!A2:A508, 0))} -> 0 | T23: =H23&" "&M23
B25: HORARIO SEMANAL*11)
B26: DISTRIBUCIÓN DE HORAS | H26: LUNES | J26: MARTES | L26: MIERCOLES | N26: JUEVES | P26: VIERNES | R26: SÁBADO
B27: 07:00 A 08:00
B28: 08:00 A 09:00
B29: 09:00 A 10:00
B30: 10:00 A 11:00
B31: 11:00 A 12:00
B32: 12:00 A 13:00
B33: 13:00 A 14:00
B34: 14:00 A 15:00
B35: 15:00 A 16:00
B36: 16:00 A 17:00
B37: 17:00 A 18:00
B38: 18:00 A 19:00
... B41: 21:00 A 22:00
C46: MTRO. OLIVER RAÚL VELÁZQUEZ TORRES | N46: =B10 -> MONROY TREJO ALEJANDRO
C47: NOMBRE Y FIRMA DEL DIRECTOR ACADÉMICO | N47: NOMBRE Y FIRMA DE LA PROFESORA O PROFESOR
C50: MTRO. OSCAR ARMANDO BAEZA HUICOCHEA
C51: NOMBRE Y FIRMA DEL DIRECTOR ACADÉMICO

Sheet MURGUIA GONZALEZ CYNTHIA BEATRI
B1: UNIVERSIDAD TECNOLÓGICA FIDEL VELÁZQUEZ
B2: SECRETARÍA ACADÉMICA
B3: CARGA HORARIA PROFESOR DE ASIGNATURA
I5: NOMBRE DE LA DIVISIÓN: TELEMÁTICA
I6: PERIODO CUATRIMESTRAL: (MAYO - AGOSTO 2025) 2025-2
I7: VIGENCIA APARTIR DE: 01/05/2025 AL 30/08/2025
B10: MURGUIA GONZALEZ CYNTHIA BEATRIZ | N10: MAESTRÍA
B11: NOMBRE DE LA PROFESORA O PROFESOR | N11: PROFESIÓN Y GRADO MÁXIMO DE ESTUDIOS
B13: DISTRIBUCIÓN DE HORAS AL CUATRIMESTRE
B14: DOCENCIA | D14: FRENTE A GRUPO | H14: ASIGNATURA | L14: CLAVE | M14: GRUPO | N14: HORAS/SEMANA/MES | R14: HORAS TOTALES POR SEMANA**
L15: {=INDEX(z_3_Materias!B2:B508, MATCH(H15, z_3_Materias!A2:A508, 0))} -> 0 | N15: {=INDEX(z_3_Materias!D2:D508, MATCH(H15, z_3_Materias!A2:A508, 0))} -> 0 | R15: =SUM(N15:Q23) -> 0 | T15: =H15&" "&M15
L16: {=INDEX(z_3_Materias!B2:B508, MATCH(H16, z_3_Materias!A2:A508, 0))} -> 0 | N16: {=INDEX(z_3_Materias!D2:D508, MATCH(H16, z_3_Materias!A2:A508, 0))} -> 0 | T16: =H16&" "&M16
L17: {=INDEX(z_3_Materias!B2:B508, MATCH(H17, z_3_Materias!A2:A508, 0))} -> 0 | N17: {=INDEX(z_3_Materias!D2:D508, MATCH(H17, z_3_Materias!A2:A508, 0))} -> 0 | T17: =H17&" "&M17
L18: {=INDEX(z_3_Materias!B2:B508, MATCH(H18, z_3_Materias!A2:A508, 0))} -> 0 | N18: {=INDEX(z_3_Materias!D2:D508, MATCH(H18, z_3_Materias!A2:A508, 0))} -> 0 | T18: =H18&" "&M18
L19: {=INDEX(z_3_Materias!B2:B508, MATCH(H19, z_3_Materias!A2:A508, 0))} -> 0 | N19: {=INDEX(z_3_Materias!D2:D508, MATCH(H19, z_3_Materias!A2:A508, 0))} -> 0 | T19: =H19&" "&M19
L20: {=INDEX(z_3_Materias!B2:B508, MATCH(H20, z_3_Materias!A2:A508, 0))} -> 0 | N20: {=INDEX(z_3_Materias!D2:D508, MATCH(H20, z_3_Materias!A2:A508, 0))} -> 0 | T20: =H20&" "&M20
L21: {=INDEX(z_3_Materias!B2:B508, MATCH(H21, z_3_Materias!A2:A508, 0))} -> 0 | N21: {=INDEX(z_3_Materias!D2:D508, MATCH(H21, z_3_Materias!A2:A508, 0))} -> 0 | T21: =H21&" "&M21
L22: {=INDEX(z_3_Materias!B2:B508, MATCH(H22, z_3_Materias!A2:A508, 0))} -> 0 | N22: {=INDEX(z_3_Materias!D2:D508, MATCH(H22, z_3_Materias!A2:A508, 0))} -> 0 | T22: =H22&" "&M22
L23: {=INDEX(z_3_Materias!B2:B508, MATCH(H23, z_3_Materias!A2:A508, 0))} -> 0 | N23: {=INDEX(z_3_Materias!D2:D508, MATCH(H23, z_3_Materias!A2:A508, 0))} -> 0 | T23: =H23&" "&M23
B25: HORARIO SEMANAL*11)
B26: DISTRIBUCIÓN DE HORAS | H26: LUNES | J26: MARTES | L26: MIERCOLES | N26: JUEVES | P26: VIERNES | R26: SÁBADO
B27: 07:00 A 08:00
B28: 08:00 A 09:00
B29: 09:00 A 10:00
B30: 10:00 A 11:00
B31: 11:00 A 12:00
B32: 12:00 A 13:00
B33: 13:00 A 14:00
B34: 14:00 A 15:00
B35: 15:00 A 16:00
B36: 16:00 A 17:00
B37: 17:00 A 18:00
B38: 18:00 A 19:00
... B41: 21:00 A 22:00
C46: MTRO. OLIVER RAÚL VELÁZQUEZ TORRES | N46: =B10 -> MURGUIA GONZALEZ CYNTHIA BEATRIZ
C47: NOMBRE Y FIRMA DEL DIRECTOR ACADÉMICO | N47: NOMBRE Y FIRMA DE LA PROFESORA O PROFESOR

Sheet OLMOS OLALDE VICTOR HUGO
B1: UNIVERSIDAD TECNOLÓGICA FIDEL VELÁZQUEZ
B2: SECRETARÍA ACADÉMICA
B3: CARGA HORARIA PROFESOR DE ASIGNATURA
I5: NOMBRE DE LA DIVISIÓN: TELEMÁTICA
I6: PERIODO CUATRIMESTRAL: (MAYO - AGOSTO 2025) 2025-2
I7: VIGENCIA APARTIR DE: 01/05/2025 AL 30/08/2025
B10: OLMOS OLALDE VICTOR HUGO | N10: MAESTRÍA
B11: NOMBRE DE LA PROFESORA O PROFESOR | N11: PROFESIÓN Y GRADO MÁXIMO DE ESTUDIOS
B13: DISTRIBUCIÓN DE HORAS AL CUATRIMESTRE
B14: DOCENCIA | D14: FRENTE A GRUPO | H14: ASIGNATURA | L14: CLAVE | M14: GRUPO | N14: HORAS/SEMANA/MES | R14: HORAS TOTALES POR SEMANA**
H15: Desarrollo del Pensamiento y Toma de Decisiones* | L15: {=INDEX(z_3_Materias!B2:B508, MATCH(H15, z_3_Materias!A2:A508, 0))} -> 24CD016 | M15: CD301 | N15: {=INDEX(z_3_Materias!D2:D508, MATCH(H15, z_3_Materias!A2:A508, 0))} -> 4 | R15: =SUM(N15:Q23) -> 12 | T15: =H15&" "&M15 -> Desarrollo del Pensamiento y Toma de Decisiones* CD301
H16: Desarrollo del Pensamiento y Toma de Decisiones_ | L16: {=INDEX(z_3_Materias!B2:B508, MATCH(H16, z_3_Materias!A2:A508, 0))} -> 24IRD016 | M16: IRD301 | N16: {=INDEX(z_3_Materias!D2:D508, MATCH(H16, z_3_Materias!A2:A508, 0))} -> 4 | T16: =H16&" "&M16 -> Desarrollo del Pensamiento y Toma de Decisiones_ IRD301
H17: Desarrollo del Pensamiento y Toma de Decisiones_ | L17: {=INDEX(z_3_Materias!B2:B508, MATCH(H17, z_3_Materias!A2:A508, 0))} -> 24IRD016 | M17: IRD302 | N17: {=INDEX(z_3_Materias!D2:D508, MATCH(H17, z_3_Materias!A2:A508, 0))} -> 4 | T17: =H17&" "&M17 -> Desarrollo del Pensamiento y Toma de Decisiones_ IRD302
L18: {=INDEX(z_3_Materias!B2:B508, MATCH(H18, z_3_Materias!A2:A508, 0))} -> 0 | N18: {=INDEX(z_3_Materias!D2:D508, MATCH(H18, z_3_Materias!A2:A508, 0))} -> 0 | T18: =H18&" "&M18
L19: {=INDEX(z_3_Materias!B2:B508, MATCH(H19, z_3_Materias!A2:A508, 0))} -> 0 | N19: {=INDEX(z_3_Materias!D2:D508, MATCH(H19, z_3_Materias!A2:A508, 0))} -> 0 | T19: =H19&" "&M19
L20: {=INDEX(z_3_Materias!B2:B508, MATCH(H20, z_3_Materias!A2:A508, 0))} -> 0 | N20: {=INDEX(z_3_Materias!D2:D508, MATCH(H20, z_3_Materias!A2:A508, 0))} -> 0 | T20: =H20&" "&M20
L21: {=INDEX(z_3_Materias!B2:B508, MATCH(H21, z_3_Materias!A2:A508, 0))} -> 0 | N21: {=INDEX(z_3_Materias!D2:D508, MATCH(H21, z_3_Materias!A2:A508, 0))} -> 0 | T21: =H21&" "&M21
L22: {=INDEX(z_3_Materias!B2:B508, MATCH(H22, z_3_Materias!A2:A508, 0))} -> 0 | N22: {=INDEX(z_3_Materias!D2:D508, MATCH(H22, z_3_Materias!A2:A508, 0))} -> 0 | T22: =H22&" "&M22
L23: {=INDEX(z_3_Materias!B2:B508, MATCH(H23, z_3_Materias!A2:A508, 0))} -> 0 | N23: {=INDEX(z_3_Materias!D2:D508, MATCH(H23, z_3_Materias!A2:A508, 0))} -> 0 | T23: =H23&" "&M23
B25: HORARIO SEMANAL*11)
B26: DISTRIBUCIÓN DE HORAS | H26: LUNES | J26: MARTES | L26: MIERCOLES | N26: JUEVES | P26: VIERNES | R26: SÁBADO
B27: 07:00 A 08:00 | H27: Desarrollo del Pensamiento y Toma de Decisiones_ IRD301 | J27: Desarrollo del Pensamiento y Toma de Decisiones_ IRD302 | L27: Desarrollo del Pensamiento y Toma de Decisiones_ IRD301 | N27: Desarrollo del Pensamiento y Toma de Decisiones_ IRD302
B28: 08:00 A 09:00 | H28: Desarrollo del Pensamiento y Toma de Decisiones_ IRD301 | J28: Desarrollo del Pensamiento y Toma de Decisiones_ IRD302 | L28: Desarrollo del Pensamiento y Toma de Decisiones_ IRD301 | N28: Desarrollo del Pensamiento y Toma de Decisiones_ IRD302
B29: 09:00 A 10:00 | H29: Desarrollo del Pensamiento y Toma de Decisiones* CD301 | J29: Desarrollo del Pensamiento y Toma de Decisiones* CD301 | L29: Desarrollo del Pensamiento y Toma de Decisiones* CD301 | N29: Desarrollo del Pensamiento y Toma de Decisiones* CD301
B30: 10:00 A 11:00
B31: 11:00 A 12:00
B32: 12:00 A 13:00
B33: 13:00 A 14:00
B34: 14:00 A 15:00
B35: 15:00 A 16:00
B36: 16:00 A 17:00
B37: 17:00 A 18:00
B38: 18:00 A 19:00
B39: 19:00 A 20:00
B40: 20:00 A 21:00
B41: 21:00 A 22:00
C46: MTRO. OLIVER RAÚL VELÁZQUEZ TORRES | N46: =B10 -> OLMOS OLALDE VICTOR HUGO
C47: NOMBRE Y FIRMA DEL DIRECTOR ACADÉMICO | N47: NOMBRE Y FIRMA DE LA PROFESORA O PROFESOR

Sheet ORDOÑEZ MORALES LUIS MARTIN
B1: UNIVERSIDAD TECNOLÓGICA FIDEL VELÁZQUEZ
B2: SECRETARÍA ACADÉMICA
B3: CARGA HORARIA PROFESOR DE ASIGNATURA
I5: NOMBRE DE LA DIVISIÓN: TELEMÁTICA
I6: PERIODO CUATRIMESTRAL: (MAYO - AGOSTO 2025) 2025-2
I7: VIGENCIA APARTIR DE: 01/05/2025 AL 30/08/2025
B10: ORDOÑEZ MORALES LUIS MARTIN | N10: MAESTRÍA
B11: NOMBRE DE LA PROFESORA O PROFESOR | N11: PROFESIÓN Y GRADO MÁXIMO DE ESTUDIOS
B13: DISTRIBUCIÓN DE HORAS AL CUATRIMESTRE
B14: DOCENCIA | D14: FRENTE A GRUPO | H14: ASIGNATURA | L14: CLAVE | M14: GRUPO | N14: HORAS/SEMANA/MES | R14: HORAS TOTALES POR SEMANA**
L15: {=INDEX(z_3_Materias!B2:B508, MATCH(H15, z_3_Materias!A2:A508, 0))} -> 0 | N15: {=INDEX(z_3_Materias!D2:D508, MATCH(H15, z_3_Materias!A2:A508, 0))} -> 0 | R15: =SUM(N15:Q23) -> 0 | T15: =H15&" "&M15
L16: {=INDEX(z_3_Materias!B2:B508, MATCH(H16, z_3_Materias!A2:A508, 0))} -> 0 | N16: {=INDEX(z_3_Materias!D2:D508, MATCH(H16, z_3_Materias!A2:A508, 0))} -> 0 | T16: =H16&" "&M16
L17: {=INDEX(z_3_Materias!B2:B508, MATCH(H17, z_3_Materias!A2:A508, 0))} -> 0 | N17: {=INDEX(z_3_Materias!D2:D508, MATCH(H17, z_3_Materias!A2:A508, 0))} -> 0 | T17: =H17&" "&M17
L18: {=INDEX(z_3_Materias!B2:B508, MATCH(H18, z_3_Materias!A2:A508, 0))} -> 0 | N18: {=INDEX(z_3_Materias!D2:D508, MATCH(H18, z_3_Materias!A2:A508, 0))} -> 0 | T18: =H18&" "&M18
L19: {=INDEX(z_3_Materias!B2:B508, MATCH(H19, z_3_Materias!A2:A508, 0))} -> 0 | N19: {=INDEX(z_3_Materias!D2:D508, MATCH(H19, z_3_Materias!A2:A508, 0))} -> 0 | T19: =H19&" "&M19
L20: {=INDEX(z_3_Materias!B2:B508, MATCH(H20, z_3_Materias!A2:A508, 0))} -> 0 | N20: {=INDEX(z_3_Materias!D2:D508, MATCH(H20, z_3_Materias!A2:A508, 0))} -> 0 | T20: =H20&" "&M20
L21: {=INDEX(z_3_Materias!B2:B508, MATCH(H21, z_3_Materias!A2:A508, 0))} -> 0 | N21: {=INDEX(z_3_Materias!D2:D508, MATCH(H21, z_3_Materias!A2:A508, 0))} -> 0 | T21: =H21&" "&M21
L22: {=INDEX(z_3_Materias!B2:B508, MATCH(H22, z_3_Materias!A2:A508, 0))} -> 0 | N22: {=INDEX(z_3_Materias!D2:D508, MATCH(H22, z_3_Materias!A2:A508, 0))} -> 0 | T22: =H22&" "&M22
L23: {=INDEX(z_3_Materias!B2:B508, MATCH(H23, z_3_Materias!A2:A508, 0))} -> 0 | N23: {=INDEX(z_3_Materias!D2:D508, MATCH(H23, z_3_Materias!A2:A508, 0))} -> 0 | T23: =H23&" "&M23
B25: HORARIO SEMANAL*11)
B26: DISTRIBUCIÓN DE HORAS | H26: LUNES | J26: MARTES | L26: MIERCOLES | N26: JUEVES | P26: VIERNES | R26: SÁBADO
B27: 07:00 A 08:00
B28: 08:00 A 09:00
B29: 09:00 A 10:00
B30: 10:00 A 11:00
B31: 11:00 A 12:00
B32: 12:00 A 13:00
B33: 13:00 A 14:00
B34: 14:00 A 15:00
B35: 15:00 A 16:00
B36: 16:00 A 17:00
B37: 17:00 A 18:00
B38: 18:00 A 19:00
... B41: 21:00 A 22:00
C46: MTRO. OLIVER RAÚL VELÁZQUEZ TORRES | N46: =B10 -> ORDOÑEZ MORALES LUIS MARTIN
C47: NOMBRE Y FIRMA DEL DIRECTOR ACADÉMICO | N47: NOMBRE Y FIRMA DE LA PROFESORA O PROFESOR

Sheet PEREZ SANCHEZ RAFAEL
B1: UNIVERSIDAD TECNOLÓGICA FIDEL VELÁZQUEZ
B2: SECRETARÍA ACADÉMICA
B3: CARGA HORARIA PROFESOR DE ASIGNATURA
I5: NOMBRE DE LA DIVISIÓN: TELEMÁTICA
I6: PERIODO CUATRIMESTRAL: (MAYO - AGOSTO 2025) 2025-2
I7: VIGENCIA APARTIR DE: 01/05/2025 AL 30/08/2025
B10: PEREZ SANCHEZ RAFAEL | N10: MAESTRÍA
B11: NOMBRE DE LA PROFESORA O PROFESOR | N11: PROFESIÓN Y GRADO MÁXIMO DE ESTUDIOS
B13: DISTRIBUCIÓN DE HORAS AL CUATRIMESTRE
B14: DOCENCIA | D14: FRENTE A GRUPO | H14: ASIGNATURA | L14: CLAVE | M14: GRUPO | N14: HORAS/SEMANA/MES | R14: HORAS TOTALES POR SEMANA**
L15: {=INDEX(z_3_Materias!B2:B508, MATCH(H15, z_3_Materias!A2:A508, 0))} -> 0 | N15: {=INDEX(z_3_Materias!D2:D508, MATCH(H15, z_3_Materias!A2:A508, 0))} -> 0 | R15: =SUM(N15:Q23) -> 0 | T15: =H15&" "&M15
L16: {=INDEX(z_3_Materias!B2:B508, MATCH(H16, z_3_Materias!A2:A508, 0))} -> 0 | N16: {=INDEX(z_3_Materias!D2:D508, MATCH(H16, z_3_Materias!A2:A508, 0))} -> 0 | T16: =H16&" "&M16
L17: {=INDEX(z_3_Materias!B2:B508, MATCH(H17, z_3_Materias!A2:A508, 0))} -> 0 | N17: {=INDEX(z_3_Materias!D2:D508, MATCH(H17, z_3_Materias!A2:A508, 0))} -> 0 | T17: =H17&" "&M17
L18: {=INDEX(z_3_Materias!B2:B508, MATCH(H18, z_3_Materias!A2:A508, 0))} -> 0 | N18: {=INDEX(z_3_Materias!D2:D508, MATCH(H18, z_3_Materias!A2:A508, 0))} -> 0 | T18: =H18&" "&M18
L19: {=INDEX(z_3_Materias!B2:B508, MATCH(H19, z_3_Materias!A2:A508, 0))} -> 0 | N19: {=INDEX(z_3_Materias!D2:D508, MATCH(H19, z_3_Materias!A2:A508, 0))} -> 0 | T19: =H19&" "&M19
L20: {=INDEX(z_3_Materias!B2:B508, MATCH(H20, z_3_Materias!A2:A508, 0))} -> 0 | N20: {=INDEX(z_3_Materias!D2:D508, MATCH(H20, z_3_Materias!A2:A508, 0))} -> 0 | T20: =H20&" "&M20
L21: {=INDEX(z_3_Materias!B2:B508, MATCH(H21, z_3_Materias!A2:A508, 0))} -> 0 | N21: {=INDEX(z_3_Materias!D2:D508, MATCH(H21, z_3_Materias!A2:A508, 0))} -> 0 | T21: =H21&" "&M21
L22: {=INDEX(z_3_Materias!B2:B508, MATCH(H22, z_3_Materias!A2:A508, 0))} -> 0 | N22: {=INDEX(z_3_Materias!D2:D508, MATCH(H22, z_3_Materias!A2:A508, 0))} -> 0 | T22: =H22&" "&M22
L23: {=INDEX(z_3_Materias!B2:B508, MATCH(H23, z_3_Materias!A2:A508, 0))} -> 0 | N23: {=INDEX(z_3_Materias!D2:D508, MATCH(H23, z_3_Materias!A2:A508, 0))} -> 0 | T23: =H23&" "&M23
B25: HORARIO SEMANAL*11)
B26: DISTRIBUCIÓN DE HORAS | H26: LUNES | J26: MARTES | L26: MIERCOLES | N26: JUEVES | P26: VIERNES | R26: SÁBADO
B27: 07:00 A 08:00
B28: 08:00 A 09:00
B29: 09:00 A 10:00
B30: 10:00 A 11:00
B31: 11:00 A 12:00
B32: 12:00 A 13:00
B33: 13:00 A 14:00
B34: 14:00 A 15:00
B35: 15:00 A 16:00
B36: 16:00 A 17:00
B37: 17:00 A 18:00
B38: 18:00 A 19:00
... B41: 21:00 A 22:00
C46: MTRO. OLIVER RAÚL VELÁZQUEZ TORRES | N46: =B10 -> PEREZ SANCHEZ RAFAEL
C47: NOMBRE Y FIRMA DEL DIRECTOR ACADÉMICO | N47: NOMBRE Y FIRMA DE LA PROFESORA O PROFESOR
C49: MTRO. OSCAR ARMANDO BAEZA HUICOCHEA
C50: NOMBRE Y FIRMA DEL DIRECTOR ACADÉMICO

Sheet RAMOS GAMA JOSELYN KAREN
B1: UNIVERSIDAD TECNOLÓGICA FIDEL VELÁZQUEZ
B2: SECRETARÍA ACADÉMICA
B3: CARGA HORARIA PROFESOR DE ASIGNATURA
I5: NOMBRE DE LA DIVISIÓN: TELEMÁTICA
I6: PERIODO CUATRIMESTRAL: (MAYO - AGOSTO 2025) 2025-2
I7: VIGENCIA APARTIR DE: 01/05/2025 AL 30/08/2025
B10: RAMOS GAMA JOSELYN KAREN | N10: MAESTRÍA
B11: NOMBRE DE LA PROFESORA O PROFESOR | N11: PROFESIÓN Y GRADO MÁXIMO DE ESTUDIOS
B13: DISTRIBUCIÓN DE HORAS AL CUATRIMESTRE
B14: DOCENCIA | D14: FRENTE A GRUPO | H14: ASIGNATURA | L14: CLAVE | M14: GRUPO | N14: HORAS/SEMANA/MES | R14: HORAS TOTALES POR SEMANA**
L15: {=INDEX(z_3_Materias!B2:B508, MATCH(H15, z_3_Materias!A2:A508, 0))} -> 0 | N15: {=INDEX(z_3_Materias!D2:D508, MATCH(H15, z_3_Materias!A2:A508, 0))} -> 0 | R15: =SUM(N15:Q25) -> 0 | T15: =H15&" "&M15
L16: {=INDEX(z_3_Materias!B2:B508, MATCH(H16, z_3_Materias!A2:A508, 0))} -> 0 | N16: {=INDEX(z_3_Materias!D2:D508, MATCH(H16, z_3_Materias!A2:A508, 0))} -> 0 | T16: =H16&" "&M16
L17: {=INDEX(z_3_Materias!B2:B508, MATCH(H17, z_3_Materias!A2:A508, 0))} -> 0 | N17: {=INDEX(z_3_Materias!D2:D508, MATCH(H17, z_3_Materias!A2:A508, 0))} -> 0 | T17: =H17&" "&M17
L18: {=INDEX(z_3_Materias!B2:B508, MATCH(H18, z_3_Materias!A2:A508, 0))} -> 0 | N18: {=INDEX(z_3_Materias!D2:D508, MATCH(H18, z_3_Materias!A2:A508, 0))} -> 0 | T18: =H18&" "&M18
L19: {=INDEX(z_3_Materias!B2:B508, MATCH(H19, z_3_Materias!A2:A508, 0))} -> 0 | N19: {=INDEX(z_3_Materias!D2:D508, MATCH(H19, z_3_Materias!A2:A508, 0))} -> 0 | T19: =H19&" "&M19
L20: {=INDEX(z_3_Materias!B2:B508, MATCH(H20, z_3_Materias!A2:A508, 0))} -> 0 | N20: {=INDEX(z_3_Materias!D2:D508, MATCH(H20, z_3_Materias!A2:A508, 0))} -> 0 | T20: =H20&" "&M20
L21: {=INDEX(z_3_Materias!B2:B508, MATCH(H21, z_3_Materias!A2:A508, 0))} -> 0 | N21: {=INDEX(z_3_Materias!D2:D508, MATCH(H21, z_3_Materias!A2:A508, 0))} -> 0 | T21: =H21&" "&M21
