Workbook

Sheet BASTIDA MIRANDA JULIO
A1: UNIVERSIDAD TECNOLÓGICA FIDEL VELÁZQUEZ
A2: SECRETARÍA ACADÉMICA
A3: CARGA HORARIA PROFESOR DE TIEMPO COMPLETO
H5: NOMBRE DE LA DIVISIÓN: DIVISIÓN ACADÉMICA DE DISEÑO, REDES E INTELIGENCIA ARTIFICIAL
H6: PERIODO CUATRIMESTRAL: (MAYO - AGOSTO 2025) 2025-2
H7: VIGENCIA A PARTIR DE: 01/05/2025 AL 30/08/2025
A9: BASTIDA MIRANDA JULIO | M9: MAESTRÍA
A10: NOMBRE DEL PROFESOR O PROFESORA | M10: PROFESIÓN Y GRADO MÁXIMO DE ESTUDIOS
A12: DISTRIBUCIÓN DE HORAS AL CUATRIMESTRE
A13: 1.DOCENCIA | C13: 1.1 FRENTE A GRUPO | G13: ASIGNATURA | K13: CLAVE | L13: GRUPO | M13: HORA /SEMANA/MES | Q13: TOTAL DE HORAS/SEMANA/MES
G14: Cálculo Integral* | K14: {=INDEX(z_4_Materias2!B9:B141, MATCH(G14, z_4_Materias2!A9:A141, 0))} -> 24CD017 | L14: CD301 | M14: {=INDEX(z_4_Materias2!D9:D141, MATCH(G14, z_4_Materias2!A9:A141, 0))} -> 4 | Q14: =SUM(M14:P18) -> 8 | S14: =G14&" "&L14 -> Cálculo Integral* CD301
G15: Cálculo Integral_ | K15: {=INDEX(z_4_Materias2!B10:B141, MATCH(G15, z_4_Materias2!A10:A141, 0))} -> 24IRD017 | L15: IRD301 | M15: {=INDEX(z_4_Materias2!D9:D141, MATCH(G15, z_4_Materias2!A9:A141, 0))} -> 4 | S15: =G15&" "&L15 -> Cálculo Integral_ IRD301
K16: {=INDEX(z_4_Materias2!B11:B141, MATCH(G16, z_4_Materias2!A11:A141, 0))} -> 0 | M16: {=INDEX(z_4_Materias2!D9:D141, MATCH(G16, z_4_Materias2!A9:A141, 0))} -> 0 | S16: =G16&" "&L16
K17: {=INDEX(z_4_Materias2!B12:B141, MATCH(G17, z_4_Materias2!A12:A141, 0))} -> 0 | M17: {=INDEX(z_4_Materias2!D9:D141, MATCH(G17, z_4_Materias2!A9:A141, 0))} -> 0 | S17: =G17&" "&L17
K18: {=INDEX(z_4_Materias2!B13:B141, MATCH(G18, z_4_Materias2!A13:A141, 0))} -> 0 | M18: {=INDEX(z_4_Materias2!D9:D141, MATCH(G18, z_4_Materias2!A9:A141, 0))} -> 0 | S18: =G18&" "&L18
G19: GRUPOS ASIGNADOS | L19: ENTREGABLE | Q19: H/S/M
C20: 1.2 TUTORÍA | G20: CD201 | Q20: 1
G25: ACTIVIDADES | L25: ENTREGABLE | Q25: H/S/M
C26: 1.3 ASESORÍA | G26: Asesoría especial | Q26: 6
G30: ACTIVIDADES | L30: ENTREGABLE 18) | Q30: H/S/M
A31: 2. VINCULACIÓN Y GESTIÓN ACADÉMICA | G31: Actualización de planes de estudio | Q31: 6
G32: Preparación de clases, elaboración de material didáctico, revisión de tareas y corrección de exámenes | Q32: 7
A35: 3. TRANSFERENCIA DE TECNOLOGÍA
G38: GRAN TOTAL DE HORAS/SEMANA/MES | Q38: =SUM(Q14,Q20:R24,Q26:R29,Q31:R33,Q35:R37) -> 28
A40: HORARIO SEMANAL*24)
A41: DISTRIBUCIÓN DE HORAS | G41: LUNES | I41: MARTES | K41: MIERCOLES | M41: JUEVES | O41: VIERNES | Q41: SÁBADO
A42: 07:00 A 08:00 | I42: Cálculo Integral* CD301 | K42: Cálculo Integral* CD301 | M42: Cálculo Integral_ IRD301
A43: 08:00 A 09:00 | I43: Cálculo Integral* CD301 | K43: Cálculo Integral* CD301 | M43: Cálculo Integral_ IRD301
A44: 09:00 A 10:00
A45: 10:00 A 11:00 | I45: Cálculo Integral_ IRD301 | K45: Cálculo Integral_ IRD301
A46: 11:00 A 12:00
A47: 12:00 A 13:00
A48: 13:00 A 14:00
A49: 14:00 A 15:00
A50: 15:00 A 16:00
A51: 16:00 A 17:00
A52: 17:00 A 18:00
A53: 18:00 A 19:00
A54: 19:00 A 20:00
A55: 20:00 A 21:00
...

Sheet CASAS GOMEZ VICTOR MANUEL
A1: UNIVERSIDAD TECNOLÓGICA FIDEL VELÁZQUEZ
A2: SECRETARÍA ACADÉMICA
A3: CARGA HORARIA PROFESOR DE TIEMPO COMPLETO
H5: NOMBRE DE LA DIVISIÓN: DIVISIÓN ACADÉMICA DE DISEÑO, REDES E INTELIGENCIA ARTIFICIAL
H6: PERIODO CUATRIMESTRAL: (MAYO - AGOSTO 2025) 2025-2
H7: VIGENCIA A PARTIR DE: 01/05/2025 AL 30/08/2025
A9: CASAS GÓMEZ VÍCTOR MANUEL | M9: MAESTRÍA
A10: NOMBRE DEL PROFESOR O PROFESORA | M10: PROFESIÓN Y GRADO MÁXIMO DE ESTUDIOS
A12: DISTRIBUCIÓN DE HORAS AL CUATRIMESTRE
A13: 1.DOCENCIA | C13: 1.1 FRENTE A GRUPO | G13: ASIGNATURA | K13: CLAVE | L13: GRUPO | M13: HORA /SEMANA/MES | Q13: TOTAL DE HORAS/SEMANA/MES
G14: Proyecto Integrador I_ | K14: {=INDEX(z_4_Materias2!B9:B141, MATCH(G14, z_4_Materias2!A9:A141, 0))} -> 24IRD021 | L14: IRD301 | M14: {=INDEX(z_4_Materias2!D9:D141, MATCH(G14, z_4_Materias2!A9:A141, 0))} -> 4 | Q14: =SUM(M14:P18) -> 8 | S14: =G14&" "&L14 -> Proyecto Integrador I_ IRD301
G15: Cálculo Integral_ | K15: {=INDEX(z_4_Materias2!B10:B141, MATCH(G15, z_4_Materias2!A10:A141, 0))} -> 24IRD017 | L15: IRD302 | M15: {=INDEX(z_4_Materias2!D9:D141, MATCH(G15, z_4_Materias2!A9:A141, 0))} -> 4 | S15: =G15&" "&L15 -> Cálculo Integral_ IRD302
K16: {=INDEX(z_4_Materias2!B11:B141, MATCH(G16, z_4_Materias2!A11:A141, 0))} -> 0 | M16: {=INDEX(z_4_Materias2!D9:D141, MATCH(G16, z_4_Materias2!A9:A141, 0))} -> 0 | S16: =G16&" "&L16
K17: {=INDEX(z_4_Materias2!B12:B141, MATCH(G17, z_4_Materias2!A12:A141, 0))} -> 0 | M17: {=INDEX(z_4_Materias2!D9:D141, MATCH(G17, z_4_Materias2!A9:A141, 0))} -> 0 | S17: =G17&" "&L17
K18: {=INDEX(z_4_Materias2!B13:B141, MATCH(G18, z_4_Materias2!A13:A141, 0))} -> 0 | M18: {=INDEX(z_4_Materias2!D9:D141, MATCH(G18, z_4_Materias2!A9:A141, 0))} -> 0 | S18: =G18&" "&L18
G19: GRUPOS ASIGNADOS | L19: ENTREGABLE | Q19: H/S/M
C20: 1.2 TUTORÍA | G20: IRD501 | Q20: 1
G25: ACTIVIDADES | L25: ENTREGABLE | Q25: H/S/M
C26: 1.3 ASESORÍA | G26: Asesoría especial | Q26: 4
G30: ACTIVIDADES | L30: ENTREGABLE 18) | Q30: H/S/M
A31: 2. VINCULACIÓN Y GESTIÓN ACADÉMICA | G31: Actualización de planes de estudio | Q31: 4
G32: Cuerpo Académico | Q32: 4
G33: Preparación de clases, elaboración de material didáctico, revisión de tareas y corrección de exámenes | Q33: 5
A35: 3. TRANSFERENCIA DE TECNOLOGÍA
G38: GRAN TOTAL DE HORAS/SEMANA/MES | Q38: =SUM(Q14,Q20:R24,Q26:R29,Q31:R33,Q35:R37) -> 26
A40: HORARIO SEMANAL*24)
A41: DISTRIBUCIÓN DE HORAS | G41: LUNES | I41: MARTES | K41: MIERCOLES | M41: JUEVES | O41: VIERNES | Q41: SÁBADO
A42: 07:00 A 08:00
A43: 08:00 A 09:00
A44: 09:00 A 10:00 | M44: Proyecto Integrador I_ IRD301 | O44: Cálculo Integral_ IRD302
A45: 10:00 A 11:00 | M45: Proyecto Integrador I_ IRD301 | O45: Cálculo Integral_ IRD302
A46: 11:00 A 12:00
A47: 12:00 A 13:00 | M47: Cálculo Integral_ IRD302 | O47: Proyecto Integrador I_ IRD301
A48: 13:00 A 14:00 | M48: Cálculo Integral_ IRD302 | O48: Proyecto Integrador I_ IRD301
A49: 14:00 A 15:00
A50: 15:00 A 16:00
A51: 16:00 A 17:00
A52: 17:00 A 18:00
A53: 18:00 A 19:00
A54: 19:00 A 20:00
...

Sheet DESCHAMPS SOLORZANO JOSÉ ALEJAN
A1: UNIVERSIDAD TECNOLÓGICA FIDEL VELÁZQUEZ
A2: SECRETARÍA ACADÉMICA
A3: CARGA HORARIA PROFESOR DE TIEMPO COMPLETO
H5: NOMBRE DE LA DIVISIÓN: DIVISIÓN ACADÉMICA DE DISEÑO, REDES E INTELIGENCIA ARTIFICIAL
H6: PERIODO CUATRIMESTRAL: (MAYO - AGOSTO 2025) 2025-2
H7: VIGENCIA A PARTIR DE: 01/05/2025 AL 30/08/2025
A9: DESCHAMPS SOLORZANO JOSÉ ALEJANDRO | M9: MAESTRÍA
A10: NOMBRE DEL PROFESOR O PROFESORA | M10: PROFESIÓN Y GRADO MÁXIMO DE ESTUDIOS
A12: DISTRIBUCIÓN DE HORAS AL CUATRIMESTRE
A13: 1.DOCENCIA | C13: 1.1 FRENTE A GRUPO | G13: ASIGNATURA | K13: CLAVE | L13: GRUPO | M13: HORA /SEMANA/MES | Q13: TOTAL DE HORAS/SEMANA/MES
K14: {=INDEX(z_4_Materias2!B9:B141, MATCH(G14, z_4_Materias2!A9:A141, 0))} -> 0 | M14: {=INDEX(z_4_Materias2!D9:D141, MATCH(G14, z_4_Materias2!A9:A141, 0))} -> 0 | Q14: =SUM(M14:P18) -> 0 | S14: =G14&" "&L14
K15: {=INDEX(z_4_Materias2!B10:B141, MATCH(G15, z_4_Materias2!A10:A141, 0))} -> 0 | M15: {=INDEX(z_4_Materias2!D9:D141, MATCH(G15, z_4_Materias2!A9:A141, 0))} -> 0 | S15: =G15&" "&L15
K16: {=INDEX(z_4_Materias2!B11:B141, MATCH(G16, z_4_Materias2!A11:A141, 0))} -> 0 | M16: {=INDEX(z_4_Materias2!D9:D141, MATCH(G16, z_4_Materias2!A9:A141, 0))} -> 0 | S16: =G16&" "&L16
K17: {=INDEX(z_4_Materias2!B12:B141, MATCH(G17, z_4_Materias2!A12:A141, 0))} -> 0 | M17: {=INDEX(z_4_Materias2!D9:D141, MATCH(G17, z_4_Materias2!A9:A141, 0))} -> 0 | S17: =G17&" "&L17
K18: {=INDEX(z_4_Materias2!B13:B141, MATCH(G18, z_4_Materias2!A13:A141, 0))} -> 0 | M18: {=INDEX(z_4_Materias2!D9:D141, MATCH(G18, z_4_Materias2!A9:A141, 0))} -> 0 | S18: =G18&" "&L18
L19: ENTREGABLE | Q19: H/S/M
C20: 1.2 TUTORÍA | G20: DAD203 | Q20: 1
G21: DAD204 | Q21: 1
G25: ACTIVIDADES | L25: ENTREGABLE | Q25: H/S/M
C26: 1.3 ASESORÍA | G26: Asesoría especial | Q26: 5
G30: ACTIVIDADES | L30: ENTREGABLE 18) | Q30: H/S/M
A31: 2. VINCULACIÓN Y GESTIÓN ACADÉMICA | G31: Actualización de planes de estudio | Q31: 6
G32: Preparación de clases, elaboración de material didáctico, revisión de tareas y corrección de exámenes | Q32: 7
A35: 3. TRANSFERENCIA DE TECNOLOGÍA
G38: GRAN TOTAL DE HORAS/SEMANA/MES | Q38: =SUM(Q14,Q20:R24,Q26:R29,Q31:R33,Q35:R37) -> 20
A40: HORARIO SEMANAL*24)
A41: DISTRIBUCIÓN DE HORAS | G41: LUNES | I41: MARTES | K41: MIERCOLES | M41: JUEVES | O41: VIERNES | Q41: SÁBADO
A42: 07:00 A 08:00
A43: 08:00 A 09:00
A44: 09:00 A 10:00
A45: 10:00 A 11:00
A46: 11:00 A 12:00
A47: 12:00 A 13:00
A48: 13:00 A 14:00
A49: 14:00 A 15:00
A50: 15:00 A 16:00
A51: 16:00 A 17:00
A52: 17:00 A 18:00
A53: 18:00 A 19:00
... A56: 21:00 A 22:00
...

Sheet ESPINOSA JIMÉNEZ MARÍA MARGARIT
A1: UNIVERSIDAD TECNOLÓGICA FIDEL VELÁZQUEZ
A2: SECRETARÍA ACADÉMICA
A3: CARGA HORARIA PROFESOR DE TIEMPO COMPLETO
H5: NOMBRE DE LA DIVISIÓN: DIVISIÓN ACADÉMICA DE DISEÑO, REDES E INTELIGENCIA ARTIFICIAL
H6: PERIODO CUATRIMESTRAL: (MAYO - AGOSTO 2025) 2025-2
H7: VIGENCIA A PARTIR DE: 01/05/2025 AL 30/08/2025
A9: ESPINOSA JIMÉNEZ MARÍA MARGARITA | M9: MAESTRÍA
A10: NOMBRE DEL PROFESOR O PROFESORA | M10: PROFESIÓN Y GRADO MÁXIMO DE ESTUDIOS
A12: DISTRIBUCIÓN DE HORAS AL CUATRIMESTRE
A13: 1.DOCENCIA | C13: 1.1 FRENTE A GRUPO | G13: ASIGNATURA | K13: CLAVE | L13: GRUPO | M13: HORA /SEMANA/MES | Q13: TOTAL DE HORAS/SEMANA/MES
K14: {=INDEX(z_4_Materias2!B9:B141, MATCH(G14, z_4_Materias2!A9:A141, 0))} -> 0 | M14: {=INDEX(z_4_Materias2!D9:D141, MATCH(G14, z_4_Materias2!A9:A141, 0))} -> 0 | Q14: =SUM(M14:P18) -> 0 | S14: =G14&" "&L14
K15: {=INDEX(z_4_Materias2!B10:B141, MATCH(G15, z_4_Materias2!A10:A141, 0))} -> 0 | M15: {=INDEX(z_4_Materias2!D9:D141, MATCH(G15, z_4_Materias2!A9:A141, 0))} -> 0 | S15: =G15&" "&L15
K16: {=INDEX(z_4_Materias2!B11:B141, MATCH(G16, z_4_Materias2!A11:A141, 0))} -> 0 | M16: {=INDEX(z_4_Materias2!D9:D141, MATCH(G16, z_4_Materias2!A9:A141, 0))} -> 0 | S16: =G16&" "&L16
K17: {=INDEX(z_4_Materias2!B12:B141, MATCH(G17, z_4_Materias2!A12:A141, 0))} -> 0 | M17: {=INDEX(z_4_Materias2!D9:D141, MATCH(G17, z_4_Materias2!A9:A141, 0))} -> 0 | S17: =G17&" "&L17
K18: {=INDEX(z_4_Materias2!B13:B141, MATCH(G18, z_4_Materias2!A13:A141, 0))} -> 0 | M18: {=INDEX(z_4_Materias2!D9:D141, MATCH(G18, z_4_Materias2!A9:A141, 0))} -> 0 | S18: =G18&" "&L18
G19: GRUPOS ASIGNADOS | L19: ENTREGABLE | Q19: H/S/M
C20: 1.2 TUTORÍA
G21: DAD206 | Q21: 1
G22: DAD209 | Q22: 1
G23: DDA504 | Q23: 1
G25: ACTIVIDADES | L25: ENTREGABLE | Q25: H/S/M
C26: 1.3 ASESORÍA | G26: Asesoría especial | Q26: 5
G30: ACTIVIDADES | L30: ENTREGABLE 18) | Q30: H/S/M
A31: 2. VINCULACIÓN Y GESTIÓN ACADÉMICA | G31: Actualización de planes de estudio | Q31: 6
G32: Preparación de clases, elaboración de material didáctico, revisión de tareas y corrección de exámenes | Q32: 6
A35: 3. TRANSFERENCIA DE TECNOLOGÍA
G38: GRAN TOTAL DE HORAS/SEMANA/MES | Q38: =SUM(Q14,Q20:R24,Q26:R29,Q31:R33,Q35:R37) -> 20
A40: HORARIO SEMANAL*24)
A41: DISTRIBUCIÓN DE HORAS | G41: LUNES | I41: MARTES | K41: MIERCOLES | M41: JUEVES | O41: VIERNES | Q41: SÁBADO
A42: 07:00 A 08:00
A43: 08:00 A 09:00
A44: 09:00 A 10:00
A45: 10:00 A 11:00
A46: 11:00 A 12:00
A47: 12:00 A 13:00
A48: 13:00 A 14:00
A49: 14:00 A 15:00
A50: 15:00 A 16:00
A51: 16:00 A 17:00
A52: 17:00 A 18:00
...

Sheet GARCÍA ROMERO LUIS ÁNGEL
A1: UNIVERSIDAD TECNOLÓGICA FIDEL VELÁZQUEZ
A2: SECRETARÍA ACADÉMICA
A3: CARGA HORARIA PROFESOR DE TIEMPO COMPLETO
H5: NOMBRE DE LA DIVISIÓN: DIVISIÓN ACADÉMICA DE DISEÑO, REDES E INTELIGENCIA ARTIFICIAL
H6: PERIODO CUATRIMESTRAL: (MAYO - AGOSTO 2025) 2025-2
H7: VIGENCIA A PARTIR DE: 01/05/2025 AL 30/08/2025
A9: GARCÍA ROMERO LUIS ÁNGEL | M9: MAESTRÍA
A10: NOMBRE DEL PROFESOR O PROFESORA | M10: PROFESIÓN Y GRADO MÁXIMO DE ESTUDIOS
A12: DISTRIBUCIÓN DE HORAS AL CUATRIMESTRE
A13: 1.DOCENCIA | C13: 1.1 FRENTE A GRUPO | G13: ASIGNATURA | K13: CLAVE | L13: GRUPO | M13: HORA /SEMANA/MES | Q13: TOTAL DE HORAS/SEMANA/MES
K14: {=INDEX(z_4_Materias2!B9:B141, MATCH(G14, z_4_Materias2!A9:A141, 0))} -> 0 | M14: {=INDEX(z_4_Materias2!D9:D141, MATCH(G14, z_4_Materias2!A9:A141, 0))} -> 0 | Q14: =SUM(M14:P18) -> 7 | S14: =G14&" "&L14
K15: {=INDEX(z_4_Materias2!B10:B141, MATCH(G15, z_4_Materias2!A10:A141, 0))} -> 0 | M15: {=INDEX(z_4_Materias2!D9:D141, MATCH(G15, z_4_Materias2!A9:A141, 0))} -> 0 | S15: =G15&" "&L15
K16: {=INDEX(z_4_Materias2!B11:B141, MATCH(G16, z_4_Materias2!A11:A141, 0))} -> 0 | M16: {=INDEX(z_4_Materias2!D9:D141, MATCH(G16, z_4_Materias2!A9:A141, 0))} -> 0 | S16: =G16&" "&L16
K17: {=INDEX(z_4_Materias2!B12:B141, MATCH(G17, z_4_Materias2!A12:A141, 0))} -> 0 | M17: {=INDEX(z_4_Materias2!D9:D141, MATCH(G17, z_4_Materias2!A9:A141, 0))} -> 0 | S17: =G17&" "&L17
M18: 7 | S18: =G18&" "&L18
G19: GRUPOS ASIGNADOS | L19: ENTREGABLE | Q19: H/S/M
C20: 1.2 TUTORÍA | G20: DAD201 | Q20: 1
G21: DDA301 | Q21: 1
G25: ACTIVIDADES | L25: ENTREGABLE | Q25: H/S/M
C26: 1.3 ASESORÍA | G26: Asesoría especial | Q26: 4
G30: ACTIVIDADES | L30: ENTREGABLE 18) | Q30: H/S/M
A31: 2. VINCULACIÓN Y GESTIÓN ACADÉMICA | G31: Actualización de planes de estudio | Q31: 3
G32: Preparación de clases, elaboración de material didáctico, revisión de tareas y corrección de exámenes | Q32: 3
A35: 3. TRANSFERENCIA DE TECNOLOGÍA
G38: GRAN TOTAL DE HORAS/SEMANA/MES | Q38: =SUM(Q14,Q20:R24,Q26:R29,Q31:R33,Q35:R37) -> 19
A40: HORARIO SEMANAL*24)
A41: DISTRIBUCIÓN DE HORAS | G41: LUNES | I41: MARTES | K41: MIERCOLES | M41: JUEVES | O41: VIERNES | Q41: SÁBADO
A42: 07:00 A 08:00
A43: 08:00 A 09:00
A44: 09:00 A 10:00
A45: 10:00 A 11:00
A46: 11:00 A 12:00
A47: 12:00 A 13:00
A48: 13:00 A 14:00
A49: 14:00 A 15:00
A50: 15:00 A 16:00
A51: 16:00 A 17:00
A52: 17:00 A 18:00
A53: 18:00 A 19:00
... A56: 21:00 A 22:00
...

Sheet HERNANDEZ JIMENEZ ARTURO
A1: UNIVERSIDAD TECNOLÓGICA FIDEL VELÁZQUEZ
A2: SECRETARÍA ACADÉMICA
A3: CARGA HORARIA PROFESOR DE TIEMPO COMPLETO
H5: NOMBRE DE LA DIVISIÓN: DIVISIÓN ACADÉMICA DE DISEÑO, REDES E INTELIGENCIA ARTIFICIAL
H6: PERIODO CUATRIMESTRAL: (MAYO - AGOSTO 2025) 2025-2
H7: VIGENCIA A PARTIR DE: 01/05/2025 AL 30/08/2025
A9: HERNÁNDEZ JIMÉNEZ ARTURO | M9: MAESTRÍA
A10: NOMBRE DEL PROFESOR O PROFESORA | M10: PROFESIÓN Y GRADO MÁXIMO DE ESTUDIOS
A12: DISTRIBUCIÓN DE HORAS AL CUATRIMESTRE
A13: 1.DOCENCIA | C13: 1.1 FRENTE A GRUPO | G13: ASIGNATURA | K13: CLAVE | L13: GRUPO | M13: HORA /SEMANA/MES | Q13: TOTAL DE HORAS/SEMANA/MES
K14: {=INDEX(z_4_Materias2!B9:B141, MATCH(G14, z_4_Materias2!A9:A141, 0))} -> 0 | M14: {=INDEX(z_4_Materias2!D9:D141, MATCH(G14, z_4_Materias2!A9:A141, 0))} -> 0 | Q14: =SUM(M14:P18) -> 0 | S14: =G14&" "&L14
K15: {=INDEX(z_4_Materias2!B10:B141, MATCH(G15, z_4_Materias2!A10:A141, 0))} -> 0 | M15: {=INDEX(z_4_Materias2!D9:D141, MATCH(G15, z_4_Materias2!A9:A141, 0))} -> 0 | S15: =G15&" "&L15
K16: {=INDEX(z_4_Materias2!B11:B141, MATCH(G16, z_4_Materias2!A11:A141, 0))} -> 0 | M16: {=INDEX(z_4_Materias2!D9:D141, MATCH(G16, z_4_Materias2!A9:A141, 0))} -> 0 | S16: =G16&" "&L16
K17: {=INDEX(z_4_Materias2!B12:B141, MATCH(G17, z_4_Materias2!A12:A141, 0))} -> 0 | M17: {=INDEX(z_4_Materias2!D9:D141, MATCH(G17, z_4_Materias2!A9:A141, 0))} -> 0 | S17: =G17&" "&L17
K18: {=INDEX(z_4_Materias2!B13:B141, MATCH(G18, z_4_Materias2!A13:A141, 0))} -> 0 | M18: {=INDEX(z_4_Materias2!D9:D141, MATCH(G18, z_4_Materias2!A9:A141, 0))} -> 0 | S18: =G18&" "&L18
G19: GRUPOS ASIGNADOS | L19: ENTREGABLE | Q19: H/S/M
C20: 1.2 TUTORÍA | G20: Tutoría
G21: IRICE701 | Q21: 1
G22: IRICE801 | Q22: 1
G23: IRICE802 | Q23: 1
G25: ACTIVIDADES | L25: ENTREGABLE | Q25: H/S/M
C26: 1.3 ASESORÍA | G26: Asesoría especial | Q26: 5
G30: ACTIVIDADES | L30: ENTREGABLE 18) | Q30: H/S/M
A31: 2. VINCULACIÓN Y GESTIÓN ACADÉMICA | G31: Actualización de planes de estudio | Q31: 5
G32: Preparación de clases, elaboración de material didáctico, revisión de tareas y corrección de exámenes | Q32: 6
A35: 3. TRANSFERENCIA DE TECNOLOGÍA
G38: GRAN TOTAL DE HORAS/SEMANA/MES | Q38: =SUM(Q14,Q20:R24,Q26:R29,Q31:R33,Q35:R37) -> 19
A40: HORARIO SEMANAL*24)
A41: DISTRIBUCIÓN DE HORAS | G41: LUNES | I41: MARTES | K41: MIERCOLES | M41: JUEVES | O41: VIERNES | Q41: SÁBADO
A42: 07:00 A 08:00
A43: 08:00 A 09:00
A44: 09:00 A 10:00
A45: 10:00 A 11:00
A46: 11:00 A 12:00
A47: 12:00 A 13:00
A48: 13:00 A 14:00
A49: 14:00 A 15:00
A50: 15:00 A 16:00
A51: 16:00 A 17:00
A52: 17:00 A 18:00
...

Sheet HIDALGO BAEZA MARIA DEL CARMEN
A1: UNIVERSIDAD TECNOLÓGICA FIDEL VELÁZQUEZ
A2: SECRETARÍA ACADÉMICA
A3: CARGA HORARIA PROFESOR DE TIEMPO COMPLETO
H5: NOMBRE DE LA DIVISIÓN: DIVISIÓN ACADÉMICA DE DISEÑO, REDES E INTELIGENCIA ARTIFICIAL
H6: PERIODO CUATRIMESTRAL: (MAYO - AGOSTO 2025) 2025-2
H7: VIGENCIA A PARTIR DE: 01/05/2025 AL 30/08/2025
A9: HIDALGO BAEZA MARÍA DEL CARMEN | M9: MAESTRÍA
A10: NOMBRE DEL PROFESOR O PROFESORA | M10: PROFESIÓN Y GRADO MÁXIMO DE ESTUDIOS
A12: DISTRIBUCIÓN DE HORAS AL CUATRIMESTRE
A13: 1.DOCENCIA | C13: 1.1 FRENTE A GRUPO | G13: ASIGNATURA | K13: CLAVE | L13: GRUPO | M13: HORA /SEMANA/MES | Q13: TOTAL DE HORAS/SEMANA/MES
G14: Bases de Datos_ | K14: {=INDEX(z_4_Materias2!B9:B141, MATCH(G14, z_4_Materias2!A9:A141, 0))} -> 24IRD019 | L14: IRD301 | M14: {=INDEX(z_4_Materias2!D9:D141, MATCH(G14, z_4_Materias2!A9:A141, 0))} -> 5 | Q14: =SUM(M14:P18) -> 10 | S14: =G14&" "&L14 -> Bases de Datos_ IRD301
G15: Bases de Datos_ | K15: {=INDEX(z_4_Materias2!B10:B141, MATCH(G15, z_4_Materias2!A10:A141, 0))} -> 24IRD019 | L15: IRD302 | M15: {=INDEX(z_4_Materias2!D9:D141, MATCH(G15, z_4_Materias2!A9:A141, 0))} -> 5 | S15: =G15&" "&L15 -> Bases de Datos_ IRD302
K16: {=INDEX(z_4_Materias2!B11:B141, MATCH(G16, z_4_Materias2!A11:A141, 0))} -> 0 | M16: {=INDEX(z_4_Materias2!D9:D141, MATCH(G16, z_4_Materias2!A9:A141, 0))} -> 0 | S16: =G16&" "&L16
K17: {=INDEX(z_4_Materias2!B12:B141, MATCH(G17, z_4_Materias2!A12:A141, 0))} -> 0 | M17: {=INDEX(z_4_Materias2!D9:D141, MATCH(G17, z_4_Materias2!A9:A141, 0))} -> 0 | S17: =G17&" "&L17
K18: {=INDEX(z_4_Materias2!B13:B141, MATCH(G18, z_4_Materias2!A13:A141, 0))} -> 0 | M18: {=INDEX(z_4_Materias2!D9:D141, MATCH(G18, z_4_Materias2!A9:A141, 0))} -> 0 | S18: =G18&" "&L18
G19: GRUPOS ASIGNADOS | L19: ENTREGABLE | Q19: H/S/M
C20: 1.2 TUTORÍA | G20: Tutoría
G21: IRD201 | Q21: 1
G25: ACTIVIDADES | L25: ENTREGABLE | Q25: H/S/M
C26: 1.3 ASESORÍA | G26: Asesoría especial | Q26: 4
G30: ACTIVIDADES | L30: ENTREGABLE 18) | Q30: H/S/M
A31: 2. VINCULACIÓN Y GESTIÓN ACADÉMICA | G31: Coordinadora de Tutorías | Q31: 3
G32: Actualización de planes de estudio | Q32: 2
G33: Cuerpo Académico | Q33: 4
G34: Preparación de clases, elaboración de material didáctico, revisión de tareas y corrección de exámenes | Q34: 4
A35: 3. TRANSFERENCIA DE TECNOLOGÍA
G38: GRAN TOTAL DE HORAS/SEMANA/MES | Q38: =SUM(Q14,Q20:R24,Q26:R29,Q31:R34,Q35:R37) -> 28
A40: HORARIO SEMANAL*24)
A41: DISTRIBUCIÓN DE HORAS | G41: LUNES | I41: MARTES | K41: MIERCOLES | M41: JUEVES | O41: VIERNES | Q41: SÁBADO
A42: 07:00 A 08:00
A43: 08:00 A 09:00
A44: 09:00 A 10:00 | G44: Bases de Datos_ IRD302 | I44: Bases de Datos_ IRD302 | K44: Bases de Datos_ IRD301
A45: 10:00 A 11:00 | G45: Bases de Datos_ IRD302 | I45: Bases de Datos_ IRD302 | K45: Bases de Datos_ IRD302
A46: 11:00 A 12:00
A47: 12:00 A 13:00 | G47: Bases de Datos_ IRD301 | I47: Bases de Datos_ IRD301
A48: 13:00 A 14:00 | G48: Bases de Datos_ IRD301 | I48: Bases de Datos_ IRD301
A49: 14:00 A 15:00
A50: 15:00 A 16:00
A51: 16:00 A 17:00
A52: 17:00 A 18:00
...

Sheet MARQUEZ SÁNCHEZ DANIEL MAURICIO
A1: UNIVERSIDAD TECNOLÓGICA FIDEL VELÁZQUEZ
A2: SECRETARÍA ACADÉMICA
A3: CARGA HORARIA PROFESOR DE TIEMPO COMPLETO
H5: NOMBRE DE LA DIVISIÓN: DIVISIÓN ACADÉMICA DE DISEÑO, REDES E INTELIGENCIA ARTIFICIAL
H6: PERIODO CUATRIMESTRAL: (MAYO - AGOSTO 2025) 2025-2
H7: VIGENCIA A PARTIR DE: 01/05/2025 AL 30/08/2025
A9: MARQUEZ SÁNCHEZ DANIEL MAURICIO | M9: MAESTRÍA
A10: NOMBRE DEL PROFESOR O PROFESORA | M10: PROFESIÓN Y GRADO MÁXIMO DE ESTUDIOS
A12: DISTRIBUCIÓN DE HORAS AL CUATRIMESTRE
A13: 1.DOCENCIA | C13: 1.1 FRENTE A GRUPO | G13: ASIGNATURA | K13: CLAVE | L13: GRUPO | M13: HORA /SEMANA/MES | Q13: TOTAL DE HORAS/SEMANA/MES
K14: {=INDEX(z_4_Materias2!B9:B141, MATCH(G14, z_4_Materias2!A9:A141, 0))} -> 0 | M14: {=INDEX(z_4_Materias2!D9:D141, MATCH(G14, z_4_Materias2!A9:A141, 0))} -> 0 | Q14: =SUM(M14:P18) -> 0 | S14: =G14&" "&L14
K15: {=INDEX(z_4_Materias2!B10:B141, MATCH(G15, z_4_Materias2!A10:A141, 0))} -> 0 | M15: {=INDEX(z_4_Materias2!D9:D141, MATCH(G15, z_4_Materias2!A9:A141, 0))} -> 0 | S15: =G15&" "&L15
K16: {=INDEX(z_4_Materias2!B11:B141, MATCH(G16, z_4_Materias2!A11:A141, 0))} -> 0 | M16: {=INDEX(z_4_Materias2!D9:D141, MATCH(G16, z_4_Materias2!A9:A141, 0))} -> 0 | S16: =G16&" "&L16
K17: {=INDEX(z_4_Materias2!B12:B141, MATCH(G17, z_4_Materias2!A12:A141, 0))} -> 0 | M17: {=INDEX(z_4_Materias2!D9:D141, MATCH(G17, z_4_Materias2!A9:A141, 0))} -> 0 | S17: =G17&" "&L17
K18: {=INDEX(z_4_Materias2!B13:B141, MATCH(G18, z_4_Materias2!A13:A141, 0))} -> 0 | M18: {=INDEX(z_4_Materias2!D9:D141, MATCH(G18, z_4_Materias2!A9:A141, 0))} -> 0 | S18: =G18&" "&L18
G19: GRUPOS ASIGNADOS | L19: ENTREGABLE | Q19: H/S/M
C20: 1.2 TUTORÍA | G20: DAD202 | Q20: 1
G21: DAD101 | Q21: 1
G25: ACTIVIDADES | L25: ENTREGABLE | Q25: H/S/M
C26: 1.3 ASESORÍA | G26: Asesoría especial | Q26: 6
G30: ACTIVIDADES | L30: ENTREGABLE 18) | Q30: H/S/M
A31: 2. VINCULACIÓN Y GESTIÓN ACADÉMICA | G31: Actualización de planes de estudio | Q31: 6
G32: Preparación de clases, elaboración de material didáctico, revisión de tareas y corrección de exámenes | Q32: 6
A35: 3. TRANSFERENCIA DE TECNOLOGÍA
G38: GRAN TOTAL DE HORAS/SEMANA/MES | Q38: =SUM(Q14,Q20:R24,Q26:R29,Q31:R33,Q35:R37) -> 20
A40: HORARIO SEMANAL*24)
A41: DISTRIBUCIÓN DE HORAS | G41: LUNES | I41: MARTES | K41: MIERCOLES | M41: JUEVES | O41: VIERNES | Q41: SÁBADO
A42: 07:00 A 08:00
A43: 08:00 A 09:00
A44: 09:00 A 10:00
A45: 10:00 A 11:00
A46: 11:00 A 12:00
A47: 12:00 A 13:00
A48: 13:00 A 14:00
A49: 14:00 A 15:00
A50: 15:00 A 16:00
A51: 16:00 A 17:00
A52: 17:00 A 18:00
A53: 18:00 A 19:00
... A56: 21:00 A 22:00
...

Sheet MONDRAGON DIEGO JOSE LUIS
A1: UNIVERSIDAD TECNOLÓGICA FIDEL VELÁZQUEZ
A2: SECRETARÍA ACADÉMICA
A3: CARGA HORARIA PROFESOR DE TIEMPO COMPLETO
H5: NOMBRE DE LA DIVISIÓN: DIVISIÓN ACADÉMICA DE DISEÑO, REDES E INTELIGENCIA ARTIFICIAL
H6: PERIODO CUATRIMESTRAL: (MAYO - AGOSTO 2025) 2025-2
H7: VIGENCIA A PARTIR DE: 01/05/2025 AL 30/08/2025
A9: MONDRAGÓN DIEGO JOSÉ LUIS | M9: MAESTRÍA
A10: NOMBRE DEL PROFESOR O PROFESORA | M10: PROFESIÓN Y GRADO MÁXIMO DE ESTUDIOS
A12: DISTRIBUCIÓN DE HORAS AL CUATRIMESTRE
A13: 1.DOCENCIA | C13: 1.1 FRENTE A GRUPO | G13: ASIGNATURA | K13: CLAVE | L13: GRUPO | M13: HORA /SEMANA/MES | Q13: TOTAL DE HORAS/SEMANA/MES
G14: Proyecto Integrador I* | K14: {=INDEX(z_4_Materias2!B9:B141, MATCH(G14, z_4_Materias2!A9:A141, 0))} -> 24CD021 | L14: CD301 | M14: {=INDEX(z_4_Materias2!D9:D141, MATCH(G14, z_4_Materias2!A9:A141, 0))} -> 4 | Q14: =SUM(M14:P18) -> 8 | S14: =G14&" "&L14 -> Proyecto Integrador I* CD301
G15: Proyecto Integrador I_ | K15: {=INDEX(z_4_Materias2!B10:B141, MATCH(G15, z_4_Materias2!A10:A141, 0))} -> 24IRD021 | L15: IRD302 | M15: {=INDEX(z_4_Materias2!D9:D141, MATCH(G15, z_4_Materias2!A9:A141, 0))} -> 4 | S15: =G15&" "&L15 -> Proyecto Integrador I_ IRD302
K16: {=INDEX(z_4_Materias2!B11:B141, MATCH(G16, z_4_Materias2!A11:A141, 0))} -> 0 | M16: {=INDEX(z_4_Materias2!D9:D141, MATCH(G16, z_4_Materias2!A9:A141, 0))} -> 0 | S16: =G16&" "&L16
K17: {=INDEX(z_4_Materias2!B12:B141, MATCH(G17, z_4_Materias2!A12:A141, 0))} -> 0 | M17: {=INDEX(z_4_Materias2!D9:D141, MATCH(G17, z_4_Materias2!A9:A141, 0))} -> 0 | S17: =G17&" "&L17
K18: {=INDEX(z_4_Materias2!B13:B141, MATCH(G18, z_4_Materias2!A13:A141, 0))} -> 0 | M18: {=INDEX(z_4_Materias2!D9:D141, MATCH(G18, z_4_Materias2!A9:A141, 0))} -> 0 | S18: =G18&" "&L18
G19: GRUPOS ASIGNADOS | L19: ENTREGABLE | Q19: H/S/M
C20: 1.2 TUTORÍA | G20: IRD202 | Q20: 1
G21: IRD502 | Q21: 1
G25: ACTIVIDADES | L25: ENTREGABLE | Q25: H/S/M
C26: 1.3 ASESORÍA | G26: Asesoría especial | Q26: 5
G30: ACTIVIDADES | L30: ENTREGABLE 18) | Q30: H/S/M
A31: 2. VINCULACIÓN Y GESTIÓN ACADÉMICA | G31: Actualización de planes de estudio | Q31: 5
G32: Preparación de clases, elaboración de material didáctico, revisión de tareas y corrección de exámenes | Q32: 6
A35: 3. TRANSFERENCIA DE TECNOLOGÍA
G38: GRAN TOTAL DE HORAS/SEMANA/MES | Q38: =SUM(Q14,Q20:R24,Q26:R29,Q31:R33,Q35:R37) -> 26
A40: HORARIO SEMANAL*24)
A41: DISTRIBUCIÓN DE HORAS | G41: LUNES | I41: MARTES | K41: MIERCOLES | M41: JUEVES | O41: VIERNES | Q41: SÁBADO
A42: 07:00 A 08:00 | G42: Proyecto Integrador I* CD301 | M42: Proyecto Integrador I* CD301
A43: 08:00 A 09:00 | G43: Proyecto Integrador I* CD301 | M43: Proyecto Integrador I* CD301
A44: 09:00 A 10:00
A45: 10:00 A 11:00
A46: 11:00 A 12:00
A47: 12:00 A 13:00 | G47: Proyecto Integrador I_ IRD302 | K47: Proyecto Integrador I_ IRD302
A48: 13:00 A 14:00 | G48: Proyecto Integrador I_ IRD302 | K48: Proyecto Integrador I_ IRD302
A49: 14:00 A 15:00
A50: 15:00 A 16:00
A51: 16:00 A 17:00
A52: 17:00 A 18:00
A53: 18:00 A 19:00
A54: 19:00 A 20:00
...

Sheet MORENO LOAIZA CAROLINA
A1: UNIVERSIDAD TECNOLÓGICA FIDEL VELÁZQUEZ
A2: SECRETARÍA ACADÉMICA
A3: CARGA HORARIA PROFESOR DE TIEMPO COMPLETO
H5: NOMBRE DE LA DIVISIÓN: DIVISIÓN ACADÉMICA DE DISEÑO, REDES E INTELIGENCIA ARTIFICIAL
H6: PERIODO CUATRIMESTRAL: (MAYO - AGOSTO 2025) 2025-2
H7: VIGENCIA A PARTIR DE: 01/05/2025 AL 30/08/2025
A9: MORENO LOAIZA CAROLINA | M9: DOCTORADO
A10: NOMBRE DEL PROFESOR O PROFESORA | M10: PROFESIÓN Y GRADO MÁXIMO DE ESTUDIOS
A12: DISTRIBUCIÓN DE HORAS AL CUATRIMESTRE
A13: 1.DOCENCIA | C13: 1.1 FRENTE A GRUPO | G13: ASIGNATURA | K13: CLAVE | L13: GRUPO | M13: HORA /SEMANA/MES | Q13: TOTAL DE HORAS/SEMANA/MES
K14: {=INDEX(z_4_Materias2!B9:B141, MATCH(G14, z_4_Materias2!A9:A141, 0))} -> 0 | M14: {=INDEX(z_4_Materias2!D1:D141, MATCH(G14, z_4_Materias2!A1:A141, 0))} -> 0 | Q14: =SUM(M14:P18) -> 0 | S14: =G14&" "&L14
K15: {=INDEX(z_4_Materias2!B9:B141, MATCH(G15, z_4_Materias2!A9:A141, 0))} -> 0 | M15: {=INDEX(z_4_Materias2!D1:D141, MATCH(G15, z_4_Materias2!A1:A141, 0))} -> 0 | S15: =G15&" "&L15
K16: {=INDEX(z_4_Materias2!B9:B141, MATCH(G16, z_4_Materias2!A9:A141, 0))} -> 0 | M16: {=INDEX(z_4_Materias2!D1:D141, MATCH(G16, z_4_Materias2!A1:A141, 0))} -> 0 | S16: =G16&" "&L16
K17: {=INDEX(z_4_Materias2!B9:B141, MATCH(G17, z_4_Materias2!A9:A141, 0))} -> 0 | M17: {=INDEX(z_4_Materias2!D1:D141, MATCH(G17, z_4_Materias2!A1:A141, 0))} -> 0 | S17: =G17&" "&L17
K18: {=INDEX(z_4_Materias2!B9:B141, MATCH(G18, z_4_Materias2!A9:A141, 0))} -> 0 | M18: {=INDEX(z_4_Materias2!D1:D141, MATCH(G18, z_4_Materias2!A1:A141, 0))} -> 0 | S18: =G18&" "&L18
G19: GRUPOS ASIGNADOS | L19: ENTREGABLE | Q19: H/S/M
C20: 1.2 TUTORÍA | G20: LDDPA801 | Q20: 1
G21: LDDPA802 | Q21: 1
G22: LDDPA803 | Q22: 1
G25: ACTIVIDADES | L25: ENTREGABLE | Q25: H/S/M
C26: 1.3 ASESORÍA | G26: Asesoría especial | Q26: 5
G30: ACTIVIDADES | L30: ENTREGABLE 18) | Q30: H/S/M
A31: 2. VINCULACIÓN Y GESTIÓN ACADÉMICA | G31: Actualización de planes de estudio | Q31: 5
G32: Preparación de clases, elaboración de material didáctico, revisión de tareas y corrección de exámenes | Q32: 6
A35: 3. TRANSFERENCIA DE TECNOLOGÍA
G38: GRAN TOTAL DE HORAS/SEMANA/MES | Q38: =SUM(Q14,Q20:R24,Q26:R29,Q31:R33,Q35:R37) -> 19
A40: HORARIO SEMANAL*24)
A41: DISTRIBUCIÓN DE HORAS | G41: LUNES | I41: MARTES | K41: MIERCOLES | M41: JUEVES | O41: VIERNES | Q41: SÁBADO
A42: 07:00 A 08:00
A43: 08:00 A 09:00
A44: 09:00 A 10:00
A45: 10:00 A 11:00
A46: 11:00 A 12:00
A47: 12:00 A 13:00
A48: 13:00 A 14:00
A49: 14:00 A 15:00
A50: 15:00 A 16:00
A51: 16:00 A 17:00
A52: 17:00 A 18:00
A53: 18:00 A 19:00
...

Sheet OLMOS ZARIÑAN GRISELDA
A1: UNIVERSIDAD TECNOLÓGICA FIDEL VELÁZQUEZ
A2: SECRETARÍA ACADÉMICA
A3: CARGA HORARIA PROFESOR DE TIEMPO COMPLETO
H5: NOMBRE DE LA DIVISIÓN: DIVISIÓN ACADÉMICA DE DISEÑO, REDES E INTELIGENCIA ARTIFICIAL
H6: PERIODO CUATRIMESTRAL: (MAYO - AGOSTO 2025) 2025-2
H7: VIGENCIA A PARTIR DE: 01/05/2025 AL 30/08/2025
A9: OLMOS ZARIÑAN GRISELDA | M9: DOCTORADO
A10: NOMBRE DEL PROFESOR O PROFESORA | M10: PROFESIÓN Y GRADO MÁXIMO DE ESTUDIOS
A12: DISTRIBUCIÓN DE HORAS AL CUATRIMESTRE
A13: 1.DOCENCIA | C13: 1.1 FRENTE A GRUPO | G13: ASIGNATURA | K13: CLAVE | L13: GRUPO | M13: HORA /SEMANA/MES | Q13: TOTAL DE HORAS/SEMANA/MES
K14: {=INDEX(z_4_Materias2!B9:B141, MATCH(G14, z_4_Materias2!A9:A141, 0))} -> 0 | M14: {=INDEX(z_4_Materias2!D9:D141, MATCH(G14, z_4_Materias2!A9:A141, 0))} -> 0 | Q14: =SUM(M14:P18) -> 0 | S14: =G14&" "&L14
K15: {=INDEX(z_4_Materias2!B10:B141, MATCH(G15, z_4_Materias2!A10:A141, 0))} -> 0 | M15: {=INDEX(z_4_Materias2!D9:D141, MATCH(G15, z_4_Materias2!A9:A141, 0))} -> 0 | S15: =G15&" "&L15
K16: {=INDEX(z_4_Materias2!B11:B141, MATCH(G16, z_4_Materias2!A11:A141, 0))} -> 0 | M16: {=INDEX(z_4_Materias2!D9:D141, MATCH(G16, z_4_Materias2!A9:A141, 0))} -> 0 | S16: =G16&" "&L16
K17: {=INDEX(z_4_Materias2!B12:B141, MATCH(G17, z_4_Materias2!A12:A141, 0))} -> 0 | M17: {=INDEX(z_4_Materias2!D9:D141, MATCH(G17, z_4_Materias2!A9:A141, 0))} -> 0 | S17: =G17&" "&L17
K18: {=INDEX(z_4_Materias2!B13:B141, MATCH(G18, z_4_Materias2!A13:A141, 0))} -> 0 | M18: {=INDEX(z_4_Materias2!D9:D141, MATCH(G18, z_4_Materias2!A9:A141, 0))} -> 0 | S18: =G18&" "&L18
G19: GRUPOS ASIGNADOS | L19: ENTREGABLE | Q19: H/S/M
C20: 1.2 TUTORÍA | G20: DDA505 | Q20: 1
G21: LDDPA901 | Q21: 1
G22: LDDPA1001 | Q22: 1
G25: ACTIVIDADES | L25: ENTREGABLE | Q25: H/S/M
C26: 1.3 ASESORÍA | G26: Asesoría especial | Q26: 5
G30: ACTIVIDADES | L30: ENTREGABLE 18) | Q30: H/S/M
A31: 2. VINCULACIÓN Y GESTIÓN ACADÉMICA | G31: Coordinadora de Tutorías | Q31: 3
G32: Actualización de planes de estudio | Q32: 3
G33: Preparación de clases, elaboración de material didáctico, revisión de tareas y corrección de exámenes | Q33: 5
A35: 3. TRANSFERENCIA DE TECNOLOGÍA
G38: GRAN TOTAL DE HORAS/SEMANA/MES | Q38: =SUM(Q14,Q20:R24,Q26:R29,Q31:R33,Q35:R37) -> 19
A40: HORARIO SEMANAL*24)
A41: DISTRIBUCIÓN DE HORAS | G41: LUNES | I41: MARTES | K41: MIERCOLES | M41: JUEVES | O41: VIERNES | Q41: SÁBADO
A42: 07:00 A 08:00
A43: 08:00 A 09:00
A44: 09:00 A 10:00
A45: 10:00 A 11:00
A46: 11:00 A 12:00
A47: 12:00 A 13:00
A48: 13:00 A 14:00
A49: 14:00 A 15:00
A50: 15:00 A 16:00
A51: 16:00 A 17:00
A52: 17:00 A 18:00
...

Sheet TELLEZ VELÁZQUEZ SERGIO
A1: UNIVERSIDAD TECNOLÓGICA FIDEL VELÁZQUEZ
A2: SECRETARÍA ACADÉMICA
A3: CARGA HORARIA PROFESOR DE TIEMPO COMPLETO
H5: NOMBRE DE LA DIVISIÓN: DIVISIÓN ACADÉMICA DE DISEÑO, REDES E INTELIGENCIA ARTIFICIAL
H6: PERIODO CUATRIMESTRAL: (MAYO - AGOSTO 2025) 2025-2
H7: VIGENCIA A PARTIR DE: 01/05/2025 AL 30/08/2025
A9: TELLEZ VELÁZQUEZ SERGIO | M9: MAESTRÍA
A10: NOMBRE DEL PROFESOR O PROFESORA | M10: PROFESIÓN Y GRADO MÁXIMO DE ESTUDIOS
A12: DISTRIBUCIÓN DE HORAS AL CUATRIMESTRE
A13: 1.DOCENCIA | C13: 1.1 FRENTE A GRUPO | G13: ASIGNATURA | K13: CLAVE | L13: GRUPO | M13: HORA /SEMANA/MES | Q13: TOTAL DE HORAS/SEMANA/MES
K14: {=INDEX(z_4_Materias2!B9:B141, MATCH(G14, z_4_Materias2!A9:A141, 0))} -> 0 | M14: {=INDEX(z_4_Materias2!D9:D141, MATCH(G14, z_4_Materias2!A9:A141, 0))} -> 0 | Q14: =SUM(M14:P18) -> 0 | S14: =G14&" "&L14
K15: {=INDEX(z_4_Materias2!B10:B141, MATCH(G15, z_4_Materias2!A10:A141, 0))} -> 0 | M15: {=INDEX(z_4_Materias2!D9:D141, MATCH(G15, z_4_Materias2!A9:A141, 0))} -> 0 | S15: =G15&" "&L15
K16: {=INDEX(z_4_Materias2!B11:B141, MATCH(G16, z_4_Materias2!A11:A141, 0))} -> 0 | M16: {=INDEX(z_4_Materias2!D9:D141, MATCH(G16, z_4_Materias2!A9:A141, 0))} -> 0 | S16: =G16&" "&L16
S17: =G17&" "&L17
S18: =G18&" "&L18
G19: GRUPOS ASIGNADOS | L19: ENTREGABLE | Q19: H/S/M
C20: 1.2 TUTORÍA | G20: DDA501 | Q20: 1
G21: DDA502 | Q21: 1
G25: ACTIVIDADES | L25: ENTREGABLE | Q25: H/S/M
C26: 1.3 ASESORÍA | G26: Asesoría especial | Q26: 5
G30: ACTIVIDADES | L30: ENTREGABLE 18) | Q30: H/S/M
A31: 2. VINCULACIÓN Y GESTIÓN ACADÉMICA | G31: Actualización de planes de estudio | Q31: 2
G32: Preparación de clases, elaboración de material didáctico, revisión de tareas y corrección de exámenes | Q32: 3
A35: 3. TRANSFERENCIA DE TECNOLOGÍA
G38: GRAN TOTAL DE HORAS/SEMANA/MES | Q38: =SUM(Q14,Q20:R24,Q26:R29,Q31:R33,Q35:R37) -> 12
A40: HORARIO SEMANAL*24)
A41: DISTRIBUCIÓN DE HORAS | G41: LUNES | I41: MARTES | K41: MIERCOLES | M41: JUEVES | O41: VIERNES | Q41: SÁBADO
A42: 07:00 A 08:00
A43: 08:00 A 09:00
A44: 09:00 A 10:00
A45: 10:00 A 11:00
A46: 11:00 A 12:00
A47: 12:00 A 13:00
A48: 13:00 A 14:00
A49: 14:00 A 15:00
A50: 15:00 A 16:00
A51: 16:00 A 17:00
A52: 17:00 A 18:00
A53: 18:00 A 19:00
... A56: 21:00 A 22:00
...

Sheet z_1_PLANTILLA
A1: UNIVERSIDAD TECNOLÓGICA FIDEL VELÁZQUEZ
A2: SECRETARÍA ACADÉMICA
A3: CARGA HORARIA PROFESOR DE TIEMPO COMPLETO
H5: NOMBRE DE LA DIVISIÓN: DIVISIÓN ACADÉMICA DE DISEÑO, REDES E INTELIGENCIA ARTIFICIAL
H6: PERIODO CUATRIMESTRAL: (MAYO - AGOSTO 2025) 2025-2
H7: VIGENCIA A PARTIR DE: 01/05/2025 AL 30/08/2025
M9: MAESTRÍA
A10: NOMBRE DEL PROFESOR O PROFESORA | M10: PROFESIÓN Y GRADO MÁXIMO DE ESTUDIOS
A12: DISTRIBUCIÓN DE HORAS AL CUATRIMESTRE
A13: 1.DOCENCIA | C13: 1.1 FRENTE A GRUPO | G13: ASIGNATURA | K13: CLAVE | L13: GRUPO | M13: HORA /SEMANA/MES | Q13: TOTAL DE HORAS/SEMANA/MES
K14: {=INDEX(z_3_Materias!B2:B51, MATCH(G14, z_3_Materias!A2:A51, 0))} -> #N/A | L14: DDA401 | M14: {=INDEX(z_3_Materias!D2:D51, MATCH(G14, z_3_Materias!A2:A51, 0))} -> #N/A | Q14: =SUM(M14:P18) -> #N/A | S14: =G14&" "&L14 -> DDA401
K15: {=INDEX(z_3_Materias!B2:B51, MATCH(G15, z_3_Materias!A2:A51, 0))} -> #N/A | L15: DDA402 | M15: {=INDEX(z_3_Materias!D2:D51, MATCH(G15, z_3_Materias!A2:A51, 0))} -> #N/A | S15: =G15&" "&L15 -> DDA402
K16: {=INDEX(z_3_Materias!B3:B52, MATCH(G16, z_3_Materias!A3:A52, 0))} -> #N/A | L16: DDA403 | M16: {=INDEX(z_3_Materias!D2:D51, MATCH(G16, z_3_Materias!A2:A51, 0))} -> #N/A | S16: =G16&" "&L16 -> DDA403
K17: {=INDEX(z_3_Materias!B4:B53, MATCH(G17, z_3_Materias!A4:A53, 0))} -> #N/A | M17: {=INDEX(z_3_Materias!D2:D51, MATCH(G17, z_3_Materias!A2:A51, 0))} -> #N/A | S17: =G17&" "&L17
K18: {=INDEX(z_3_Materias!B5:B54, MATCH(G18, z_3_Materias!A5:A54, 0))} -> #N/A | M18: {=INDEX(z_3_Materias!D2:D51, MATCH(G18, z_3_Materias!A2:A51, 0))} -> #N/A | S18: =G18&" "&L18
G19: GRUPOS ASIGNADOS | L19: ENTREGABLE | Q19: H/S/M
C20: 1.2 TUTORÍA
G25: ACTIVIDADES | L25: ENTREGABLE | Q25: H/S/M
C26: 1.3 ASESORÍA
G30: ACTIVIDADES | L30: ENTREGABLE 18) | Q30: H/S/M
A31: 2. VINCULACIÓN Y GESTIÓN ACADÉMICA
A35: 3. TRANSFERENCIA DE TECNOLOGÍA
G38: GRAN TOTAL DE HORAS/SEMANA/MES | Q38: =SUM(Q14,Q20:R24,Q26:R29,Q31:R33,Q35:R37) -> #N/A
A40: HORARIO SEMANAL*24)
A41: DISTRIBUCIÓN DE HORAS | G41: LUNES | I41: MARTES | K41: MIERCOLES | M41: JUEVES | O41: VIERNES | Q41: SÁBADO
A42: 07:00 A 08:00
A43: 08:00 A 09:00
A44: 09:00 A 10:00
A45: 10:00 A 11:00
A46: 11:00 A 12:00
A47: 12:00 A 13:00
A48: 13:00 A 14:00
A49: 14:00 A 15:00
A50: 15:00 A 16:00
A51: 16:00 A 17:00
A52: 17:00 A 18:00
A53: 18:00 A 19:00
... A56: 21:00 A 22:00
A58: FIRMA | L58: FIRMA
A61: MTRO. OLIVER RAÚL VELÁZQUEZ TORRES | L61: =A9 -> 0
...

Sheet z_2_Maestros
A1: id | B1: nombre | C1: cargo | D1: div
A2: 1 | B2: BASTIDA MIRANDA JULIO | C2: PTC | D2: RT
A3: 2 | B3: CASAS GÓMEZ VÍCTOR MANUEL | C3: PTC | D3: RT
A4: 3 | B4: DESCHAMPS SOLORZANO JOSÉ ALEJANDRO | C4: PTC
A5: 4 | B5: ESPINOSA JIMÉNEZ MARÍA MARGARITA | C5: PTC
A6: 5 | B6: GARCÍA ROMERO LUIS ÁNGEL | C6: PTC
A7: 6 | B7: HERNÁNDEZ JIMÉNEZ ARTURO | C7: PTC | D7: RT
A8: 7 | B8: HIDALGO BAEZA MARÍA DEL CARMEN | C8: PTC | D8: RT
A9: 8 | B9: MARQUEZ SÁNCHEZ DANIEL MAURICIO | C9: PTC
A10: 9 | B10: MONDRAGÓN DIEGO JOSÉ LUIS | C10: PTC | D10: RT
A11: 10 | B11: MORENO LOAIZA CAROLINA | C11: PTC
A12: 11 | B12: OLMOS ZARIÑAN GRISELDA | C12: PTC
A13: 12 | B13: TELLEZ VELÁZQUEZ SERGIO | C13: PTC
A14: 13 | L14: DDA401
L15: DDA402
L16: DDA403

Sheet z_3_Materias
A1: name | B1: codigo | C1: cuatri | D1: hsm
A2: Desarrollo Humano y Valores. | B2: 24CD002 | C2: 1 | D2: 4 | E2: Nuevo
A3: Fundamentos Matemáticos. | B3: 24CD003 | C3: 1 | D3: 7 | E3: Nuevo
A4: Física. | B4: 24CD004 | C4: 1 | D4: 6 | E4: Nuevo
A5: Fundamentos de Algoritmos. | B5: 24CD005 | C5: 1 | D5: 4 | E5: Nuevo
A6: Introducción a la Ingeniería de Datos. | B6: 24CD006 | C6: 1 | D6: 4 | E6: Nuevo
A7: Comunicación y Habilidades Digitales. | B7: 24CD007 | C7: 1 | D7: 5 | E7: Nuevo
A8: Habilidades Socioemocionales y Manejo de Conflictos. | B8: 24CD009 | C8: 2 | D8: 4 | E8: Nuevo
A9: Cálculo Diferencial. | B9: 24CD010 | C9: 2 | D9: 6 | E9: Nuevo
A10: Programación. | B10: 24CD011 | C10: 2 | D10: 6 | E10: Nuevo | L10: DDA401
A11: Probabilidad y Estadística. | B11: 24CD012 | C11: 2 | D11: 5 | E11: Nuevo | L11: DDA402
A12: Matemáticas Discretas. | B12: 24CD013 | C12: 2 | D12: 5 | E12: Nuevo | L12: DDA403
A13: Arquitectura de Computadoras y Servidores. | B13: 24CD014 | C13: 2 | D13: 4 | E13: Nuevo
A14: Desarrollo del Pensamiento y Toma de Decisiones* | B14: 24CD016 | C14: 3 | D14: 4 | E14: Nuevo
A15: Cálculo Integral* | B15: 24CD017 | C15: 3 | D15: 4 | E15: Nuevo
A16: Estructura de Datos* | B16: 24CD018 | C16: 3 | D16: 6 | E16: Nuevo
A17: Procesamiento de Datos* | B17: 24CD019 | C17: 3 | D17: 6 | E17: Nuevo
A18: Modelos Estadísticos* | B18: 24CD020 | C18: 3 | D18: 6 | E18: Nuevo
A19: Proyecto Integrador I* | B19: 24CD021 | C19: 3 | D19: 4 | E19: Nuevo
A20: Desarrollo Humano y Valores._ | B20: 24DAD002 | C20: 1 | D20: 4 | E20: Nuevo
A21: Fundamentos Matemáticos._ | B21: 24DAD003 | C21: 1 | D21: 7 | E21: Nuevo
A22: Fundamentos de Diseño y del Lenguaje Visual._ | B22: 24DAD004 | C22: 1 | D22: 7 | E22: Nuevo
A23: Representación Visual._ | B23: 24DAD005 | C23: 1 | D23: 4 | E23: Nuevo
A24: Comunicación Gráfica._ | B24: 24DAD006 | C24: 1 | D24: 3 | E24: Nuevo
... A137: Negociación Empresarial | B137: 20IRIC025 | C137: 10 | D137: 2 | E137: Anterior
A138: Tecnologías y Desarrollo de Producto Grafico | B138: TG-501 | C138: 5 | D138: 4
A139: Tecnologías Alternativas de Impresión | B139: TG-501 | C139: 5 | D139: 3
A140: Sistema Offset | B140: TG-501 | C140: 5 | D140: 7
C141: 0

Sheet z_4_FOR-DE LLENADO
D2: FORMA DE LLENADO | E2: Revisión: 0 | F2: Código:
E3: Requerimiento ISO 9001:2015: 8.5.1
E4: Fecha: 23-FEB-2023 | G4: Página 1 de 1
B6: N° | C6: Descripción
B7: 1 | C7: Se anota el nombre completo de la División a la que pertenece el registro. Ejemplo: MANTENIMIENTO INDUSTRIAL,ELECTRICIDAD Y ELECTRÓNICA; ADMINISTRACIÓN; INFORMÁTICA; TECNOLOGÍA AMBIENTAL; CONTABILIDAD CORPORATIVA; TELEMÁTICA; PROCESOS DE PRODUCCIÓN y CIENCIAS DE LA SALUD.
B8: 2 | C8: Se escribe el periodo cuatrimestral. Ejemplo: 2023-1 (ENERO-ABRIL) , 2023-2 (MAYO-AGOSTO), 2023-3 (SEPTIEMBRE-DICIEMBRE).
B9: 3 | C9: Se escribe la fecha en la que se establece la vigencia de la contratación según el periodo: Del 01 de enero al 30 de abril , del 01 de mayo al 31 de agosto o del 01 de septiembre al 31 de diciembre, correspondiente al año en curso.
B10: 4 | C10: Se escribe el nombre completo del profesor o profesora de quien corresponde la carga horaria. Ejemplo: JOSÉ ANTONIO HUERTA TORRES.
B11: 5 | C11: Se escribe la profesión y último grado de estudios obtenido de la profesora o el profesor de quién se elabora la Carga Horaria. Ejemplo: Maestro en Ciencias en Ingeniería Química, Doctora en Ciencias de la Educación, etcétera siempre y cuando esté titulado y/o cuente con cédula profesional.
B12: 6 | C12: Se enlistan las nombres de las asignaturas que la profesora o el profesor impartirá en el periodo cuatrimestral.
B13: 7 | C13: Se coloca la clave de la asignatura conforme al catálogo que presenta el Sistema de Administación Escolar.
B14: 8 | C14: Se enlistan los grupos a los cuales la profesora o el profesor impartirá cada asignatura en el periodo cuatrimestral. | L14: DDA401
B15: 9 | C15: Se enlistan las horas/semana/mes en las que la profesora o el profesor impartirá cada asignatura en el grupo correspondiente según el numeral 6. | L15: DDA402
B16: 10 | C16: Se escriben las horas subtotales por semana que la profesora o el profesor impartirá frente a los grupos mencionados en el numeral 8. | L16: DDA403
B17: 11 | C17: Se escriben los grupos que se han asignado a la profesora o el profesor para impartir tutoria.
B18: 12 | C18: Se escriben los resultados o entregables tangibles para cada uno de los grupos de tutoria asignados a la profesora o el profesor al concluir el cuatrimestre, ejemplo: Informe Final .
B19: 13 | C19: Número de horas/semana/mes subtotales dedicadas por la profesora o el profesor a la impartición de tutorias.
B20: 14 | C20: Se enlistan las actividades asociadas a la asesoria impartida por la profesora o el profesor (evaluacines especiales, estadias, remediales,regularización académica,eduación dual, etcétera).
B21: 15 | C21: Se escriben los resultados o entregables tangibles para cada una de las actividades que se enlistan en el numeral 14 que la profesora o el profesor tendrán en temas de asesoria, al concluir el cuatrimestre.
B22: 16 | C22: Número de horas/semana/mes subtotales dedicadas por la profesora o el profesor a la impartición de asesorias.
B23: 17 | C23: Se enlistan las actividades que la profesora o el profesor llevará a cabo en temas de vinculación y gestión académica, que desarrollará en el transcurso del cuatrimestre. 1. Gestión de proyectos vinculados a algún sector 2. Gestión de proyectos a desarrollar en el Centro de Cooperación Academia Industria. 3. Participación en programas de Educación Continua (Certificaciones otorgadas por el CONOCER) o participación en la impartición de algún estándar de competencia. 4. Participación en Cuerpo Colegiado institucional o externo. 5. Participación como auditor o par evaluador institucional o externo comisionado por la institución. 6. Organización y/o participación en eventos académicos o concursos. Participar en tareas de actividad institucional: Coordinación / supervisión de actividades académicas.
B24: 18 | C24: Se escriben los los resultados o entregables tangibles para cada una de las actividades enlistadas en el numeral 17 que la profesora o el profesor llevará a cabo en temas de vinculación y gestión académica, al concluir el cuatrimestre.
B25: 19 | C25: Número de horas/semana/mes subtotales dedicadas por la profesora o el profesor a la vinculación y gestión académica.
B26: 20 | C26: Se enlistan las actividades que la profesora o el profesor llevará a cabo en temas de transferencia de tecnología, en el transcurso del cuatrimestre: 1. Dirección y /o desarrollo de proyectos 2. Participación en el desarrollo o implementación de líneas de investigación; Perfil Deseable; redes de Investigación. 3. Participación en la publicación de artículos en las áreas de ciencia, social, y tecnología; congresos; publicaciones en revistas científicas, tecnológicas o sociales; publicación de libros o artículos con registro ISB, ISSN, DOIT entre otros.
B27: 21 | C27: Se escriben los resultados o entregables tangibles para cada una de las actividades enlistadas en el nuneral 20 que la profesora o el profesor llevarán a cabo en temas de transferencia de tecnología, al concluir el cuatrimestre.
B28: 22 | C28: Número de horas/semana/mes subtotales dedicadas por la profesora o el profesor a la Transferencia de tecnología.
... B32: 26 | C32: Firma de la Profesora o el Profesor de Tiempo Completo.

Sheet z_4_Materias2
A1: name | B1: codigo | C1: cuatri | D1: hsm
A2: Desarrollo Humano y Valores. | B2: 24CD002 | C2: 1 | D2: 4 | E2: Nuevo
A3: Fundamentos Matemáticos. | B3: 24CD003 | C3: 1 | D3: 7 | E3: Nuevo
A4: Física. | B4: 24CD004 | C4: 1 | D4: 6 | E4: Nuevo
A5: Fundamentos de Algoritmos. | B5: 24CD005 | C5: 1 | D5: 4 | E5: Nuevo
A6: Introducción a la Ingeniería de Datos. | B6: 24CD006 | C6: 1 | D6: 4 | E6: Nuevo
A7: Comunicación y Habilidades Digitales. | B7: 24CD007 | C7: 1 | D7: 5 | E7: Nuevo
A8: Habilidades Socioemocionales y Manejo de Conflictos. | B8: 24CD009 | C8: 2 | D8: 4 | E8: Nuevo
A9: Cálculo Diferencial. | B9: 24CD010 | C9: 2 | D9: 6 | E9: Nuevo
A10: Programación. | B10: 24CD011 | C10: 2 | D10: 6 | E10: Nuevo
A11: Probabilidad y Estadística. | B11: 24CD012 | C11: 2 | D11: 5 | E11: Nuevo
A12: Matemáticas Discretas. | B12: 24CD013 | C12: 2 | D12: 5 | E12: Nuevo
A13: Arquitectura de Computadoras y Servidores. | B13: 24CD014 | C13: 2 | D13: 4 | E13: Nuevo
... A137: Negociación Empresarial | B137: 20IRIC025 | C137: 10 | D137: 2 | E137: Anterior
A138: Tecnologías y Desarrollo de Producto Grafico | B138: TG-501 | C138: 5 | D138: 4
A139: Tecnologías Alternativas de Impresión | B139: TG-501 | C139: 5 | D139: 3
A140: Sistema Offset | B140: TG-501 | C140: 5 | D140: 7
C141: 0
