Workbook

Sheet CD201
D1: }
A3: UNIVERSIDAD TECNOLÓGICA FIDEL VELÁZQUEZ
A5: División Académica de Telemática
A6: Carrera en Ciencia de Datos
A7: Horario de Grupo
A8: Cuatrimestre: Enero - Abril | E8: GRUPO: CD201
A9: Período: 2025-1 | C9: TUTOR: BASTIDA MIRANDA JULIO
A12: Hora | B12: Lunes | C12: Martes | D12: Miércoles | E12: Jueves | F12: Viernes | G12: Sábado
A13: 07:00 08:00 | B13: Habilidades Socioemocionales y Manejo de Conflictos. - M103 | C13: Programación. - M108 | D13: Programación. - M108 | E13: Programación. - M108 | F13: Actividades Culturales y Deportivas II
A14: 08:00 09:00 | B14: Habilidades Socioemocionales y Manejo de Conflictos. - M103 | C14: Programación. - M108 | D14: Programación. - M108 | E14: Programación. - M108 | F14: Actividades Culturales y Deportivas II
A15: 09:00 10:00 | B15: Tutoría II. - M103 | C15: Cálculo Diferencial. - M103 | D15: Cálculo Diferencial. - M103 | E15: Habilidades Socioemocionales y Manejo de Conflictos. - M103 | F15: Habilidades Socioemocionales y Manejo de Conflictos. - M103
A16: 10:00 11:00 | B16: Inglés II | C16: Inglés II | D16: Inglés II | E16: Inglés II | F16: Inglés II
A17: 11:00 12:00 | B17: Matemáticas Discretas. - M103 | C17: Arquitectura de Computadoras y Servidores. - M107 | D17: Matemáticas Discretas. - M103 | E17: Matemáticas Discretas. - M103 | F17: Matemáticas Discretas. - M103
A18: 12:00 13:00 | B18: Cálculo Diferencial. - M103 | C18: Arquitectura de Computadoras y Servidores. - M107 | D18: Probabilidad y Estadística. - M108 | E18: Matemáticas Discretas. - M103 | F18: Probabilidad y Estadística. - M108
A19: 13:00 14:00 | B19: Cálculo Diferencial. - M103 | C19: Arquitectura de Computadoras y Servidores. - M107 | D19: Probabilidad y Estadística. - M108 | E19: Arquitectura de Computadoras y Servidores. - M103 | F19: Probabilidad y Estadística. - M108
A20: 14:00 15:00 | D20: Probabilidad y Estadística. - M108 | E20: Cálculo Diferencial. - M103 | F20: Cálculo Diferencial. - M103
A21: 15:00 16:00
A22: 16:00 17:00
A23: 17:00 18:00
A24: 18:00 19:00
A25: 19:00 20:00
A26: 20:00 21:00
A27: 21:00 22:00
A28: Horario generado: | G28: asc Horarios.
A29: Asignatura | D29: Horas | E29: Profesores
A30: Inglés II. | D30: =VLOOKUP(A30, Materias!A2:C180, 3, FALSE) -> 5 | E30: COORDINACIÓN DE INGLES
A31: Habilidades Socioemocionales y Manejo de Conflictos. | D31: =VLOOKUP(A31, Materias!A2:C180, 3, FALSE) -> 4 | E31: OLMOS OLALDE VICTOR HUGO
A32: Cálculo Diferencial. | D32: =VLOOKUP(A32, Materias!A2:C180, 3, FALSE) -> 6 | E32: BASTIDA MIRANDA JULIO
A33: Programación. | D33: =VLOOKUP(A33, Materias!A2:C180, 3, FALSE) -> 6 | E33: LIMA ARRONA FERNANDO
A34: Probabilidad y Estadística. | D34: =VLOOKUP(A34, Materias!A2:C180, 3, FALSE) -> 5 | E34: RODRIGUEZ RIVERA NAYELI BERENICE
A35: Matemáticas Discretas. | D35: =VLOOKUP(A35, Materias!A2:C180, 3, FALSE) -> 5 | E35: VARELA OLMOS VIOLETA
A36: Arquitectura de Computadoras y Servidores. | D36: =VLOOKUP(A36, Materias!A3:C181, 3, FALSE) -> 4 | E36: RODRIGUEZ SANCHEZ LUIS FERNANDO
A37: Tutoría II. | D37: =VLOOKUP(A37, Materias!A4:C182, 3, FALSE) -> 1 | E37: BASTIDA MIRANDA JULIO
A38: Actividades Culturales y Deportivas II. | D38: =VLOOKUP(A38, Materias!A2:C180, 3, FALSE) -> 2 | E38: COORDINACIÓN DE DEPORTES
A39: Sesiones/Semana | D39: =SUM(D30:D38) -> 38
A41: Director de la División Académica de Telemática Nombre y Firma del Director (a) de la División Académica
A42: Mtro. Oliver Raúl Velázquez Torres

Sheet IRD201
D1: }
A3: UNIVERSIDAD TECNOLÓGICA FIDEL VELÁZQUEZ
A5: División Académica de Telemática
A6: Carrera en Infraestructura de Redes Digitales
A7: Horario de Grupo
A8: Cuatrimestre: Enero - Abril | E8: GRUPO: IRD201
A9: Período: 2025-1 | C9: TUTOR: HIDALGO BAEZA MARIA DEL CARMEN
A12: Hora | B12: Lunes | C12: Martes | D12: Miércoles | E12: Jueves | F12: Viernes | G12: Sábado
A13: 07:00 08:00 | B13: Probabilidad y Estadística. - M101 | C13: Probabilidad y Estadística. - M101 | D13: Probabilidad y Estadística. - M101 | E13: Conmutación y Enrutamiento de Redes. - M106 | F13: Actividades Culturales y Deportivas II
A14: 08:00 09:00 | B14: Probabilidad y Estadística. - M101 | C14: Probabilidad y Estadística. - M101 | D14: Sistemas Operativos. - M101 | E14: Conmutación y Enrutamiento de Redes. - M106 | F14: Actividades Culturales y Deportivas II
A15: 09:00 10:00 | B15: Habilidades Socioemocionales y Manejo de Conflictos. - M101 | C15: Sistemas Operativos. - M106 | D15: Habilidades Socioemocionales y Manejo de Conflictos. - M101 | E15: Sistemas Operativos. - M106 | F15: Cálculo Diferencial. - M101
A16: 10:00 11:00 | B16: Habilidades Socioemocionales y Manejo de Conflictos. - M101 | C16: Sistemas Operativos. - M106 | D16: Habilidades Socioemocionales y Manejo de Conflictos. - M101 | E16: Sistemas Operativos. - M106 | F16: Cálculo Diferencial. - M101
A17: 11:00 12:00 | B17: Inglés II | C17: Inglés II | D17: Inglés II | E17: Inglés II | F17: Inglés II
A18: 12:00 13:00 | B18: Conmutación y Enrutamiento de Redes. - M106 | C18: Cálculo Diferencial. - M101 | D18: Cálculo Diferencial. - M101 | E18: Cálculo Diferencial. - M101 | F18: Conmutación y Enrutamiento de Redes. - M106
A19: 13:00 14:00 | B19: Conmutación y Enrutamiento de Redes. - M106 | C19: Programación Estructurada. - M106 | D19: Programación Estructurada. - M106 | E19: Cálculo Diferencial. - M101
A20: 14:00 15:00 | B20: Programación Estructurada. - M106 | C20: Programación Estructurada. - M106 | D20: Programación Estructurada. - M106 | E20: Tutoría II. - M101
A21: 15:00 16:00
A22: 16:00 17:00
A23: 17:00 18:00
A24: 18:00 19:00
A25: 19:00 20:00 | D25: |
A26: 20:00 21:00
A27: 21:00 22:00
A28: Horario generado: | G28: asc Horarios.
A29: Asignatura | D29: Horas | E29: Profesores
A30: Inglés II. | D30: =VLOOKUP(A30, Materias!A2:C180, 3, FALSE) -> 5 | E30: COORDINACIÓN DE INGLES
A31: Habilidades Socioemocionales y Manejo de Conflictos. | D31: =VLOOKUP(A31, Materias!A2:C180, 3, FALSE) -> 4 | E31: OLMOS OLALDE VICTOR HUGO
A32: Cálculo Diferencial. | D32: =VLOOKUP(A32, Materias!A2:C180, 3, FALSE) -> 6 | E32: BASTIDA MIRANDA JULIO
A33: Conmutación y Enrutamiento de Redes. | D33: =VLOOKUP(A33, Materias!A2:C180, 3, FALSE) -> 5 | E33: CASAS GOMEZ VICTOR MANUEL
A34: Probabilidad y Estadística. | D34: =VLOOKUP(A34, Materias!A2:C180, 3, FALSE) -> 5 | E34: MONDRAGÓN DIEGO JOSÉ LUIS
A35: Programación Estructurada. | D35: =VLOOKUP(A35, Materias!A2:C180, 3, FALSE) -> 5 | E35: HERNANDEZ JIMENEZ ARTURO
A36: Sistemas Operativos. | D36: =VLOOKUP(A36, Materias!A2:C180, 3, FALSE) -> 5 | E36: HIDALGO BAEZA MARIA DEL CARMEN
A37: Tutoría II. | D37: =VLOOKUP(A37, Materias!A2:C180, 3, FALSE) -> 1 | E37: HIDALGO BAEZA MARIA DEL CARMEN
A38: Actividades Culturales y Deportivas II. | D38: =VLOOKUP(A38, Materias!A2:C180, 3, FALSE) -> 2 | E38: COORDINACIÓN DE DEPORTES
A39: Sesiones/Semana | D39: =SUM(D30:D38) -> 38
A41: Director de la División Académica de Telemática Nombre y Firma del Director (a) de la División Académica
A42: Mtro. Oliver Raúl Velázquez Torres

Sheet IRD202
D1: }
A3: UNIVERSIDAD TECNOLÓGICA FIDEL VELÁZQUEZ
A5: División Académica de Telemática
A6: Carrera en Infraestructura de Redes Digitales
A7: Horario de Grupo
A8: Cuatrimestre: Enero - Abril | E8: GRUPO: IRD202
A9: Período: 2025-1 | C9: TUTOR: MONDRAGÓN DIEGO JOSÉ LUIS
A12: Hora | B12: Lunes | C12: Martes | D12: Miércoles | E12: Jueves | F12: Viernes | G12: Sábado
A13: 07:00 08:00 | B13: Cálculo Diferencial. - M104 | C13: Cálculo Diferencial. - M104 | D13: Habilidades Socioemocionales y Manejo de Conflictos. - M104 | E13: Habilidades Socioemocionales y Manejo de Conflictos. - M104 | F13: Actividades Culturales y Deportivas II
A14: 08:00 09:00 | B14: Cálculo Diferencial. - M104 | C14: Cálculo Diferencial. - M104 | D14: Habilidades Socioemocionales y Manejo de Conflictos. - M104 | E14: Habilidades Socioemocionales y Manejo de Conflictos. - M104 | F14: Actividades Culturales y Deportivas II
A15: 09:00 10:00 | B15: Sistemas Operativos. - M107 | C15: Probabilidad y Estadística. - M104 | D15: Conmutación y Enrutamiento de Redes. - M107 | E15: Cálculo Diferencial. - M104 | F15: Conmutación y Enrutamiento de Redes. - M107
A16: 10:00 11:00 | B16: Sistemas Operativos. - M107 | C16: Probabilidad y Estadística. - M104 | D16: Conmutación y Enrutamiento de Redes. - M107 | E16: Cálculo Diferencial. - M104 | F16: Conmutación y Enrutamiento de Redes. - M107
A17: 11:00 12:00 | B17: Inglés II | C17: Inglés II | D17: Inglés II | E17: Inglés II | F17: Inglés II
A18: 12:00 13:00 | B18: Probabilidad y Estadística. - M104 | D18: Sistemas Operativos. - M107 | E18: Conmutación y Enrutamiento de Redes. - M107 | F18: Probabilidad y Estadística. - M104
A19: 13:00 14:00 | B19: Probabilidad y Estadística. - M104 | D19: Sistemas Operativos. - M107 | E19: Programación Estructurada. - M107 | F19: Programación Estructurada. - M107
A20: 14:00 15:00 | B20: Tutoría II. - M104 | D20: Sistemas Operativos. - M107 | E20: Programación Estructurada. - M107 | F20: Programación Estructurada. - M107
A21: 15:00 16:00 | F21: Programación Estructurada. - M107
A22: 16:00 17:00
A23: 17:00 18:00
A24: 18:00 19:00
A25: 19:00 20:00 | D25: |
A26: 20:00 21:00
A27: 21:00 22:00
A28: Horario generado: | G28: asc Horarios.
A29: Asignatura | D29: Horas | E29: Profesores
A30: Inglés II. | D30: =VLOOKUP(A30, Materias!A2:C180, 3, FALSE) -> 5 | E30: COORDINACIÓN DE INGLES
A31: Habilidades Socioemocionales y Manejo de Conflictos. | D31: =VLOOKUP(A31, Materias!A2:C180, 3, FALSE) -> 4 | E31: OLMOS OLALDE VICTOR HUGO
A32: Cálculo Diferencial. | D32: =VLOOKUP(A32, Materias!A2:C180, 3, FALSE) -> 6 | E32: BASTIDA MIRANDA JULIO
A33: Conmutación y Enrutamiento de Redes. | D33: =VLOOKUP(A33, Materias!A2:C180, 3, FALSE) -> 5 | E33: CASAS GOMEZ VICTOR MANUEL
A34: Probabilidad y Estadística. | D34: =VLOOKUP(A34, Materias!A2:C180, 3, FALSE) -> 5 | E34: MONDRAGÓN DIEGO JOSÉ LUIS
A35: Programación Estructurada. | D35: =VLOOKUP(A35, Materias!A2:C180, 3, FALSE) -> 5 | E35: HERNANDEZ JIMENEZ ARTURO
A36: Sistemas Operativos. | D36: =VLOOKUP(A36, Materias!A2:C180, 3, FALSE) -> 5 | E36: HIDALGO BAEZA MARIA DEL CARMEN
A37: Tutoría II. | D37: =VLOOKUP(A37, Materias!A2:C180, 3, FALSE) -> 1 | E37: MONDRAGÓN DIEGO JOSÉ LUIS
A38: Actividades Culturales y Deportivas II. | D38: =VLOOKUP(A38, Materias!A2:C180, 3, FALSE) -> 2 | E38: COORDINACIÓN DE DEPORTES
A39: Sesiones/Semana | D39: =SUM(D30:D38) -> 38
A41: Director de la División Académica de Telemática Nombre y Firma del Director (a) de la División Académica
A42: Mtro. Oliver Raúl Velázquez Torres

Sheet IRD501
D1: }
A3: UNIVERSIDAD TECNOLÓGICA FIDEL VELÁZQUEZ
A5: División Académica de Telemática
A6: Carrera en Tecnologías de la Información área Infraestructura de Redes Digitales
A7: Horario de Grupo
A8: Cuatrimestre: Enero - Abril | E8: GRUPO: IRD501
A9: Período: 2025-1 | C9: TUTOR: CASAS GOMEZ VICTOR MANUEL
A12: Hora | B12: Lunes | C12: Martes | D12: Miércoles | E12: Jueves | F12: Viernes | G12: Sábado
A13: 07:00 08:00 | B13: Introducción a Big Data - M107 | C13: Administración de Redes de Datos - M106 | D13: Administración de Redes de Datos - M106 | E13: Ciberseguridad - M102 | F13: Integradora II - M102
A14: 08:00 09:00 | B14: Introducción a Big Data - M107 | C14: Administración de Redes de Datos - M106 | D14: Administración de Redes de Datos - M106 | E14: Ciberseguridad - M102 | F14: Integradora II - M102
A15: 09:00 10:00 | B15: Administración de Redes de Datos - M106 | C15: Introducción a Big Data - M107 | D15: Administración de Servidores II - M102 | E15: Introducción a Big Data - M107 | F15: Ciberseguridad - M102
A16: 10:00 11:00 | B16: Administración de Redes de Datos - M106 | C16: Introducción a Big Data - M107 | D16: Administración de Servidores II - M102 | E16: Introducción a Big Data - M107 | F16: Ciberseguridad - M102
A17: 11:00 12:00 | B17: Inglés V | C17: Inglés V | D17: Inglés V | E17: Inglés V | F17: Ciberseguridad - M102
A18: 12:00 13:00 | B18: Expresión Oral y Escrita II - M101 | C18: Administración de Servidores II - M102 | D18: Ciberseguridad - M102 | E18: Administración de Servidores II - M102 | F18: Expresión Oral y Escrita II - M101
A19: 13:00 14:00 | B19: Expresión Oral y Escrita II - M101 | C19: Administración de Servidores II - M102 | E19: Administración de Servidores II - M102 | F19: Expresión Oral y Escrita II - M101
A20: 14:00 15:00 | B20: Expresión Oral y Escrita II - M101
A21: 15:00 16:00
A22: 16:00 17:00
A23: 17:00 18:00
A24: 18:00 19:00
A25: 19:00 20:00 | D25: |
A26: 20:00 21:00
A27: 21:00 22:00
A28: Horario generado: | G28: asc Horarios.
A29: Asignatura | D29: Horas | E29: Profesores
A30: Introducción a Big Data | D30: =VLOOKUP(A30, Materias!A2:C180, 3, FALSE) -> 6 | E30: LIMA ARRONA FERNANDO
A31: Administración de Redes de Datos | D31: =VLOOKUP(A31, Materias!A2:C180, 3, FALSE) -> 6 | E31: CASAS GOMEZ VICTOR MANUEL
A32: Administración de Servidores II | D32: =VLOOKUP(A32, Materias!A2:C180, 3, FALSE) -> 6 | E32: HIDALGO BAEZA MARIA DEL CARMEN
A33: Ciberseguridad | D33: =VLOOKUP(A33, Materias!A2:C180, 3, FALSE) -> 6 | E33: MONDRAGÓN DIEGO JOSÉ LUIS
A34: Integradora II | D34: =VLOOKUP(A34, Materias!A2:C180, 3, FALSE) -> 2 | E34: BASTIDA MIRANDA JULIO
A35: Inglés V | D35: =VLOOKUP(A35, Materias!A2:C180, 3, FALSE) -> 4 | E35: COORDINACIÓN DE INGLES
A36: Expresión Oral y Escrita II | D36: =VLOOKUP(A36, Materias!A3:C181, 3, FALSE) -> 5 | E36: OLMOS OLALDE VICTOR HUGO
A37: Sesiones/Semana | D37: =SUM(D30:D36) -> 35
A39: Director de la División Académica de Telemática Nombre y Firma del Director (a) de la División Académica
A40: Mtro. Oliver Raúl Velázquez Torres

Sheet IRD502
D1: }
A3: UNIVERSIDAD TECNOLÓGICA FIDEL VELÁZQUEZ
A5: División Académica de Telemática
A6: Carrera en Tecnologías de la Información área Infraestructura de Redes Digitales
A7: Horario de Grupo
A8: Cuatrimestre: Enero - Abril | E8: GRUPO: IRD502
A9: Período: 2025-1 | C9: TUTOR: MONDRAGÓN DIEGO JOSÉ LUIS
A12: Hora | B12: Lunes | C12: Martes | D12: Miércoles | E12: Jueves | F12: Viernes | G12: Sábado
A13: 07:00 08:00 | B13: Administración de Redes de Datos - M108 | F13: Introducción a Big Data - M108
A14: 08:00 09:00 | B14: Administración de Redes de Datos - M108 | E14: Administración de Servidores II - M103 | F14: Introducción a Big Data - M108
A15: 09:00 10:00 | B15: Introducción a Big Data - M108 | C15: Administración de Redes de Datos - M108 | D15: Introducción a Big Data - M108 | E15: Administración de Redes de Datos - M108 | F15: Introducción a Big Data - M108
A16: 10:00 11:00 | B16: Ciberseguridad - M108 | C16: Administración de Redes de Datos - M108 | D16: Introducción a Big Data - M108 | E16: Administración de Redes de Datos - M108 | F16: Expresión Oral y Escrita II - M104
A17: 11:00 12:00 | B17: Inglés V | C17: Inglés V | D17: Inglés V | E17: Inglés V | F17: Expresión Oral y Escrita II - M104
A18: 12:00 13:00 | B18: Administración de Servidores II - M102 | C18: Ciberseguridad - M108 | D18: Expresión Oral y Escrita II - M104 | E18: Ciberseguridad - M108
A19: 13:00 14:00 | B19: Administración de Servidores II - M102 | C19: Ciberseguridad - M108 | D19: Expresión Oral y Escrita II - M104 | E19: Ciberseguridad - M108
A20: 14:00 15:00 | B20: Administración de Servidores II - M102 | C20: Administración de Servidores II - M102 | D20: Expresión Oral y Escrita II - M104 | E20: Ciberseguridad - M108
A21: 15:00 16:00 | B21: Integradora II - M102 | C21: Administración de Servidores II - M102 | D21: Integradora II - M102
A22: 16:00 17:00
A23: 17:00 18:00
A24: 18:00 19:00
A25: 19:00 20:00 | D25: |
A26: 20:00 21:00
A27: 21:00 22:00
A28: Horario generado: | G28: asc Horarios.
A29: Asignatura | D29: Horas | E29: Profesores
A30: Introducción a Big Data | D30: =VLOOKUP(A30, Materias!A2:C180, 3, FALSE) -> 6 | E30: LIMA ARRONA FERNANDO
A31: Administración de Redes de Datos | D31: =VLOOKUP(A31, Materias!A2:C180, 3, FALSE) -> 6 | E31: CASAS GOMEZ VICTOR MANUEL
A32: Administración de Servidores II | D32: =VLOOKUP(A32, Materias!A2:C180, 3, FALSE) -> 6 | E32: HIDALGO BAEZA MARIA DEL CARMEN
A33: Ciberseguridad | D33: =VLOOKUP(A33, Materias!A2:C180, 3, FALSE) -> 6 | E33: MONDRAGÓN DIEGO JOSÉ LUIS
A34: Integradora II | D34: =VLOOKUP(A34, Materias!A2:C180, 3, FALSE) -> 2 | E34: HERNANDEZ JIMENEZ ARTURO
A35: Inglés V | D35: =VLOOKUP(A35, Materias!A2:C180, 3, FALSE) -> 4 | E35: COORDINACIÓN DE INGLES
A36: Expresión Oral y Escrita II | D36: =VLOOKUP(A36, Materias!A3:C181, 3, FALSE) -> 5 | E36: OLMOS OLALDE VICTOR HUGO
A37: Sesiones/Semana | D37: =SUM(D30:D36) -> 35
A39: Director de la División Académica de Telemática Nombre y Firma del Director (a) de la División Académica
A40: Mtro. Oliver Raúl Velázquez Torres

Sheet IRICE701
D1: }
A3: UNIVERSIDAD TECNOLÓGICA FIDEL VELÁZQUEZ
A5: División Académica de Telemática
A6: Carrera en Ingeniería en Redes Inteligentes y Ciberseguridad
A7: Horario de Grupo
A8: Cuatrimestre: Enero - Abril | E8: GRUPO: IRICE701
A9: Período: 2025-1 | C9: TUTOR: HERNANDEZ JIMENEZ ARTURO
A12: Hora | B12: Lunes | C12: Martes | D12: Miércoles | E12: Jueves | F12: Viernes | G12: Sábado
A13: 07:00 08:00
A14: 08:00 09:00 | G14: Administración del Tiempo - M103
A15: 09:00 10:00 | G15: Administración del Tiempo - M103
A16: 10:00 11:00 | G16: Administración Avanzada de Infraestructura Virtualizada - M107
A17: 11:00 12:00 | G17: Administración Avanzada de Infraestructura Virtualizada - M107
A18: 12:00 13:00 | B18: Administración Avanzada de Infraestructura Virtualizada NP | C18: Administración Avanzada de Infraestructura Virtualizada NP | D18: Infraestructura de Centros de Datos NP | E18: Infraestructura de Centros de Datos NP | G18: Inglés VI
A19: 13:00 14:00 | B19: Administración Avanzada de Infraestructura Virtualizada NP | C19: Inglés VI NP | G19: Inglés VI
A20: 14:00 15:00 | B20: Tecnologias para Manejo Masivo de Datos NP | C20: Inglés VI NP
A21: 15:00 16:00 | B21: Tecnologias para Manejo Masivo de Datos NP | C21: Tecnologias para Manejo Masivo de Datos NP
A22: 16:00 17:00 | F22: Tecnologias para Manejo Masivo de Datos - M107
A23: 17:00 18:00 | F23: Tecnologias para Manejo Masivo de Datos - M107
A24: 18:00 19:00 | F24: Infraestructura de Centros de Datos - M107
A25: 19:00 20:00 | D25: Administración del Tiempo* NP | F25: Infraestructura de Centros de Datos - M107
A26: 20:00 21:00 | D26: Cálculo Integral NP | F26: Cálculo Integral - M103
A27: 21:00 22:00 | D27: Cálculo Integral NP | F27: Cálculo Integral - M103
A28: Horario generado: | G28: asc Horarios.
A29: Asignatura | D29: Horas | E29: Profesores
A30: Cálculo Integral | D30: =VLOOKUP(A30, Materias!A2:C180, 3, FALSE) -> 4 | E30: PEREZ SANCHEZ RAFAEL
A31: Administración Avanzada de Infraestructura Virtualizada | D31: =VLOOKUP(A31, Materias!A2:C180, 3, FALSE) -> 5 | E31: VALADEZ VARGAS ALEJANDRO
A32: Tecnologias para Manejo Masivo de Datos | D32: =VLOOKUP(A32, Materias!A2:C180, 3, FALSE) -> 5 | E32: ALFARO LINARES SANDRA
A33: Infraestructura de Centros de Datos | D33: =VLOOKUP(A33, Materias!A2:C180, 3, FALSE) -> 4 | E33: HERNANDEZ JIMENEZ ARTURO
A34: Inglés VI | D34: =VLOOKUP(A34, Materias!A2:C180, 3, FALSE) -> 4 | E34: COORDINACIÓN DE INGLES
A35: Administración del Tiempo* | D35: =VLOOKUP(A35, Materias!A2:C180, 3, FALSE) -> 3 | E35: TIRADOR GOMEZ DANIELA LIZETH
A36: Sesiones/Semana | D36: =SUM(D30:D35) -> 25
A38: Director de la División Académica de Telemática Nombre y Firma del Director (a) de la División Académica
A39: Mtro. Oliver Raúl Velázquez Torres

Sheet IRICE801
D1: }
A3: UNIVERSIDAD TECNOLÓGICA FIDEL VELÁZQUEZ
A5: División Académica de Telemática
A6: Carrera en Ingeniería en Redes Inteligentes y Ciberseguridad
A7: Horario de Grupo
A8: Cuatrimestre: Enero - Abril | E8: GRUPO: IRICE801
A9: Período: 2025-1 | C9: TUTOR: HERNANDEZ JIMENEZ ARTURO
A12: Hora | B12: Lunes | C12: Martes | D12: Miércoles | E12: Jueves | F12: Viernes | G12: Sábado
A13: 07:00 08:00 | G13: Planeación y Organización del Trabajo - M211
A14: 08:00 09:00 | G14: Planeación y Organización del Trabajo - M211
A15: 09:00 10:00 | G15: Cómputo en la Nube - Lab. Diseño PC
A16: 10:00 11:00 | G16: Inglés VII
A17: 11:00 12:00 | B17: Gestión de La Seguridad Informática NP | G17: Inglés VII NP
A18: 12:00 13:00 | B18: Gestión de La Seguridad Informática NP | C18: Gestión de La Seguridad Informática NP | D18: Planeación y Organización del Trabajo_* NP | G18: Dirección de Proyectos I - M211
A19: 13:00 14:00 | B19: Matemáticas para Ingeniería I NP | C19: Matemáticas para Ingeniería I NP | D19: Dirección de Proyectos I NP | G19: Dirección de Proyectos I - M211
A20: 14:00 15:00 | B20: Inglés VII NP | C20: Cómputo en la Nube NP | D20: Dirección de Proyectos I NP
A21: 15:00 16:00 | B21: Inglés VII NP | C21: Inglés VII NP | D21: Cómputo en la Nube NP
A22: 16:00 17:00 | F22: Gestión de La Seguridad Informática - Lab. Diseño PC
A23: 17:00 18:00 | F23: Gestión de La Seguridad Informática - Lab. Diseño PC
A24: 18:00 19:00 | F24: Matemáticas para Ingeniería I - M211
A25: 19:00 20:00 | F25: Matemáticas para Ingeniería I - M211
A26: 20:00 21:00 | F26: Cómputo en la Nube - Lab. Diseño PC
A27: 21:00 22:00 | F27: Cómputo en la Nube - Lab. Diseño PC
A28: Horario generado: | G28: asc Horarios.
A29: Asignatura | D29: Horas | E29: Profesores
A30: Matemáticas para Ingeniería I | D30: =VLOOKUP(A30, Materias!A2:C180, 3, FALSE) -> 4 | E30: GARCIA TRINIDAD ENRIQUE
A31: Gestión de La Seguridad Informática | D31: =VLOOKUP(A31, Materias!A2:C180, 3, FALSE) -> 5 | E31: HERNANDEZ JIMENEZ ARTURO
A32: Cómputo en la Nube | D32: =VLOOKUP(A32, Materias!A2:C180, 3, FALSE) -> 5 | E32: ALFARO LINARES SANDRA
A33: Dirección de Proyectos I | D33: =VLOOKUP(A33, Materias!A2:C180, 3, FALSE) -> 4 | E33: VALADEZ VARGAS ALEJANDRO
A34: Inglés VII | D34: =VLOOKUP(A34, Materias!A2:C180, 3, FALSE) -> 4 | E34: COORDINACIÓN DE INGLES
A35: Planeación y Organización del Trabajo_* | D35: =VLOOKUP(A35, Materias!A2:C180, 3, FALSE) -> 3 | E35: PEREZ SANCHEZ RAFAEL
A36: Sesiones/Semana | D36: =SUM(D30:D35) -> 25
A38: Director de la División Académica de Telemática Nombre y Firma del Director (a) de la División Académica
A39: Mtro. Oliver Raúl Velázquez Torres

Sheet IRICE802
D1: }
A3: UNIVERSIDAD TECNOLÓGICA FIDEL VELÁZQUEZ
A5: División Académica de Telemática
A6: Carrera en Ingeniería en Redes Inteligentes y Ciberseguridad
A7: Horario de Grupo
A8: Cuatrimestre: Enero - Abril | E8: GRUPO: IRICE802
A9: Período: 2025-1 | C9: TUTOR: HERNANDEZ JIMENEZ ARTURO
A12: Hora | B12: Lunes | C12: Martes | D12: Miércoles | E12: Jueves | F12: Viernes | G12: Sábado
A13: 07:00 08:00
A14: 08:00 09:00 | G14: Inglés VII
A15: 09:00 10:00 | G15: Inglés VII
A16: 10:00 11:00 | G16: Cómputo en la Nube - Lab. Diseño PC
A17: 11:00 12:00 | G17: Cómputo en la Nube - Lab. Diseño PC
A18: 12:00 13:00 | B18: Planeación y Organización del Trabajo_* NP | G18: Planeación y Organización del Trabajo - M210
A19: 13:00 14:00 | B19: Cómputo en la Nube NP | C19: Cómputo en la Nube NP | G19: Planeación y Organización del Trabajo - M210
A20: 14:00 15:00 | B20: Matemáticas para Ingeniería I NP | C20: Matemáticas para Ingeniería I NP | D20: Gestión de La Seguridad Informática NP | E20: Gestión de La Seguridad Informática NP | G20: Dirección de Proyectos I - M210
A21: 15:00 16:00 | B21: Inglés VII NP | D21: Dirección de Proyectos I NP | E21: Dirección de Proyectos I NP | G21: Dirección de Proyectos I - M210
A22: 16:00 17:00 | B22: Inglés VII NP | F22: Gestión de La Seguridad Informática - Lab. Info. Básica
A23: 17:00 18:00 | F23: Gestión de La Seguridad Informática - Lab. Info. Básica
A24: 18:00 19:00 | F24: Gestión de La Seguridad Informática - Lab. Info. Básica
A25: 19:00 20:00 | F25: Cómputo en la Nube - Lab. Diseño PC
A26: 20:00 21:00 | F26: Matemáticas para Ingeniería I - M211
A27: 21:00 22:00 | F27: Matemáticas para Ingeniería I - M211
A28: Horario generado: | G28: asc Horarios.
A29: Asignatura | D29: Horas | E29: Profesores
A30: Matemáticas para Ingeniería I | D30: =VLOOKUP(A30, Materias!A2:C180, 3, FALSE) -> 4 | E30: GARCIA TRINIDAD ENRIQUE
A31: Gestión de La Seguridad Informática | D31: =VLOOKUP(A31, Materias!A2:C180, 3, FALSE) -> 5 | E31: INFANTE DE LA FUENTE JUAN GABRIEL
A32: Cómputo en la Nube | D32: =VLOOKUP(A32, Materias!A2:C180, 3, FALSE) -> 5 | E32: ALFARO LINARES SANDRA
A33: Dirección de Proyectos I | D33: =VLOOKUP(A33, Materias!A2:C180, 3, FALSE) -> 4 | E33: VALADEZ VARGAS ALEJANDRO
A34: Inglés VII | D34: =VLOOKUP(A34, Materias!A2:C180, 3, FALSE) -> 4 | E34: COORDINACIÓN DE INGLES
A35: Planeación y Organización del Trabajo_* | D35: =VLOOKUP(A35, Materias!A2:C180, 3, FALSE) -> 3 | E35: PEREZ SANCHEZ RAFAEL
A36: Sesiones/Semana | D36: =SUM(D30:D35) -> 25
A38: Director de la División Académica de Telemática Nombre y Firma del Director (a) de la División Académica
A39: Mtro. Oliver Raúl Velázquez Torres

Sheet DAD101
D1: }
A3: UNIVERSIDAD TECNOLÓGICA FIDEL VELÁZQUEZ
A5: División Académica de Telemática
A6: Carrera en Diseño y Animación Digital
A7: Horario de Grupo
A8: Cuatrimestre: Enero - Abril | E8: GRUPO: DAD101
A9: Período: 2025-1 | C9: TUTOR: MARQUEZ SÁNCHEZ DANIEL MAURICIO
A12: Hora | B12: Lunes | C12: Martes | D12: Miércoles | E12: Jueves | F12: Viernes | G12: Sábado
A13: 07:00 08:00 | B13: Comunicación Gráfica. - L102 | E13: Comunicación Gráfica. - L102 | F13: Actividades Culturales y Deportivas I.
A14: 08:00 09:00 | B14: Fundamentos Matemáticos. - L102 | C14: Comunicación y Habilidades Digitales. - L102 | D14: Fundamentos Matemáticos. - L102 | E14: Comunicación y Habilidades Digitales. - L102 | F14: Actividades Culturales y Deportivas I.
A15: 09:00 10:00 | B15: Fundamentos Matemáticos. - L102 | C15: Comunicación y Habilidades Digitales. - L102 | D15: Fundamentos Matemáticos. - L102 | E15: Comunicación y Habilidades Digitales. - L102 | F15: Comunicación y Habilidades Digitales. - L102
A16: 10:00 11:00 | B16: Inglés I. | C16: Inglés I. | D16: Inglés I. | E16: Inglés I. | F16: Inglés I.
A17: 11:00 12:00 | B17: Representación Visual. - L102 | C17: Desarrollo Humano y Valores. - L102 | D17: Comunicación Gráfica. - L102 | E17: Fundamentos de Diseño y del Lenguaje Visual. - L106 | F17: Fundamentos de Diseño y del Lenguaje Visual. - L106
A18: 12:00 13:00 | B18: Fundamentos de Diseño y del Lenguaje Visual. - L106 | C18: Desarrollo Humano y Valores. - L102 | D18: Tutoría I - L102 | E18: Representación Visual. - L102 | F18: Fundamentos de Diseño y del Lenguaje Visual. - L106
A19: 13:00 14:00 | B19: Fundamentos de Diseño y del Lenguaje Visual. - L106 | C19: Desarrollo Humano y Valores. - L102 | D19: Desarrollo Humano y Valores. - L102 | E19: Fundamentos Matemáticos. - L102 | F19: Fundamentos de Diseño y del Lenguaje Visual. - L106
A20: 14:00 15:00 | B20: Fundamentos de Diseño y del Lenguaje Visual. - L106 | E20: Fundamentos Matemáticos. - L102 | F20: Representación Visual. - L102
A21: 15:00 16:00 | E21: Fundamentos Matemáticos. - L102 | F21: Representación Visual. - L102
A22: 16:00 17:00
A23: 17:00 18:00
A24: 18:00 19:00
A25: 19:00 20:00 | D25: |
A26: 20:00 21:00
A27: 21:00 22:00
A28: Horario generado: | G28: asc Horarios.
A29: Asignatura | D29: Horas | E29: Profesores
A30: Inglés I. | D30: =VLOOKUP(A30, Materias!A2:C180, 3, FALSE) -> 5 | E30: COORDINACIÓN DE INGLES
A31: Desarrollo Humano y Valores. | D31: =VLOOKUP(A31, Materias!A2:C180, 3, FALSE) -> 4 | E31: ROSAS DUARTE ROSA RUTH
A32: Fundamentos Matemáticos. | D32: =VLOOKUP(A32, Materias!A2:C180, 3, FALSE) -> 7 | E32: VARELA OLMOS VIOLETA
A33: Fundamentos de Diseño y del Lenguaje Visual. | D33: =VLOOKUP(A33, Materias!A2:C180, 3, FALSE) -> 7 | E33: ZAMACONA PRADO NAYELI
A34: Representación Visual. | D34: =VLOOKUP(A34, Materias!A2:C180, 3, FALSE) -> 4 | E34: LANDIN HERREJON JOSE LUIS GUSTAVO
A35: Comunicación Gráfica. | D35: =VLOOKUP(A35, Materias!A2:C180, 3, FALSE) -> 3 | E35: BAEZA FLORES MARIA DEL CARMEN
A36: Comunicación y Habilidades Digitales. | D36: =VLOOKUP(A36, Materias!A2:C180, 3, FALSE) -> 5 | E36: VILLA CUETO MA. ISABEL
A37: Tutoría I. | D37: =VLOOKUP(A37, Materias!A2:C180, 3, FALSE) -> 1 | E37: MARQUEZ SÁNCHEZ DANIEL MAURICIO
A38: Actividades Culturales y Deportivas I. | D38: =VLOOKUP(A38, Materias!A2:C180, 3, FALSE) -> 2 | E38: COORDINACIÓN DE DEPORTES
A39: Sesiones/Semana | D39: =SUM(D30:D38) -> 38
A41: Director de la División Académica de Telemática Nombre y Firma del Director (a) de la División Académica
A42: Mtro. Oliver Raúl Velázquez Torres

Sheet DAD201
D1: }
A3: UNIVERSIDAD TECNOLÓGICA FIDEL VELÁZQUEZ
A5: División Académica de Telemática
A6: Carrera en Diseño y Animación Digital
A7: Horario de Grupo
A8: Cuatrimestre: Enero - Abril | E8: GRUPO: DAD201
A9: Período: 2025-1 | C9: TUTOR: GARCIA ROMERO LUIS ANGEL
A12: Hora | B12: Lunes | C12: Martes | D12: Miércoles | E12: Jueves | F12: Viernes | G12: Sábado
A13: 07:00 08:00 | D13: Geometría Descriptiva. - Lab. Diseño PC | F13: Actividades Culturales y Deportivas II
A14: 08:00 09:00 | B14: Representación Geométrica. - BITMAP | C14: Representación Geométrica. - BITMAP | D14: Geometría Descriptiva. - Lab. Diseño PC | E14: Habilidades Socioemocionales y Manejo de Conflictos. - M211 | F14: Actividades Culturales y Deportivas II
A15: 09:00 10:00 | B15: Representación Geométrica. - BITMAP | C15: Representación Geométrica. - BITMAP | D15: Geometría Descriptiva. - Lab. Diseño PC | E15: Habilidades Socioemocionales y Manejo de Conflictos. - M211 | F15: Ilustración Digital. - M204
A16: 10:00 11:00 | B16: Inglés II | C16: Inglés II | D16: Inglés II | E16: Inglés II | F16: Inglés II
A17: 11:00 12:00 | B17: Modelado Manual. - M210 | C17: Mercadotecnia. - M210 | D17: Modelado Manual. - M210 | E17: Ilustración Digital. - M204 | F17: Modelado Manual. - M210
A18: 12:00 13:00 | B18: Modelado Manual. - M210 | C18: Mercadotecnia. - M210 | D18: Modelado Manual. - M210 | E18: Ilustración Digital. - M204 | F18: Habilidades Socioemocionales y Manejo de Conflictos. - M211
A19: 13:00 14:00 | B19: Ilustración Digital. - M204 | C19: Mercadotecnia. - M210 | D19: Representación Geométrica. - BITMAP | E19: Ilustración Digital. - M204 | F19: Habilidades Socioemocionales y Manejo de Conflictos. - M211
A20: 14:00 15:00 | B20: Ilustración Digital. - M204 | C20: Geometría Descriptiva. - M104 | D20: Representación Geométrica. - BITMAP | E20: Geometría Descriptiva. - M104 | F20: Representación Geométrica. - M210
A21: 15:00 16:00 | B21: Emprendimiento Wadhwani NP | D21: Emprendimiento Wadhwani NP | F21: Tutoría II. - M210
A22: 16:00 17:00 | B22: Emprendimiento Wadhwani NP | C22: Emprendimiento Wadhwani NP | F22: Emprendimiento Wadhwani NP
A23: 17:00 18:00
A24: 18:00 19:00
A25: 19:00 20:00
A26: 20:00 21:00
A27: 21:00 22:00
A28: Horario generado: | G28: asc Horarios.
A29: Asignatura | D29: Horas | E29: Profesores
A30: Inglés II. | D30: =VLOOKUP(A30, Materias!A2:C180, 3, FALSE) -> 5 | E30: COORDINACIÓN DE INGLES
A31: Habilidades Socioemocionales y Manejo de Conflictos. | D31: =VLOOKUP(A31, Materias!A2:C180, 3, FALSE) -> 4 | E31: ROSAS DUARTE ROSA RUTH
A32: Geometría Descriptiva. | D32: =VLOOKUP(A32, Materias!A2:C180, 3, FALSE) -> 5 | E32: MARQUEZ SANCHEZ DANIEL MAURICIO
A33: Ilustración Digital. | D33: =VLOOKUP(A33, Materias!A2:C180, 3, FALSE) -> 6 | E33: MENDOZA CALVA HECTOR RAUL
A34: Modelado Manual. | D34: =VLOOKUP(A34, Materias!A2:C180, 3, FALSE) -> 5 | E34: IBARRA VAZQUEZ JESSICA DANIELA
A35: Representación Geométrica. | D35: =VLOOKUP(A35, Materias!A2:C180, 3, FALSE) -> 7 | E35: GARCIA ROMERO LUIS ANGEL
A36: Mercadotecnia. | D36: =VLOOKUP(A36, Materias!A2:C180, 3, FALSE) -> 3 | E36: ZAMACONA PRADO NAYELI
A37: Tutoría II. | D37: =VLOOKUP(A37, Materias!A2:C180, 3, FALSE) -> 1 | E37: GARCIA ROMERO LUIS ANGEL
A38: Actividades Culturales y Deportivas II. | D38: =VLOOKUP(A38, Materias!A1:C179, 3, FALSE) -> 2 | E38: COORDINACIÓN DE DEPORTES
A39: Emprendimiento Wadhwani | D39: 5 | E39: RODRÍGUEZ RIVERA NAYELI BERENICE
A40: Sesiones/Semana | D40: =SUM(D30:D38) -> 38
A42: Director de la División Académica de Telemática Nombre y Firma del Director (a) de la División Académica
A43: Mtro. Oliver Raúl Velázquez Torres

Sheet DAD202
D1: }
A3: UNIVERSIDAD TECNOLÓGICA FIDEL VELÁZQUEZ
A5: División Académica de Telemática
A6: Carrera en Diseño y Animación Digital
A7: Horario de Grupo
A8: Cuatrimestre: Enero - Abril | E8: GRUPO: DAD202
A9: Período: 2025-1 | C9: TUTOR: MARQUEZ SANCHEZ DANIEL MAURICIO
A12: Hora | B12: Lunes | C12: Martes | D12: Miércoles | E12: Jueves | F12: Viernes | G12: Sábado
A13: 07:00 08:00 | B13: Representación Geométrica. - M210 | F13: Actividades Culturales y Deportivas II.
A14: 08:00 09:00 | B14: Representación Geométrica. - M210 | C14: Tutoría II. -M210 | D14: Representación Geométrica. - M210 | E14: Modelado Manual. - M210 | F14: Actividades Culturales y Deportivas II.
A15: 09:00 10:00 | B15: Representación Geométrica. - M210 | C15: Geometría Descriptiva. - M210 | D15: Mercadotecnia. - M211 | E15: Modelado Manual. - M210 | F15: Modelado Manual. - M210
A16: 10:00 11:00 | B16: Inglés II. | C16: Inglés II. | D16: Inglés II. | E16: Inglés II. | F16: Inglés II.
A17: 11:00 12:00 | B17: Ilustración Digital. - BITMAP | C17: Representación Geométrica. - CCAI PC | D17: Habilidades Socioemocionales y Manejo de Conflictos. - M211 | E17: Habilidades Socioemocionales y Manejo de Conflictos. - M211 | F17: Ilustración Digital. - BITMAP
A18: 12:00 13:00 | B18: Ilustración Digital. - BITMAP | C18: Representación Geométrica. - CCAI PC | D18: Habilidades Socioemocionales y Manejo de Conflictos. - M211 | E18: Habilidades Socioemocionales y Manejo de Conflictos. - M211 | F18: Ilustración Digital. - BITMAP
A19: 13:00 14:00 | B19: Modelado Manual. - M210 | C19: Representación Geométrica. - CCAI PC | D19: Modelado Manual. - M210 | E19: Mercadotecnia. - M211 | F19: Geometría Descriptiva. - M102
A20: 14:00 15:00 | B20: Geometría Descriptiva. M210 | C20: Ilustración Digital. - BITMAP | D20: Geometría Descriptiva. - M210 | E20: Mercadotecnia. - M211 | F20: Geometría Descriptiva. - M102
A21: 15:00 16:00 | B21: Emprendimiento Wadhwani NP | C21: Ilustración Digital. - BITMAP | D21: Emprendimiento Wadhwani NP
A22: 16:00 17:00 | B22: Emprendimiento Wadhwani NP | C22: Emprendimiento Wadhwani NP | F22: Emprendimiento Wadhwani NP
A23: 17:00 18:00
A24: 18:00 19:00
A25: 19:00 20:00
A26: 20:00 21:00
A27: 21:00 22:00
A28: Horario generado: | G28: asc Horarios.
A29: Asignatura | D29: Horas | E29: Profesores
A30: Inglés II. | D30: =VLOOKUP(A30, Materias!A2:C180, 3, FALSE) -> 5 | E30: COORDINACIÓN DE INGLES
A31: Habilidades Socioemocionales y Manejo de Conflictos. | D31: =VLOOKUP(A31, Materias!A2:C180, 3, FALSE) -> 4 | E31: ROSAS DUARTE ROSA RUTH
A32: Geometría Descriptiva. | D32: =VLOOKUP(A32, Materias!A2:C180, 3, FALSE) -> 5 | E32: MARQUEZ SANCHEZ DANIEL MAURICIO
A33: Ilustración Digital. | D33: =VLOOKUP(A33, Materias!A2:C180, 3, FALSE) -> 6 | E33: MENDOZA CALVA HECTOR RAUL
A34: Modelado Manual. | D34: =VLOOKUP(A34, Materias!A2:C180, 3, FALSE) -> 5 | E34: IBARRA VAZQUEZ JESSICA DANIELA
A35: Representación Geométrica. | D35: =VLOOKUP(A35, Materias!A2:C180, 3, FALSE) -> 7 | E35: BERNAL FUENTES SILVIA GUADALUPE
A36: Mercadotecnia. | D36: =VLOOKUP(A36, Materias!A2:C180, 3, FALSE) -> 3 | E36: ZAMACONA PRADO NAYELI
A37: Tutoría II. | D37: =VLOOKUP(A37, Materias!A2:C180, 3, FALSE) -> 1 | E37: MARQUEZ SANCHEZ DANIEL MAURICIO
A38: Actividades Culturales y Deportivas II. | D38: =VLOOKUP(A38, Materias!A1:C179, 3, FALSE) -> 2 | E38: COORDINACIÓN DE DEPORTES
A39: Emprendimiento Wadhwani | D39: 5 | E39: RODRÍGUEZ RIVERA NAYELI BERENICE
A40: Sesiones/Semana | D40: =SUM(D30:D38) -> 38
A42: Director de la División Académica de Telemática Nombre y Firma del Director (a) de la División Académica
A43: Mtro. Oliver Raúl Velázquez Torres

Sheet DAD203
D1: }
A3: UNIVERSIDAD TECNOLÓGICA FIDEL VELÁZQUEZ
A5: División Académica de Telemática
A6: Carrera en Diseño y Animación Digital
A7: Horario de Grupo
A8: Cuatrimestre: Enero - Abril | E8: GRUPO: DAD203
A9: Período: 2025-1 | C9: TUTOR: DESCHAMPS SOLORZANO JOSÉ ALEJANDRO
A12: Hora | B12: Lunes | C12: Martes | D12: Miércoles | E12: Jueves | F12: Viernes | G12: Sábado
A13: 07:00 08:00 | E13: Geometría Descriptiva. - Lab. Info. Básica | F13: Actividades Culturales y Deportivas II.
A14: 08:00 09:00 | B14: Ilustración Digital. - M204 | C14: Ilustración Digital. - M204 | D14: Ilustración Digital. - M204 | E14: Geometría Descriptiva. - Lab. Info. Básica | F14: Actividades Culturales y Deportivas II.
A15: 09:00 10:00 | B15: Ilustración Digital. - M204 | C15: Ilustración Digital. - M204 | D15: Ilustración Digital. - M204 | E15: Geometría Descriptiva. - Lab. Info. Básica | F15: Habilidades Socioemocionales y Manejo de Conflictos. - M206
A16: 10:00 11:00 | B16: Inglés II. | C16: Inglés II. | D16: Inglés II. | E16: Inglés II. | F16: Inglés II.
A17: 11:00 12:00 | B17: Geometría Descriptiva. - Lab. Info. Básica | C17: Habilidades Socioemocionales y Manejo de Conflictos. - M206 | D17: Mercadotecnia. - M206 | E17: Modelado Manual. - M206 | F17: Representación Geométrica. - M204
A18: 12:00 13:00 | B18: Geometría Descriptiva. - Lab. Info. Básica | C18: Representación Geométrica. - M206 | D18: Mercadotecnia. - M206 | E18: Modelado Manual. - M206 | F18: Representación Geométrica. - M204
A19: 13:00 14:00 | B19: Modelado Manual. - M206 | C19: Modelado Manual. - M206 | D19: Mercadotecnia. - M206 | E19: Modelado Manual. - M206 | F19: Representación Geométrica. - M204
A20: 14:00 15:00 | C20: Tutoría II. - M206 | D20: Habilidades Socioemocionales y Manejo de Conflictos. - M206 | E20: Representación Geométrica. - M206
A21: 15:00 16:00 | B21: Representación Geométrica. - M206 | D21: Habilidades Socioemocionales y Manejo de Conflictos. - M206 | E21: Representación Geométrica. - M206
A22: 16:00 17:00
A23: 17:00 18:00
A24: 18:00 19:00
A25: 19:00 20:00
A26: 20:00 21:00
A27: 21:00 22:00
A28: Horario generado: | G28: asc Horarios.
A29: Asignatura | D29: Horas | E29: Profesores
A30: Inglés II. | D30: =VLOOKUP(A30, Materias!A2:C180, 3, FALSE) -> 5 | E30: COORDINACIÓN DE INGLES
A31: Habilidades Socioemocionales y Manejo de Conflictos. | D31: =VLOOKUP(A31, Materias!A2:C180, 3, FALSE) -> 4 | E31: DESCHAMPS SOLORZANO JOSE ALEJANDRO
A32: Geometría Descriptiva. | D32: =VLOOKUP(A32, Materias!A2:C180, 3, FALSE) -> 5 | E32: MARQUEZ SANCHEZ DANIEL MAURICIO
A33: Ilustración Digital. | D33: =VLOOKUP(A33, Materias!A2:C180, 3, FALSE) -> 6 | E33: ORDOÑEZ MORALES LUIS MARTIN
A34: Modelado Manual. | D34: =VLOOKUP(A34, Materias!A2:C180, 3, FALSE) -> 5 | E34: MALDONADO GUERRERO ALHAN GERARD
A35: Representación Geométrica. | D35: =VLOOKUP(A35, Materias!A2:C180, 3, FALSE) -> 7 | E35: GARCIA ROMERO LUIS ANGEL
A36: Mercadotecnia. | D36: =VLOOKUP(A36, Materias!A2:C180, 3, FALSE) -> 3 | E36: ZAMACONA PRADO NAYELI
A37: Tutoría II. | D37: =VLOOKUP(A37, Materias!A2:C180, 3, FALSE) -> 1 | E37: DESCHAMPS SOLORZANO JOSÉ ALEJANDRO
A38: Actividades Culturales y Deportivas II. | D38: =VLOOKUP(A38, Materias!A2:C180, 3, FALSE) -> 2 | E38: COORDINACIÓN DE DEPORTES
A39: Sesiones/Semana | D39: =SUM(D30:D38) -> 38
A41: Director de la División Académica de Telemática Nombre y Firma del Director (a) de la División Académica
A42: Mtro. Oliver Raúl Velázquez Torres

Sheet DAD204
D1: }
A3: UNIVERSIDAD TECNOLÓGICA FIDEL VELÁZQUEZ
A5: División Académica de Telemática
A6: Carrera en Diseño y Animación Digital
A7: Horario de Grupo
A8: Cuatrimestre: Enero - Abril | E8: GRUPO: DAD204
A9: Período: 2025-1 | C9: TUTOR: DESCHAMPS SOLORZANO JOSE ALEJANDRO
A12: Hora | B12: Lunes | C12: Martes | D12: Miércoles | E12: Jueves | F12: Viernes | G12: Sábado
A13: 07:00 08:00 | B13: Geometría Descriptiva. - Lab. Info. Básica | C13: Geometría Descriptiva. - M207 | E13: Habilidades Socioemocionales y Manejo de Conflictos. - M207 | F13: Actividades Culturales y Deportivas II.
A14: 08:00 09:00 | B14: Geometría Descriptiva. - Lab. Info. Básica | C14: Modelado Manual. - M207 | D14: Mercadotecnia. - M207 | E14: Mercadotecnia. - M207 | F14: Actividades Culturales y Deportivas II.
A15: 09:00 10:00 | B15: Geometría Descriptiva. - Lab. Info. Básica | C15: Modelado Manual. - M207 | D15: Modelado Manual. - M207 | E15: Mercadotecnia. - M207 | F15: Geometría Descriptiva. - M207
A16: 10:00 11:00 | B16: Inglés II. | C16: Inglés II. | D16: Inglés II. | E16: Inglés II. | F16: Inglés II.
A17: 11:00 12:00 | B17: Modelado Manual. - M207 | C17: Representación Geométrica. - M204 | D17: Ilustración Digital. - Lab. Info. Básica | E17: Ilustración Digital. - Lab. Info. Básica | F17: Ilustración Digital. - Lab. Info. Básica
A18: 12:00 13:00 | B18: Representación Geométrica. - M201 | C18: Representación Geométrica. - M204 | D18: Ilustración Digital. - Lab. Info. Básica | E18: Ilustración Digital. - Lab. Info. Básica | F18: Ilustración Digital. - Lab. Info. Básica
A19: 13:00 14:00 | B19: Representación Geométrica. - M201 | C19: Representación Geométrica. - M204 | D19: Representación Geométrica. - M207 | E19: Representación Geométrica. - M207 | F19: Habilidades Socioemocionales y Manejo de Conflictos. - M207
A20: 14:00 15:00 | B20: Tutoría II. - M201 | E20: Modelado Manual. - M207 | F20: Habilidades Socioemocionales y Manejo de Conflictos. - M207
A21: 15:00 16:00 | F21: Habilidades Socioemocionales y Manejo de Conflictos. - M207
A22: 16:00 17:00
A23: 17:00 18:00
A24: 18:00 19:00
A25: 19:00 20:00
A26: 20:00 21:00
A27: 21:00 22:00
A28: Horario generado: | G28: asc Horarios.
A29: Asignatura | D29: Horas | E29: Profesores
A30: Inglés II. | D30: =VLOOKUP(A30, Materias!A2:C180, 3, FALSE) -> 5 | E30: COORDINACIÓN DE INGLES
A31: Habilidades Socioemocionales y Manejo de Conflictos. | D31: =VLOOKUP(A31, Materias!A2:C180, 3, FALSE) -> 4 | E31: ROMERO ROJAS RUTH MARCELA
A32: Geometría Descriptiva. | D32: =VLOOKUP(A32, Materias!A2:C180, 3, FALSE) -> 5 | E32: MARQUEZ SANCHEZ DANIEL MAURICIO
A33: Ilustración Digital. | D33: =VLOOKUP(A33, Materias!A2:C180, 3, FALSE) -> 6 | E33: ROJAS DIEGO RAUL
A34: Modelado Manual. | D34: =VLOOKUP(A34, Materias!A2:C180, 3, FALSE) -> 5 | E34: DESCHAMPS SOLORZANO JOSE ALEJANDRO
A35: Representación Geométrica. | D35: =VLOOKUP(A35, Materias!A2:C180, 3, FALSE) -> 7 | E35: SERRANO SILVA IVAN ENRIQUE
A36: Mercadotecnia. | D36: =VLOOKUP(A36, Materias!A2:C180, 3, FALSE) -> 3 | E36: LANDIN HERREJON JOSE LUIS GUSTAVO
A37: Tutoría II. | D37: =VLOOKUP(A37, Materias!A2:C180, 3, FALSE) -> 1 | E37: DESCHAMPS SOLORZANO JOSE ALEJANDRO
A38: Actividades Culturales y Deportivas II. | D38: =VLOOKUP(A38, Materias!A2:C180, 3, FALSE) -> 2 | E38: COORDINACIÓN DE DEPORTES
A39: Sesiones/Semana | D39: =SUM(D30:D38) -> 38
A41: Director de la División Académica de Telemática Nombre y Firma del Director (a) de la División Académica
A42: Mtro. Oliver Raúl Velázquez Torres

Sheet DAD205
D1: }
A3: UNIVERSIDAD TECNOLÓGICA FIDEL VELÁZQUEZ
A5: División Académica de Telemática
A6: Carrera en Diseño y Animación Digital
A7: Horario de Grupo
A8: Cuatrimestre: Enero - Abril | E8: GRUPO: DAD205
A9: Período: 2025-1 | C9: TUTOR: TORRES HERNANDEZ LUIS ENRIQUE
A12: Hora | B12: Lunes | C12: Martes | D12: Miércoles | E12: Jueves | F12: Viernes | G12: Sábado
A13: 07:00 08:00
A14: 08:00 09:00
A15: 09:00 10:00
A16: 10:00 11:00
A17: 11:00 12:00
A18: 12:00 13:00 | B18: Habilidades Socioemocionales y Manejo de Conflictos. - M209
A19: 13:00 14:00 | B19: Modelado Manual. - M207 | C19: Geometría Descriptiva. - Lab. Info. Básica | D19: Ilustración Digital. - Lab. Info. Básica | E19: Ilustración Digital. - Lab. Info. Básica | F19: Habilidades Socioemocionales y Manejo de Conflictos. - M209
A20: 14:00 15:00 | B20: Modelado Manual. - M207 | C20: Geometría Descriptiva. - Lab. Info. Básica | D20: Ilustración Digital. - Lab. Info. Básica | E20: Ilustración Digital. - Lab. Info. Básica | F20: Habilidades Socioemocionales y Manejo de Conflictos. - M209
A21: 15:00 16:00 | B21: Modelado Manual. - M207 | C21: Geometría Descriptiva. - Lab. Info. Básica | D21: Ilustración Digital. - Lab. Info. Básica | E21: Ilustración Digital. - Lab. Info. Básica | F21: Habilidades Socioemocionales y Manejo de Conflictos. - M209
A22: 16:00 17:00 | B22: Inglés II. | C22: Inglés II. | D22: Inglés II. | E22: Inglés II. | F22: Inglés II.
A23: 17:00 18:00 | B23: Representación Geométrica. - Lab. Info. Básica | C23: Modelado Manual. - M207 | D23: Geometría Descriptiva. - Lab. Info. Básica | E23: Mercadotecnia. - M207 | F23: Actividades Culturales y Deportivas II.
A24: 18:00 19:00 | B24: Representación Geométrica. - Lab. Info. Básica | C24: Modelado Manual. - M207 | D24: Geometría Descriptiva. - Lab. Info. Básica | E24: Mercadotecnia. - M207 | F24: Actividades Culturales y Deportivas II.
A25: 19:00 20:00 | B25: Representación Geométrica. - Lab. Info. Básica | D25: Representación Geométrica. - Lab. Info. Básica | E25: Mercadotecnia. - M207 | F25: Representación Geométrica. - Lab. Info. Básica
A26: 20:00 21:00 | B26: Tutoría II. - Lab. Info. Básica | D26: Representación Geométrica. - Lab. Info. Básica | F26: Representación Geométrica. - Lab. Info. Básica
A27: 21:00 22:00
A28: Horario generado: | G28: asc Horarios.
A29: Asignatura | D29: Horas | E29: Profesores
A30: Inglés II. | D30: =VLOOKUP(A30, Materias!A2:C180, 3, FALSE) -> 5 | E30: COORDINACIÓN DE INGLES
A31: Habilidades Socioemocionales y Manejo de Conflictos. | D31: =VLOOKUP(A31, Materias!A2:C180, 3, FALSE) -> 4 | E31: DESCHAMPS SOLORZANO JOSE ALEJANDRO
A32: Geometría Descriptiva. | D32: =VLOOKUP(A32, Materias!A2:C180, 3, FALSE) -> 5 | E32: MARTINEZ VEGA FERMIN
A33: Ilustración Digital. | D33: =VLOOKUP(A33, Materias!A2:C180, 3, FALSE) -> 6 | E33: ROJAS DIEGO RAUL
A34: Modelado Manual. | D34: =VLOOKUP(A34, Materias!A2:C180, 3, FALSE) -> 5 | E34: GONZALEZ GARCIA VERONICA
A35: Representación Geométrica. | D35: =VLOOKUP(A35, Materias!A2:C180, 3, FALSE) -> 7 | E35: TORRES HERNANDEZ LUIS ENRIQUE
A36: Mercadotecnia. | D36: =VLOOKUP(A36, Materias!A2:C180, 3, FALSE) -> 3 | E36: RAMOS GAMA JOSELYN KAREN
A37: Tutoría II. | D37: =VLOOKUP(A37, Materias!A2:C180, 3, FALSE) -> 1 | E37: TORRES HERNANDEZ LUIS ENRIQUE
A38: Actividades Culturales y Deportivas II. | D38: =VLOOKUP(A38, Materias!A2:C180, 3, FALSE) -> 2 | E38: COORDINACIÓN DE DEPORTES
A39: Sesiones/Semana | D39: =SUM(D30:D38) -> 38
A41: Director de la División Académica de Telemática Nombre y Firma del Director (a) de la División Académica
A42: Mtro. Oliver Raúl Velázquez Torres

Sheet DAD206
D1: }
A3: UNIVERSIDAD TECNOLÓGICA FIDEL VELÁZQUEZ
A5: División Académica de Telemática
A6: Carrera en Diseño y Animación Digital
A7: Horario de Grupo
A8: Cuatrimestre: Enero - Abril | E8: GRUPO: DAD206
A9: Período: 2025-1 | C9: TUTOR: ESPINOSA JIMENEZ MARIA MARGARITA
A12: Hora | B12: Lunes | C12: Martes | D12: Miércoles | E12: Jueves | F12: Viernes | G12: Sábado
A13: 07:00 08:00
A14: 08:00 09:00
A15: 09:00 10:00
A16: 10:00 11:00
A17: 11:00 12:00
A18: 12:00 13:00 | C18: Mercadotecnia. - M211 | E18: Habilidades Socioemocionales y Manejo de Conflictos. - M201 | F18: Tutoría II. M201
A19: 13:00 14:00 | B19: Representación Geométrica. - Lab. Diseño PC | C19: Mercadotecnia. - M211 | D19: Mercadotecnia. - M211 | E19: Habilidades Socioemocionales y Manejo de Conflictos. - M201 | F19: Modelado Manual. - M206
A20: 14:00 15:00 | B20: Representación Geométrica. - Lab. Diseño PC | C20: Ilustración Digital. - CCAI PC | D20: Representación Geométrica. - Lab. Diseño PC | E20: Representación Geométrica. - M201 | F20: Modelado Manual. - M206
A21: 15:00 16:00 | B21: Representación Geométrica. - Lab. Diseño PC | C21: Ilustración Digital. - CCAI PC | D21: Representación Geométrica. - Lab. Diseño PC | E21: Representación Geométrica. - M201 | F21: Modelado Manual. - M206
A22: 16:00 17:00 | B22: Inglés II. | C22: Inglés II. | D22: Inglés II. | E22: Inglés II. | F22: Inglés II.
A23: 17:00 18:00 | B23: Ilustración Digital. - CCAI PC | C23: Habilidades Socioemocionales y Manejo de Conflictos. - M201 | D23: Ilustración Digital. - CCAI PC | E23: Modelado Manual. - M206 | F23: Actividades Culturales y Deportivas II.
A24: 18:00 19:00 | B24: Ilustración Digital. - CCAI PC | C24: Habilidades Socioemocionales y Manejo de Conflictos. - M201 | D24: Ilustración Digital. - CCAI PC | E24: Modelado Manual. - M206 | F24: Actividades Culturales y Deportivas II.
A25: 19:00 20:00 | B25: Geometría Descriptiva. - Lab. Diseño PC | D25: Geometría Descriptiva. - Lab. Diseño PC | E25: Geometría Descriptiva. - Lab. Diseño PC
A26: 20:00 21:00 | B26: Geometría Descriptiva. - Lab. Diseño PC | D26: Geometría Descriptiva. - Lab. Diseño PC
A27: 21:00 22:00
A28: Horario generado: | G28: asc Horarios.
A29: Asignatura | D29: Horas | E29: Profesores
A30: Inglés II. | D30: =VLOOKUP(A30, Materias!A2:C180, 3, FALSE) -> 5 | E30: COORDINACIÓN DE INGLES
A31: Habilidades Socioemocionales y Manejo de Conflictos. | D31: =VLOOKUP(A31, Materias!A2:C180, 3, FALSE) -> 4 | E31: ESPINOSA JIMENEZ MARIA MARGARITA
A32: Geometría Descriptiva. | D32: =VLOOKUP(A32, Materias!A2:C180, 3, FALSE) -> 5 | E32: GOMEZ GONZALEZ JORGE
A33: Ilustración Digital. | D33: =VLOOKUP(A33, Materias!A2:C180, 3, FALSE) -> 6 | E33: SERRANO SILVA IVAN ENRIQUE
A34: Modelado Manual. | D34: =VLOOKUP(A34, Materias!A2:C180, 3, FALSE) -> 5 | E34: GONZALEZ GARCIA VERONICA
A35: Representación Geométrica. | D35: =VLOOKUP(A35, Materias!A2:C180, 3, FALSE) -> 7 | E35: LANDIN HERREJON JOSE LUIS GUSTAVO
A36: Mercadotecnia. | D36: =VLOOKUP(A36, Materias!A2:C180, 3, FALSE) -> 3 | E36: DESCHAMPS SOLORZANO JOSE ALEJANDRO
A37: Tutoría II. | D37: =VLOOKUP(A37, Materias!A2:C180, 3, FALSE) -> 1 | E37: ESPINOSA JIMENEZ MARIA MARGARITA
A38: Actividades Culturales y Deportivas II. | D38: =VLOOKUP(A38, Materias!A2:C180, 3, FALSE) -> 2 | E38: COORDINACIÓN DE DEPORTES
A39: Sesiones/Semana | D39: =SUM(D30:D38) -> 38
A41: Director de la División Académica de Telemática Nombre y Firma del Director (a) de la División Académica
A42: Mtro. Oliver Raúl Velázquez Torres

Sheet DAD207
D1: }
A3: UNIVERSIDAD TECNOLÓGICA FIDEL VELÁZQUEZ
A5: División Académica de Telemática
A6: Carrera en Diseño y Animación Digital
A7: Horario de Grupo
A8: Cuatrimestre: Enero - Abril | E8: GRUPO: DAD207
A9: Período: 2025-1 | C9: TUTOR: RODRIGUEZ RIVERA NAYELI BERENICE
A12: Hora | B12: Lunes | C12: Martes | D12: Miércoles | E12: Jueves | F12: Viernes | G12: Sábado
A13: 07:00 08:00
A14: 08:00 09:00
A15: 09:00 10:00
A16: 10:00 11:00
A17: 11:00 12:00 | E17: Habilidades Socioemocionales y Manejo de Conflictos. - M209
A18: 12:00 13:00 | B18: Representación Geométrica. - L102 | D18: Habilidades Socioemocionales y Manejo de Conflictos. - M209 | E18: Habilidades Socioemocionales y Manejo de Conflictos. - M209 | F18: Representación Geométrica. - L102
A19: 13:00 14:00 | B19: Habilidades Socioemocionales y Manejo de Conflictos. - M209 | C19: Representación Geométrica. - M203 | D19: Representación Geométrica. - M203 | E19: Modelado Manual. - M210 | F19: Representación Geométrica. - L102
A20: 14:00 15:00 | B20: Ilustración Digital. - CCAI PC | C20: Representación Geométrica. - M203 | D20: Ilustración Digital. - CCAI PC | E20: Modelado Manual. - M210 | F20: Geometría Descriptiva. - M106
A21: 15:00 16:00 | B21: Ilustración Digital. - CCAI PC | C21: Representación Geométrica. - M203 | D21: Ilustración Digital. - CCAI PC | E21: Modelado Manual. - M210 | F21: Geometría Descriptiva. - M106
A22: 16:00 17:00 | B22: Inglés II. | C22: Inglés II. | D22: Inglés II. | E22: Inglés II. | F22: Inglés II.
A23: 17:00 18:00 | B23: Modelado Manual. - M210 | C23: Ilustración Digital. - CCAI PC | D23: Geometría Descriptiva. - M106 | F23: Actividades Culturales y Deportivas II.
A24: 18:00 19:00 | B24: Modelado Manual. - M210 | C24: Ilustración Digital. - CCAI PC | D24: Geometría Descriptiva. - M106 | F24: Actividades Culturales y Deportivas II.
A25: 19:00 20:00 | B25: Mercadotecnia. - M209 | C25: Mercadotecnia. - M209 | D25: Geometría Descriptiva. - M106
A26: 20:00 21:00 | C26: Mercadotecnia. - M209 | D26: Tutoría II. - M106
A27: 21:00 22:00
A28: Horario generado: | G28: asc Horarios.
A29: Asignatura | D29: Horas | E29: Profesores
A30: Inglés II. | D30: =VLOOKUP(A30, Materias!A2:C180, 3, FALSE) -> 5 | E30: COORDINACIÓN DE INGLES
A31: Habilidades Socioemocionales y Manejo de Conflictos. | D31: =VLOOKUP(A31, Materias!A2:C180, 3, FALSE) -> 4 | E31: DESCHAMPS SOLORZANO JOSE ALEJANDRO
A32: Geometría Descriptiva. | D32: =VLOOKUP(A32, Materias!A2:C180, 3, FALSE) -> 5 | E32: RODRIGUEZ RIVERA NAYELI BERENICE
A33: Ilustración Digital. | D33: =VLOOKUP(A33, Materias!A2:C180, 3, FALSE) -> 6 | E33: SERRANO SILVA IVAN ENRIQUE
A34: Modelado Manual. | D34: =VLOOKUP(A34, Materias!A2:C180, 3, FALSE) -> 5 | E34: GONZALEZ GARCIA VERONICA
A35: Representación Geométrica. | D35: =VLOOKUP(A35, Materias!A2:C180, 3, FALSE) -> 7 | E35: LANDIN HERREJON JOSE LUIS GUSTAVO
A36: Mercadotecnia. | D36: =VLOOKUP(A36, Materias!A2:C180, 3, FALSE) -> 3 | E36: RAMOS GAMA JOSELYN KAREN
A37: Tutoría II. | D37: =VLOOKUP(A37, Materias!A2:C180, 3, FALSE) -> 1 | E37: RODRIGUEZ RIVERA NAYELI BERENICE
A38: Actividades Culturales y Deportivas II. | D38: =VLOOKUP(A38, Materias!A2:C180, 3, FALSE) -> 2 | E38: COORDINACIÓN DE DEPORTES
A39: Sesiones/Semana | D39: =SUM(D30:D38) -> 38
A41: Director de la División Académica de Telemática Nombre y Firma del Director (a) de la División Académica
A42: Mtro. Oliver Raúl Velázquez Torres

Sheet DAD208
D1: }
A3: UNIVERSIDAD TECNOLÓGICA FIDEL VELÁZQUEZ
A5: División Académica de Telemática
A6: Carrera en Diseño y Animación Digital
A7: Horario de Grupo
A8: Cuatrimestre: Enero - Abril | E8: GRUPO: DAD208
A9: Período: 2025-1 | C9: TUTOR: GONZALEZ GARCIA VERONICA
A12: Hora | B12: Lunes | C12: Martes | D12: Miércoles | E12: Jueves | F12: Viernes | G12: Sábado
A13: 07:00 08:00
A14: 08:00 09:00
A15: 09:00 10:00
A16: 10:00 11:00 | B16: Emprendimiento Wadhwani NP
A17: 11:00 12:00 | B17: Emprendimiento Wadhwani NP | C17: Emprendimiento Wadhwani NP | D17: Emprendimiento Wadhwani NP
A18: 12:00 13:00 | D18: Emprendimiento Wadhwani NP
A19: 13:00 14:00 | B19: Geometría Descriptiva. - Lab. Info. Básica | C19: Habilidades Socioemocionales y Manejo de Conflictos. - M201 | D19: Mercadotecnia. - M201 | F19: Representación Geométrica. - Lab. Info. Básica
A20: 14:00 15:00 | B20: Geometría Descriptiva. - Lab. Info. Básica | C20: Habilidades Socioemocionales y Manejo de Conflictos. - M201 | D20: Mercadotecnia. - M201 | E20: Ilustración Digital. - CCAI PC | F20: Representación Geométrica. - Lab. Info. Básica
A21: 15:00 16:00 | B21: Geometría Descriptiva. - Lab. Info. Básica | C21: Habilidades Socioemocionales y Manejo de Conflictos. - M201 | D21: Mercadotecnia. - M201 | E21: Ilustración Digital. - CCAI PC | F21: Representación Geométrica. - Lab. Info. Básica
A22: 16:00 17:00 | B22: Inglés II. | C22: Inglés II. | D22: Inglés II. | E22: Inglés II. | F22: Inglés II.
A23: 17:00 18:00 | B23: Habilidades Socioemocionales y Manejo de Conflictos. - M201 | C23: Geometría Descriptiva. - Lab. Info. Básica | D23: Representación Geométrica. - Lab. Diseño PC | E23: Representación Geométrica. - Lab. Info. Básica | F23: Actividades Culturales y Deportivas II.
A24: 18:00 19:00 | C24: Geometría Descriptiva. - Lab. Info. Básica | D24: Representación Geométrica. - Lab. Diseño PC | E24: Representación Geométrica. - Lab. Info. Básica | F24: Actividades Culturales y Deportivas II.
A25: 19:00 20:00 | B25: Ilustración Digital. - CCAI PC | C25: Modelado Manual. - M206 | D25: Ilustración Digital. - CCAI PC | E25: Modelado Manual. - M206
A26: 20:00 21:00 | B26: Ilustración Digital. - CCAI PC | C26: Modelado Manual. - M206 | D26: Ilustración Digital. - CCAI PC | E26: Modelado Manual. - M206
A27: 21:00 22:00 | C27: Tutoría II. - M206 | E27: Modelado Manual. - M206
A28: Horario generado: | G28: asc Horarios.
A29: Asignatura | D29: Horas | E29: Profesores
A30: Inglés II. | D30: =VLOOKUP(A30, Materias!A2:C180, 3, FALSE) -> 5 | E30: COORDINACIÓN DE INGLES
A31: Habilidades Socioemocionales y Manejo de Conflictos. | D31: =VLOOKUP(A31, Materias!A2:C180, 3, FALSE) -> 4 | E31: VILLA CUETO MA. ISABEL
A32: Geometría Descriptiva. | D32: =VLOOKUP(A32, Materias!A2:C180, 3, FALSE) -> 5 | E32: MARTINEZ VEGA FERMIN
A33: Ilustración Digital. | D33: =VLOOKUP(A33, Materias!A2:C180, 3, FALSE) -> 6 | E33: SERRANO SILVA IVAN ENRIQUE
A34: Modelado Manual. | D34: =VLOOKUP(A34, Materias!A2:C180, 3, FALSE) -> 5 | E34: GONZALEZ GARCIA VERONICA
A35: Representación Geométrica. | D35: =VLOOKUP(A35, Materias!A2:C180, 3, FALSE) -> 7 | E35: GOMEZ GONZALEZ JORGE
A36: Mercadotecnia. | D36: =VLOOKUP(A36, Materias!A2:C180, 3, FALSE) -> 3 | E36: RAMOS GAMA JOSELYN KAREN
A37: Tutoría II. | D37: =VLOOKUP(A37, Materias!A2:C180, 3, FALSE) -> 1 | E37: GONZALEZ GARCIA VERONICA
A38: Actividades Culturales y Deportivas II. | D38: =VLOOKUP(A38, Materias!A1:C179, 3, FALSE) -> 2 | E38: COORDINACIÓN DE DEPORTES
A39: Emprendimiento Wadhwani | D39: 5 | E39: DE LA CRUZ PERCASTRE MARTHA
A40: Sesiones/Semana | D40: =SUM(D30:D38) -> 38
A42: Director de la División Académica de Telemática Nombre y Firma del Director (a) de la División Académica
A43: Mtro. Oliver Raúl Velázquez Torres

Sheet DAD209
D1: }
A3: UNIVERSIDAD TECNOLÓGICA FIDEL VELÁZQUEZ
A5: División Académica de Telemática
A6: Carrera en Diseño y Animación Digital
A7: Horario de Grupo
A8: Cuatrimestre: Enero - Abril | E8: GRUPO: DAD209
A9: Período: 2025-1 | C9: TUTOR: ESPINOSA JIMENEZ MARIA MARGARITA
A12: Hora | B12: Lunes | C12: Martes | D12: Miércoles | E12: Jueves | F12: Viernes | G12: Sábado
A13: 07:00 08:00
A14: 08:00 09:00
A15: 09:00 10:00
A16: 10:00 11:00 | B16: Emprendimiento Wadhwani NP
A17: 11:00 12:00 | B17: Emprendimiento Wadhwani NP | C17: Emprendimiento Wadhwani NP | D17: Emprendimiento Wadhwani NP
A18: 12:00 13:00 | B18: Habilidades Socioemocionales y Manejo de Conflictos. - M211 | C18: Tutoría II. - M207 | D18: Emprendimiento Wadhwani NP
A19: 13:00 14:00 | B19: Habilidades Socioemocionales y Manejo de Conflictos. - M211 | C19: Modelado Manual. - M207 | E19: Geometría Descriptiva. - M105 | F19: Ilustración Digital. - CCAI PC
A20: 14:00 15:00 | B20: Habilidades Socioemocionales y Manejo de Conflictos. - M211 | C20: Modelado Manual. - M207 | D20: Modelado Manual. - M207 | E20: Geometría Descriptiva. - M105 | F20: Ilustración Digital. - CCAI PC
A21: 15:00 16:00 | B21: Habilidades Socioemocionales y Manejo de Conflictos. - M211 | C21: Modelado Manual. - M207 | D21: Modelado Manual. - M207 | E21: Geometría Descriptiva. - M105 | F21: Ilustración Digital. - CCAI PC
A22: 16:00 17:00 | B22: Inglés II. | C22: Inglés II. | D22: Inglés II. | E22: Inglés II. | F22: Inglés II.
A23: 17:00 18:00 | B23: Geometría Descriptiva. - M106 | C23: Representación Geométrica. - BITMAP | D23: Mercadotecnia. - M209 | E23: Ilustración Digital. - CCAI PC | F23: Actividades Culturales y Deportivas II.
A24: 18:00 19:00 | B24: Geometría Descriptiva. - M106 | C24: Representación Geométrica. - BITMAP | D24: Mercadotecnia. - M209 | E24: Ilustración Digital. - CCAI PC | F24: Actividades Culturales y Deportivas II.
A25: 19:00 20:00 | B25: Representación Geométrica. - BITMAP | C25: Representación Geométrica. - BITMAP | D25: Mercadotecnia. - M209 | E25: Ilustración Digital. - CCAI PC
A26: 20:00 21:00 | B26: Representación Geométrica. - BITMAP | D26: Representación Geométrica. - BITMAP | E26: Representación Geométrica. - BITMAP
A27: 21:00 22:00
A28: Horario generado: | G28: asc Horarios.
A29: Asignatura | D29: Horas | E29: Profesores
A30: Inglés II. | D30: =VLOOKUP(A30, Materias!A2:C180, 3, FALSE) -> 5 | E30: COORDINACIÓN DE INGLES
A31: Habilidades Socioemocionales y Manejo de Conflictos. | D31: =VLOOKUP(A31, Materias!A2:C180, 3, FALSE) -> 4 | E31: ESPINOSA JIMENEZ MARIA MARGARITA
A32: Geometría Descriptiva. | D32: =VLOOKUP(A32, Materias!A2:C180, 3, FALSE) -> 5 | E32: GOMEZ GONZALEZ JORGE
A33: Ilustración Digital. | D33: =VLOOKUP(A33, Materias!A2:C180, 3, FALSE) -> 6 | E33: SERRANO SILVA IVAN ENRIQUE
A34: Modelado Manual. | D34: =VLOOKUP(A34, Materias!A2:C180, 3, FALSE) -> 5 | E34: ORDOÑEZ MORALES LUIS MARTIN
A35: Representación Geométrica. | D35: =VLOOKUP(A35, Materias!A2:C180, 3, FALSE) -> 7 | E35: MONROY TREJO ALEJANDRO
A36: Mercadotecnia. | D36: =VLOOKUP(A36, Materias!A2:C180, 3, FALSE) -> 3 | E36: RAMOS GAMA JOSELYN KAREN
